2022-03-09 13:13:01 WARNING (Recorder) [homeassistant.components.recorder.util] The system could not validate that the sqlite3 database at //config/home-assistant_v2.db was shutdown cleanly
2022-03-09 13:13:01 WARNING (Recorder) [homeassistant.components.recorder.util] Ended unfinished session (id=3 from 2022-03-08 04:54:57.308690)
2022-03-09 13:13:02 WARNING (MainThread) [homeassistant.components.hassio] Can't read Supervisor data: Container addon_a0d7b954_ssh is not running
2022-03-09 13:13:03 ERROR (MainThread) [homeassistant.components.github] Bad credentials
Traceback (most recent call last):
  File "/usr/src/homeassistant/homeassistant/components/github/coordinator.py", line 125, in _async_update_data
    response = await self._client.graphql(
  File "/usr/local/lib/python3.9/site-packages/aiogithubapi/github.py", line 225, in graphql
    return await self._client.async_call_api(
  File "/usr/local/lib/python3.9/site-packages/aiogithubapi/client.py", line 140, in async_call_api
    raise exception(message or response.data)
aiogithubapi.exceptions.GitHubAuthenticationException: Bad credentials
2022-03-09 13:13:03 WARNING (MainThread) [homeassistant.config_entries] Config entry '' for github integration not ready yet: Bad credentials; Retrying in background
2022-03-09 13:13:04 ERROR (MainThread) [homeassistant.components.github] Bad credentials
Traceback (most recent call last):
  File "/usr/src/homeassistant/homeassistant/components/github/coordinator.py", line 125, in _async_update_data
    response = await self._client.graphql(
  File "/usr/local/lib/python3.9/site-packages/aiogithubapi/github.py", line 225, in graphql
    return await self._client.async_call_api(
  File "/usr/local/lib/python3.9/site-packages/aiogithubapi/client.py", line 140, in async_call_api
    raise exception(message or response.data)
aiogithubapi.exceptions.GitHubAuthenticationException: Bad credentials
2022-03-09 13:13:14 ERROR (MainThread) [homeassistant.components.github] Bad credentials
Traceback (most recent call last):
  File "/usr/src/homeassistant/homeassistant/components/github/coordinator.py", line 125, in _async_update_data
    response = await self._client.graphql(
  File "/usr/local/lib/python3.9/site-packages/aiogithubapi/github.py", line 225, in graphql
    return await self._client.async_call_api(
  File "/usr/local/lib/python3.9/site-packages/aiogithubapi/client.py", line 140, in async_call_api
    raise exception(message or response.data)
aiogithubapi.exceptions.GitHubAuthenticationException: Bad credentials
2022-03-09 13:13:35 ERROR (MainThread) [homeassistant.components.github] Bad credentials
Traceback (most recent call last):
  File "/usr/src/homeassistant/homeassistant/components/github/coordinator.py", line 125, in _async_update_data
    response = await self._client.graphql(
  File "/usr/local/lib/python3.9/site-packages/aiogithubapi/github.py", line 225, in graphql
    return await self._client.async_call_api(
  File "/usr/local/lib/python3.9/site-packages/aiogithubapi/client.py", line 140, in async_call_api
    raise exception(message or response.data)
aiogithubapi.exceptions.GitHubAuthenticationException: Bad credentials
2022-03-09 13:13:46 ERROR (MainThread) [homeassistant.components.hassio] Failed to to call /addons/a0d7b954_ssh/stats - Container addon_a0d7b954_ssh is not running
2022-03-09 13:13:51 ERROR (MainThread) [homeassistant.components.hassio] Failed to to call /addons/a0d7b954_ssh/stats - Container addon_a0d7b954_ssh is not running
2022-03-09 13:14:15 ERROR (MainThread) [homeassistant.components.github] Bad credentials
Traceback (most recent call last):
  File "/usr/src/homeassistant/homeassistant/components/github/coordinator.py", line 125, in _async_update_data
    response = await self._client.graphql(
  File "/usr/local/lib/python3.9/site-packages/aiogithubapi/github.py", line 225, in graphql
    return await self._client.async_call_api(
  File "/usr/local/lib/python3.9/site-packages/aiogithubapi/client.py", line 140, in async_call_api
    raise exception(message or response.data)
aiogithubapi.exceptions.GitHubAuthenticationException: Bad credentials
2022-03-09 13:14:47 ERROR (MainThread) [homeassistant.components.hassio] Failed to to call /addons/a0d7b954_ssh/stats - Container addon_a0d7b954_ssh is not running
2022-03-09 13:15:03 ERROR (MainThread) [homeassistant.components.hassio] Failed to to call /addons/a0d7b954_ssh/stats - Container addon_a0d7b954_ssh is not running
2022-03-09 13:15:36 ERROR (MainThread) [homeassistant.components.github] Bad credentials
Traceback (most recent call last):
  File "/usr/src/homeassistant/homeassistant/components/github/coordinator.py", line 125, in _async_update_data
    response = await self._client.graphql(
  File "/usr/local/lib/python3.9/site-packages/aiogithubapi/github.py", line 225, in graphql
    return await self._client.async_call_api(
  File "/usr/local/lib/python3.9/site-packages/aiogithubapi/client.py", line 140, in async_call_api
    raise exception(message or response.data)
aiogithubapi.exceptions.GitHubAuthenticationException: Bad credentials
2022-03-09 13:16:56 ERROR (MainThread) [homeassistant.components.github] Bad credentials
Traceback (most recent call last):
  File "/usr/src/homeassistant/homeassistant/components/github/coordinator.py", line 125, in _async_update_data
    response = await self._client.graphql(
  File "/usr/local/lib/python3.9/site-packages/aiogithubapi/github.py", line 225, in graphql
    return await self._client.async_call_api(
  File "/usr/local/lib/python3.9/site-packages/aiogithubapi/client.py", line 140, in async_call_api
    raise exception(message or response.data)
aiogithubapi.exceptions.GitHubAuthenticationException: Bad credentials
2022-03-09 13:18:02 WARNING (MainThread) [homeassistant.components.hassio] Can't read Supervisor data: Container addon_a0d7b954_phpmyadmin is not running
2022-03-09 13:18:17 ERROR (MainThread) [homeassistant.components.github] Bad credentials
Traceback (most recent call last):
  File "/usr/src/homeassistant/homeassistant/components/github/coordinator.py", line 125, in _async_update_data
    response = await self._client.graphql(
  File "/usr/local/lib/python3.9/site-packages/aiogithubapi/github.py", line 225, in graphql
    return await self._client.async_call_api(
  File "/usr/local/lib/python3.9/site-packages/aiogithubapi/client.py", line 140, in async_call_api
    raise exception(message or response.data)
aiogithubapi.exceptions.GitHubAuthenticationException: Bad credentials
2022-03-09 13:19:38 ERROR (MainThread) [homeassistant.components.github] Bad credentials
Traceback (most recent call last):
  File "/usr/src/homeassistant/homeassistant/components/github/coordinator.py", line 125, in _async_update_data
    response = await self._client.graphql(
  File "/usr/local/lib/python3.9/site-packages/aiogithubapi/github.py", line 225, in graphql
    return await self._client.async_call_api(
  File "/usr/local/lib/python3.9/site-packages/aiogithubapi/client.py", line 140, in async_call_api
    raise exception(message or response.data)
aiogithubapi.exceptions.GitHubAuthenticationException: Bad credentials
2022-03-09 13:20:59 ERROR (MainThread) [homeassistant.components.github] Bad credentials
Traceback (most recent call last):
  File "/usr/src/homeassistant/homeassistant/components/github/coordinator.py", line 125, in _async_update_data
    response = await self._client.graphql(
  File "/usr/local/lib/python3.9/site-packages/aiogithubapi/github.py", line 225, in graphql
    return await self._client.async_call_api(
  File "/usr/local/lib/python3.9/site-packages/aiogithubapi/client.py", line 140, in async_call_api
    raise exception(message or response.data)
aiogithubapi.exceptions.GitHubAuthenticationException: Bad credentials
2022-03-09 13:22:19 ERROR (MainThread) [homeassistant.components.github] Bad credentials
Traceback (most recent call last):
  File "/usr/src/homeassistant/homeassistant/components/github/coordinator.py", line 125, in _async_update_data
    response = await self._client.graphql(
  File "/usr/local/lib/python3.9/site-packages/aiogithubapi/github.py", line 225, in graphql
    return await self._client.async_call_api(
  File "/usr/local/lib/python3.9/site-packages/aiogithubapi/client.py", line 140, in async_call_api
    raise exception(message or response.data)
aiogithubapi.exceptions.GitHubAuthenticationException: Bad credentials
2022-03-09 13:23:02 WARNING (MainThread) [homeassistant.components.hassio] Can't read Supervisor data: Container addon_a0d7b954_phpmyadmin is not running
2022-03-09 13:23:40 ERROR (MainThread) [homeassistant.components.github] Bad credentials
Traceback (most recent call last):
  File "/usr/src/homeassistant/homeassistant/components/github/coordinator.py", line 125, in _async_update_data
    response = await self._client.graphql(
  File "/usr/local/lib/python3.9/site-packages/aiogithubapi/github.py", line 225, in graphql
    return await self._client.async_call_api(
  File "/usr/local/lib/python3.9/site-packages/aiogithubapi/client.py", line 140, in async_call_api
    raise exception(message or response.data)
aiogithubapi.exceptions.GitHubAuthenticationException: Bad credentials
2022-03-09 13:25:00 ERROR (MainThread) [homeassistant.components.github] Bad credentials
Traceback (most recent call last):
  File "/usr/src/homeassistant/homeassistant/components/github/coordinator.py", line 125, in _async_update_data
    response = await self._client.graphql(
  File "/usr/local/lib/python3.9/site-packages/aiogithubapi/github.py", line 225, in graphql
    return await self._client.async_call_api(
  File "/usr/local/lib/python3.9/site-packages/aiogithubapi/client.py", line 140, in async_call_api
    raise exception(message or response.data)
aiogithubapi.exceptions.GitHubAuthenticationException: Bad credentials
2022-03-09 13:26:21 ERROR (MainThread) [homeassistant.components.github] Bad credentials
Traceback (most recent call last):
  File "/usr/src/homeassistant/homeassistant/components/github/coordinator.py", line 125, in _async_update_data
    response = await self._client.graphql(
  File "/usr/local/lib/python3.9/site-packages/aiogithubapi/github.py", line 225, in graphql
    return await self._client.async_call_api(
  File "/usr/local/lib/python3.9/site-packages/aiogithubapi/client.py", line 140, in async_call_api
    raise exception(message or response.data)
aiogithubapi.exceptions.GitHubAuthenticationException: Bad credentials
2022-03-09 13:27:41 ERROR (MainThread) [homeassistant.components.github] Bad credentials
Traceback (most recent call last):
  File "/usr/src/homeassistant/homeassistant/components/github/coordinator.py", line 125, in _async_update_data
    response = await self._client.graphql(
  File "/usr/local/lib/python3.9/site-packages/aiogithubapi/github.py", line 225, in graphql
    return await self._client.async_call_api(
  File "/usr/local/lib/python3.9/site-packages/aiogithubapi/client.py", line 140, in async_call_api
    raise exception(message or response.data)
aiogithubapi.exceptions.GitHubAuthenticationException: Bad credentials
2022-03-09 13:28:02 WARNING (MainThread) [homeassistant.components.hassio] Can't read Supervisor data: Container addon_a0d7b954_phpmyadmin is not running
2022-03-09 13:29:02 ERROR (MainThread) [homeassistant.components.github] Bad credentials
Traceback (most recent call last):
  File "/usr/src/homeassistant/homeassistant/components/github/coordinator.py", line 125, in _async_update_data
    response = await self._client.graphql(
  File "/usr/local/lib/python3.9/site-packages/aiogithubapi/github.py", line 225, in graphql
    return await self._client.async_call_api(
  File "/usr/local/lib/python3.9/site-packages/aiogithubapi/client.py", line 140, in async_call_api
    raise exception(message or response.data)
aiogithubapi.exceptions.GitHubAuthenticationException: Bad credentials
2022-03-09 13:30:23 ERROR (MainThread) [homeassistant.components.github] Bad credentials
Traceback (most recent call last):
  File "/usr/src/homeassistant/homeassistant/components/github/coordinator.py", line 125, in _async_update_data
    response = await self._client.graphql(
  File "/usr/local/lib/python3.9/site-packages/aiogithubapi/github.py", line 225, in graphql
    return await self._client.async_call_api(
  File "/usr/local/lib/python3.9/site-packages/aiogithubapi/client.py", line 140, in async_call_api
    raise exception(message or response.data)
aiogithubapi.exceptions.GitHubAuthenticationException: Bad credentials
2022-03-09 13:31:43 ERROR (MainThread) [homeassistant.components.github] Bad credentials
Traceback (most recent call last):
  File "/usr/src/homeassistant/homeassistant/components/github/coordinator.py", line 125, in _async_update_data
    response = await self._client.graphql(
  File "/usr/local/lib/python3.9/site-packages/aiogithubapi/github.py", line 225, in graphql
    return await self._client.async_call_api(
  File "/usr/local/lib/python3.9/site-packages/aiogithubapi/client.py", line 140, in async_call_api
    raise exception(message or response.data)
aiogithubapi.exceptions.GitHubAuthenticationException: Bad credentials
2022-03-09 13:33:02 WARNING (MainThread) [homeassistant.components.hassio] Can't read Supervisor data: Container addon_a0d7b954_phpmyadmin is not running
2022-03-09 13:33:04 ERROR (MainThread) [homeassistant.components.github] Bad credentials
Traceback (most recent call last):
  File "/usr/src/homeassistant/homeassistant/components/github/coordinator.py", line 125, in _async_update_data
    response = await self._client.graphql(
  File "/usr/local/lib/python3.9/site-packages/aiogithubapi/github.py", line 225, in graphql
    return await self._client.async_call_api(
  File "/usr/local/lib/python3.9/site-packages/aiogithubapi/client.py", line 140, in async_call_api
    raise exception(message or response.data)
aiogithubapi.exceptions.GitHubAuthenticationException: Bad credentials
2022-03-09 13:34:25 ERROR (MainThread) [homeassistant.components.github] Bad credentials
Traceback (most recent call last):
  File "/usr/src/homeassistant/homeassistant/components/github/coordinator.py", line 125, in _async_update_data
    response = await self._client.graphql(
  File "/usr/local/lib/python3.9/site-packages/aiogithubapi/github.py", line 225, in graphql
    return await self._client.async_call_api(
  File "/usr/local/lib/python3.9/site-packages/aiogithubapi/client.py", line 140, in async_call_api
    raise exception(message or response.data)
aiogithubapi.exceptions.GitHubAuthenticationException: Bad credentials
2022-03-09 13:35:45 ERROR (MainThread) [homeassistant.components.github] Bad credentials
Traceback (most recent call last):
  File "/usr/src/homeassistant/homeassistant/components/github/coordinator.py", line 125, in _async_update_data
    response = await self._client.graphql(
  File "/usr/local/lib/python3.9/site-packages/aiogithubapi/github.py", line 225, in graphql
    return await self._client.async_call_api(
  File "/usr/local/lib/python3.9/site-packages/aiogithubapi/client.py", line 140, in async_call_api
    raise exception(message or response.data)
aiogithubapi.exceptions.GitHubAuthenticationException: Bad credentials
2022-03-09 13:37:06 ERROR (MainThread) [homeassistant.components.github] Bad credentials
Traceback (most recent call last):
  File "/usr/src/homeassistant/homeassistant/components/github/coordinator.py", line 125, in _async_update_data
    response = await self._client.graphql(
  File "/usr/local/lib/python3.9/site-packages/aiogithubapi/github.py", line 225, in graphql
    return await self._client.async_call_api(
  File "/usr/local/lib/python3.9/site-packages/aiogithubapi/client.py", line 140, in async_call_api
    raise exception(message or response.data)
aiogithubapi.exceptions.GitHubAuthenticationException: Bad credentials
2022-03-09 13:38:27 ERROR (MainThread) [homeassistant.components.github] Bad credentials
Traceback (most recent call last):
  File "/usr/src/homeassistant/homeassistant/components/github/coordinator.py", line 125, in _async_update_data
    response = await self._client.graphql(
  File "/usr/local/lib/python3.9/site-packages/aiogithubapi/github.py", line 225, in graphql
    return await self._client.async_call_api(
  File "/usr/local/lib/python3.9/site-packages/aiogithubapi/client.py", line 140, in async_call_api
    raise exception(message or response.data)
aiogithubapi.exceptions.GitHubAuthenticationException: Bad credentials
2022-03-09 13:39:47 ERROR (MainThread) [homeassistant.components.github] Bad credentials
Traceback (most recent call last):
  File "/usr/src/homeassistant/homeassistant/components/github/coordinator.py", line 125, in _async_update_data
    response = await self._client.graphql(
  File "/usr/local/lib/python3.9/site-packages/aiogithubapi/github.py", line 225, in graphql
    return await self._client.async_call_api(
  File "/usr/local/lib/python3.9/site-packages/aiogithubapi/client.py", line 140, in async_call_api
    raise exception(message or response.data)
aiogithubapi.exceptions.GitHubAuthenticationException: Bad credentials
2022-03-09 13:41:08 ERROR (MainThread) [homeassistant.components.github] Bad credentials
Traceback (most recent call last):
  File "/usr/src/homeassistant/homeassistant/components/github/coordinator.py", line 125, in _async_update_data
    response = await self._client.graphql(
  File "/usr/local/lib/python3.9/site-packages/aiogithubapi/github.py", line 225, in graphql
    return await self._client.async_call_api(
  File "/usr/local/lib/python3.9/site-packages/aiogithubapi/client.py", line 140, in async_call_api
    raise exception(message or response.data)
aiogithubapi.exceptions.GitHubAuthenticationException: Bad credentials
2022-03-09 13:42:29 ERROR (MainThread) [homeassistant.components.github] Bad credentials
Traceback (most recent call last):
  File "/usr/src/homeassistant/homeassistant/components/github/coordinator.py", line 125, in _async_update_data
    response = await self._client.graphql(
  File "/usr/local/lib/python3.9/site-packages/aiogithubapi/github.py", line 225, in graphql
    return await self._client.async_call_api(
  File "/usr/local/lib/python3.9/site-packages/aiogithubapi/client.py", line 140, in async_call_api
    raise exception(message or response.data)
aiogithubapi.exceptions.GitHubAuthenticationException: Bad credentials
2022-03-09 13:43:50 ERROR (MainThread) [homeassistant.components.github] Bad credentials
Traceback (most recent call last):
  File "/usr/src/homeassistant/homeassistant/components/github/coordinator.py", line 125, in _async_update_data
    response = await self._client.graphql(
  File "/usr/local/lib/python3.9/site-packages/aiogithubapi/github.py", line 225, in graphql
    return await self._client.async_call_api(
  File "/usr/local/lib/python3.9/site-packages/aiogithubapi/client.py", line 140, in async_call_api
    raise exception(message or response.data)
aiogithubapi.exceptions.GitHubAuthenticationException: Bad credentials
2022-03-09 13:45:10 ERROR (MainThread) [homeassistant.components.github] Bad credentials
Traceback (most recent call last):
  File "/usr/src/homeassistant/homeassistant/components/github/coordinator.py", line 125, in _async_update_data
    response = await self._client.graphql(
  File "/usr/local/lib/python3.9/site-packages/aiogithubapi/github.py", line 225, in graphql
    return await self._client.async_call_api(
  File "/usr/local/lib/python3.9/site-packages/aiogithubapi/client.py", line 140, in async_call_api
    raise exception(message or response.data)
aiogithubapi.exceptions.GitHubAuthenticationException: Bad credentials
2022-03-09 13:46:31 ERROR (MainThread) [homeassistant.components.github] Bad credentials
Traceback (most recent call last):
  File "/usr/src/homeassistant/homeassistant/components/github/coordinator.py", line 125, in _async_update_data
    response = await self._client.graphql(
  File "/usr/local/lib/python3.9/site-packages/aiogithubapi/github.py", line 225, in graphql
    return await self._client.async_call_api(
  File "/usr/local/lib/python3.9/site-packages/aiogithubapi/client.py", line 140, in async_call_api
    raise exception(message or response.data)
aiogithubapi.exceptions.GitHubAuthenticationException: Bad credentials
2022-03-09 13:47:52 ERROR (MainThread) [homeassistant.components.github] Bad credentials
Traceback (most recent call last):
  File "/usr/src/homeassistant/homeassistant/components/github/coordinator.py", line 125, in _async_update_data
    response = await self._client.graphql(
  File "/usr/local/lib/python3.9/site-packages/aiogithubapi/github.py", line 225, in graphql
    return await self._client.async_call_api(
  File "/usr/local/lib/python3.9/site-packages/aiogithubapi/client.py", line 140, in async_call_api
    raise exception(message or response.data)
aiogithubapi.exceptions.GitHubAuthenticationException: Bad credentials
2022-03-09 13:48:06 WARNING (MainThread) [homeassistant.components.hassio] Can't read Supervisor data: Container addon_a0d7b954_phpmyadmin is not running
2022-03-09 13:49:13 ERROR (MainThread) [homeassistant.components.github] Bad credentials
Traceback (most recent call last):
  File "/usr/src/homeassistant/homeassistant/components/github/coordinator.py", line 125, in _async_update_data
    response = await self._client.graphql(
  File "/usr/local/lib/python3.9/site-packages/aiogithubapi/github.py", line 225, in graphql
    return await self._client.async_call_api(
  File "/usr/local/lib/python3.9/site-packages/aiogithubapi/client.py", line 140, in async_call_api
    raise exception(message or response.data)
aiogithubapi.exceptions.GitHubAuthenticationException: Bad credentials
2022-03-09 13:50:33 ERROR (MainThread) [homeassistant.components.github] Bad credentials
Traceback (most recent call last):
  File "/usr/src/homeassistant/homeassistant/components/github/coordinator.py", line 125, in _async_update_data
    response = await self._client.graphql(
  File "/usr/local/lib/python3.9/site-packages/aiogithubapi/github.py", line 225, in graphql
    return await self._client.async_call_api(
  File "/usr/local/lib/python3.9/site-packages/aiogithubapi/client.py", line 140, in async_call_api
    raise exception(message or response.data)
aiogithubapi.exceptions.GitHubAuthenticationException: Bad credentials
2022-03-09 13:51:54 ERROR (MainThread) [homeassistant.components.github] Bad credentials
Traceback (most recent call last):
  File "/usr/src/homeassistant/homeassistant/components/github/coordinator.py", line 125, in _async_update_data
    response = await self._client.graphql(
  File "/usr/local/lib/python3.9/site-packages/aiogithubapi/github.py", line 225, in graphql
    return await self._client.async_call_api(
  File "/usr/local/lib/python3.9/site-packages/aiogithubapi/client.py", line 140, in async_call_api
    raise exception(message or response.data)
aiogithubapi.exceptions.GitHubAuthenticationException: Bad credentials
2022-03-09 13:53:06 WARNING (MainThread) [homeassistant.components.hassio] Can't read Supervisor data: Container addon_a0d7b954_phpmyadmin is not running
2022-03-09 13:53:19 ERROR (MainThread) [homeassistant.components.github] Bad credentials
Traceback (most recent call last):
  File "/usr/src/homeassistant/homeassistant/components/github/coordinator.py", line 125, in _async_update_data
    response = await self._client.graphql(
  File "/usr/local/lib/python3.9/site-packages/aiogithubapi/github.py", line 225, in graphql
    return await self._client.async_call_api(
  File "/usr/local/lib/python3.9/site-packages/aiogithubapi/client.py", line 140, in async_call_api
    raise exception(message or response.data)
aiogithubapi.exceptions.GitHubAuthenticationException: Bad credentials
2022-03-09 13:54:39 ERROR (MainThread) [homeassistant.components.github] Bad credentials
Traceback (most recent call last):
  File "/usr/src/homeassistant/homeassistant/components/github/coordinator.py", line 125, in _async_update_data
    response = await self._client.graphql(
  File "/usr/local/lib/python3.9/site-packages/aiogithubapi/github.py", line 225, in graphql
    return await self._client.async_call_api(
  File "/usr/local/lib/python3.9/site-packages/aiogithubapi/client.py", line 140, in async_call_api
    raise exception(message or response.data)
aiogithubapi.exceptions.GitHubAuthenticationException: Bad credentials
2022-03-09 13:56:05 ERROR (MainThread) [homeassistant.components.github] Bad credentials
Traceback (most recent call last):
  File "/usr/src/homeassistant/homeassistant/components/github/coordinator.py", line 125, in _async_update_data
    response = await self._client.graphql(
  File "/usr/local/lib/python3.9/site-packages/aiogithubapi/github.py", line 225, in graphql
    return await self._client.async_call_api(
  File "/usr/local/lib/python3.9/site-packages/aiogithubapi/client.py", line 140, in async_call_api
    raise exception(message or response.data)
aiogithubapi.exceptions.GitHubAuthenticationException: Bad credentials
2022-03-09 13:57:26 ERROR (MainThread) [homeassistant.components.github] Bad credentials
Traceback (most recent call last):
  File "/usr/src/homeassistant/homeassistant/components/github/coordinator.py", line 125, in _async_update_data
    response = await self._client.graphql(
  File "/usr/local/lib/python3.9/site-packages/aiogithubapi/github.py", line 225, in graphql
    return await self._client.async_call_api(
  File "/usr/local/lib/python3.9/site-packages/aiogithubapi/client.py", line 140, in async_call_api
    raise exception(message or response.data)
aiogithubapi.exceptions.GitHubAuthenticationException: Bad credentials
2022-03-09 13:58:06 WARNING (MainThread) [homeassistant.components.hassio] Can't read Supervisor data: Container addon_a0d7b954_phpmyadmin is not running
2022-03-09 13:58:47 ERROR (MainThread) [homeassistant.components.github] Bad credentials
Traceback (most recent call last):
  File "/usr/src/homeassistant/homeassistant/components/github/coordinator.py", line 125, in _async_update_data
    response = await self._client.graphql(
  File "/usr/local/lib/python3.9/site-packages/aiogithubapi/github.py", line 225, in graphql
    return await self._client.async_call_api(
  File "/usr/local/lib/python3.9/site-packages/aiogithubapi/client.py", line 140, in async_call_api
    raise exception(message or response.data)
aiogithubapi.exceptions.GitHubAuthenticationException: Bad credentials
2022-03-09 14:00:08 ERROR (MainThread) [homeassistant.components.github] Bad credentials
Traceback (most recent call last):
  File "/usr/src/homeassistant/homeassistant/components/github/coordinator.py", line 125, in _async_update_data
    response = await self._client.graphql(
  File "/usr/local/lib/python3.9/site-packages/aiogithubapi/github.py", line 225, in graphql
    return await self._client.async_call_api(
  File "/usr/local/lib/python3.9/site-packages/aiogithubapi/client.py", line 140, in async_call_api
    raise exception(message or response.data)
aiogithubapi.exceptions.GitHubAuthenticationException: Bad credentials
2022-03-09 14:01:28 ERROR (MainThread) [homeassistant.components.github] Bad credentials
Traceback (most recent call last):
  File "/usr/src/homeassistant/homeassistant/components/github/coordinator.py", line 125, in _async_update_data
    response = await self._client.graphql(
  File "/usr/local/lib/python3.9/site-packages/aiogithubapi/github.py", line 225, in graphql
    return await self._client.async_call_api(
  File "/usr/local/lib/python3.9/site-packages/aiogithubapi/client.py", line 140, in async_call_api
    raise exception(message or response.data)
aiogithubapi.exceptions.GitHubAuthenticationException: Bad credentials
2022-03-09 14:02:51 ERROR (MainThread) [homeassistant.components.github] Bad credentials
Traceback (most recent call last):
  File "/usr/src/homeassistant/homeassistant/components/github/coordinator.py", line 125, in _async_update_data
    response = await self._client.graphql(
  File "/usr/local/lib/python3.9/site-packages/aiogithubapi/github.py", line 225, in graphql
    return await self._client.async_call_api(
  File "/usr/local/lib/python3.9/site-packages/aiogithubapi/client.py", line 140, in async_call_api
    raise exception(message or response.data)
aiogithubapi.exceptions.GitHubAuthenticationException: Bad credentials
2022-03-09 14:03:07 WARNING (MainThread) [homeassistant.components.hassio] Can't read Supervisor data: Container addon_a0d7b954_phpmyadmin is not running
2022-03-09 14:04:12 ERROR (MainThread) [homeassistant.components.github] Bad credentials
Traceback (most recent call last):
  File "/usr/src/homeassistant/homeassistant/components/github/coordinator.py", line 125, in _async_update_data
    response = await self._client.graphql(
  File "/usr/local/lib/python3.9/site-packages/aiogithubapi/github.py", line 225, in graphql
    return await self._client.async_call_api(
  File "/usr/local/lib/python3.9/site-packages/aiogithubapi/client.py", line 140, in async_call_api
    raise exception(message or response.data)
aiogithubapi.exceptions.GitHubAuthenticationException: Bad credentials
2022-03-09 14:05:34 ERROR (MainThread) [homeassistant.components.github] Bad credentials
Traceback (most recent call last):
  File "/usr/src/homeassistant/homeassistant/components/github/coordinator.py", line 125, in _async_update_data
    response = await self._client.graphql(
  File "/usr/local/lib/python3.9/site-packages/aiogithubapi/github.py", line 225, in graphql
    return await self._client.async_call_api(
  File "/usr/local/lib/python3.9/site-packages/aiogithubapi/client.py", line 140, in async_call_api
    raise exception(message or response.data)
aiogithubapi.exceptions.GitHubAuthenticationException: Bad credentials
2022-03-09 14:07:07 ERROR (MainThread) [homeassistant.components.github] Bad credentials
Traceback (most recent call last):
  File "/usr/src/homeassistant/homeassistant/components/github/coordinator.py", line 125, in _async_update_data
    response = await self._client.graphql(
  File "/usr/local/lib/python3.9/site-packages/aiogithubapi/github.py", line 225, in graphql
    return await self._client.async_call_api(
  File "/usr/local/lib/python3.9/site-packages/aiogithubapi/client.py", line 140, in async_call_api
    raise exception(message or response.data)
aiogithubapi.exceptions.GitHubAuthenticationException: Bad credentials
2022-03-09 14:08:07 WARNING (MainThread) [homeassistant.components.hassio] Can't read Supervisor data: Container addon_a0d7b954_phpmyadmin is not running
2022-03-09 14:08:27 ERROR (MainThread) [homeassistant.components.github] Bad credentials
Traceback (most recent call last):
  File "/usr/src/homeassistant/homeassistant/components/github/coordinator.py", line 125, in _async_update_data
    response = await self._client.graphql(
  File "/usr/local/lib/python3.9/site-packages/aiogithubapi/github.py", line 225, in graphql
    return await self._client.async_call_api(
  File "/usr/local/lib/python3.9/site-packages/aiogithubapi/client.py", line 140, in async_call_api
    raise exception(message or response.data)
aiogithubapi.exceptions.GitHubAuthenticationException: Bad credentials
2022-03-09 14:09:48 ERROR (MainThread) [homeassistant.components.github] Bad credentials
Traceback (most recent call last):
  File "/usr/src/homeassistant/homeassistant/components/github/coordinator.py", line 125, in _async_update_data
    response = await self._client.graphql(
  File "/usr/local/lib/python3.9/site-packages/aiogithubapi/github.py", line 225, in graphql
    return await self._client.async_call_api(
  File "/usr/local/lib/python3.9/site-packages/aiogithubapi/client.py", line 140, in async_call_api
    raise exception(message or response.data)
aiogithubapi.exceptions.GitHubAuthenticationException: Bad credentials
2022-03-09 14:11:09 ERROR (MainThread) [homeassistant.components.github] Bad credentials
Traceback (most recent call last):
  File "/usr/src/homeassistant/homeassistant/components/github/coordinator.py", line 125, in _async_update_data
    response = await self._client.graphql(
  File "/usr/local/lib/python3.9/site-packages/aiogithubapi/github.py", line 225, in graphql
    return await self._client.async_call_api(
  File "/usr/local/lib/python3.9/site-packages/aiogithubapi/client.py", line 140, in async_call_api
    raise exception(message or response.data)
aiogithubapi.exceptions.GitHubAuthenticationException: Bad credentials
2022-03-09 14:12:30 ERROR (MainThread) [homeassistant.components.github] Bad credentials
Traceback (most recent call last):
  File "/usr/src/homeassistant/homeassistant/components/github/coordinator.py", line 125, in _async_update_data
    response = await self._client.graphql(
  File "/usr/local/lib/python3.9/site-packages/aiogithubapi/github.py", line 225, in graphql
    return await self._client.async_call_api(
  File "/usr/local/lib/python3.9/site-packages/aiogithubapi/client.py", line 140, in async_call_api
    raise exception(message or response.data)
aiogithubapi.exceptions.GitHubAuthenticationException: Bad credentials
2022-03-09 14:13:07 WARNING (MainThread) [homeassistant.components.hassio] Can't read Supervisor data: Container addon_a0d7b954_phpmyadmin is not running
2022-03-09 14:13:50 ERROR (MainThread) [homeassistant.components.github] Bad credentials
Traceback (most recent call last):
  File "/usr/src/homeassistant/homeassistant/components/github/coordinator.py", line 125, in _async_update_data
    response = await self._client.graphql(
  File "/usr/local/lib/python3.9/site-packages/aiogithubapi/github.py", line 225, in graphql
    return await self._client.async_call_api(
  File "/usr/local/lib/python3.9/site-packages/aiogithubapi/client.py", line 140, in async_call_api
    raise exception(message or response.data)
aiogithubapi.exceptions.GitHubAuthenticationException: Bad credentials
2022-03-09 14:15:11 ERROR (MainThread) [homeassistant.components.github] Bad credentials
Traceback (most recent call last):
  File "/usr/src/homeassistant/homeassistant/components/github/coordinator.py", line 125, in _async_update_data
    response = await self._client.graphql(
  File "/usr/local/lib/python3.9/site-packages/aiogithubapi/github.py", line 225, in graphql
    return await self._client.async_call_api(
  File "/usr/local/lib/python3.9/site-packages/aiogithubapi/client.py", line 140, in async_call_api
    raise exception(message or response.data)
aiogithubapi.exceptions.GitHubAuthenticationException: Bad credentials
2022-03-09 14:16:32 ERROR (MainThread) [homeassistant.components.github] Bad credentials
Traceback (most recent call last):
  File "/usr/src/homeassistant/homeassistant/components/github/coordinator.py", line 125, in _async_update_data
    response = await self._client.graphql(
  File "/usr/local/lib/python3.9/site-packages/aiogithubapi/github.py", line 225, in graphql
    return await self._client.async_call_api(
  File "/usr/local/lib/python3.9/site-packages/aiogithubapi/client.py", line 140, in async_call_api
    raise exception(message or response.data)
aiogithubapi.exceptions.GitHubAuthenticationException: Bad credentials
2022-03-09 14:17:53 ERROR (MainThread) [homeassistant.components.github] Bad credentials
Traceback (most recent call last):
  File "/usr/src/homeassistant/homeassistant/components/github/coordinator.py", line 125, in _async_update_data
    response = await self._client.graphql(
  File "/usr/local/lib/python3.9/site-packages/aiogithubapi/github.py", line 225, in graphql
    return await self._client.async_call_api(
  File "/usr/local/lib/python3.9/site-packages/aiogithubapi/client.py", line 140, in async_call_api
    raise exception(message or response.data)
aiogithubapi.exceptions.GitHubAuthenticationException: Bad credentials
2022-03-09 14:18:07 WARNING (MainThread) [homeassistant.components.hassio] Can't read Supervisor data: Container addon_a0d7b954_phpmyadmin is not running
2022-03-09 14:19:14 ERROR (MainThread) [homeassistant.components.github] Bad credentials
Traceback (most recent call last):
  File "/usr/src/homeassistant/homeassistant/components/github/coordinator.py", line 125, in _async_update_data
    response = await self._client.graphql(
  File "/usr/local/lib/python3.9/site-packages/aiogithubapi/github.py", line 225, in graphql
    return await self._client.async_call_api(
  File "/usr/local/lib/python3.9/site-packages/aiogithubapi/client.py", line 140, in async_call_api
    raise exception(message or response.data)
aiogithubapi.exceptions.GitHubAuthenticationException: Bad credentials
2022-03-09 14:20:35 ERROR (MainThread) [homeassistant.components.github] Bad credentials
Traceback (most recent call last):
  File "/usr/src/homeassistant/homeassistant/components/github/coordinator.py", line 125, in _async_update_data
    response = await self._client.graphql(
  File "/usr/local/lib/python3.9/site-packages/aiogithubapi/github.py", line 225, in graphql
    return await self._client.async_call_api(
  File "/usr/local/lib/python3.9/site-packages/aiogithubapi/client.py", line 140, in async_call_api
    raise exception(message or response.data)
aiogithubapi.exceptions.GitHubAuthenticationException: Bad credentials
2022-03-09 14:21:55 ERROR (MainThread) [homeassistant.components.github] Bad credentials
Traceback (most recent call last):
  File "/usr/src/homeassistant/homeassistant/components/github/coordinator.py", line 125, in _async_update_data
    response = await self._client.graphql(
  File "/usr/local/lib/python3.9/site-packages/aiogithubapi/github.py", line 225, in graphql
    return await self._client.async_call_api(
  File "/usr/local/lib/python3.9/site-packages/aiogithubapi/client.py", line 140, in async_call_api
    raise exception(message or response.data)
aiogithubapi.exceptions.GitHubAuthenticationException: Bad credentials
2022-03-09 14:23:07 WARNING (MainThread) [homeassistant.components.hassio] Can't read Supervisor data: Container addon_a0d7b954_phpmyadmin is not running
2022-03-09 14:23:16 ERROR (MainThread) [homeassistant.components.github] Bad credentials
Traceback (most recent call last):
  File "/usr/src/homeassistant/homeassistant/components/github/coordinator.py", line 125, in _async_update_data
    response = await self._client.graphql(
  File "/usr/local/lib/python3.9/site-packages/aiogithubapi/github.py", line 225, in graphql
    return await self._client.async_call_api(
  File "/usr/local/lib/python3.9/site-packages/aiogithubapi/client.py", line 140, in async_call_api
    raise exception(message or response.data)
aiogithubapi.exceptions.GitHubAuthenticationException: Bad credentials
2022-03-09 14:24:37 ERROR (MainThread) [homeassistant.components.github] Bad credentials
Traceback (most recent call last):
  File "/usr/src/homeassistant/homeassistant/components/github/coordinator.py", line 125, in _async_update_data
    response = await self._client.graphql(
  File "/usr/local/lib/python3.9/site-packages/aiogithubapi/github.py", line 225, in graphql
    return await self._client.async_call_api(
  File "/usr/local/lib/python3.9/site-packages/aiogithubapi/client.py", line 140, in async_call_api
    raise exception(message or response.data)
aiogithubapi.exceptions.GitHubAuthenticationException: Bad credentials
2022-03-09 14:25:58 ERROR (MainThread) [homeassistant.components.github] Bad credentials
Traceback (most recent call last):
  File "/usr/src/homeassistant/homeassistant/components/github/coordinator.py", line 125, in _async_update_data
    response = await self._client.graphql(
  File "/usr/local/lib/python3.9/site-packages/aiogithubapi/github.py", line 225, in graphql
    return await self._client.async_call_api(
  File "/usr/local/lib/python3.9/site-packages/aiogithubapi/client.py", line 140, in async_call_api
    raise exception(message or response.data)
aiogithubapi.exceptions.GitHubAuthenticationException: Bad credentials
2022-03-09 14:27:19 ERROR (MainThread) [homeassistant.components.github] Bad credentials
Traceback (most recent call last):
  File "/usr/src/homeassistant/homeassistant/components/github/coordinator.py", line 125, in _async_update_data
    response = await self._client.graphql(
  File "/usr/local/lib/python3.9/site-packages/aiogithubapi/github.py", line 225, in graphql
    return await self._client.async_call_api(
  File "/usr/local/lib/python3.9/site-packages/aiogithubapi/client.py", line 140, in async_call_api
    raise exception(message or response.data)
aiogithubapi.exceptions.GitHubAuthenticationException: Bad credentials
2022-03-09 14:28:39 ERROR (MainThread) [homeassistant.components.github] Bad credentials
Traceback (most recent call last):
  File "/usr/src/homeassistant/homeassistant/components/github/coordinator.py", line 125, in _async_update_data
    response = await self._client.graphql(
  File "/usr/local/lib/python3.9/site-packages/aiogithubapi/github.py", line 225, in graphql
    return await self._client.async_call_api(
  File "/usr/local/lib/python3.9/site-packages/aiogithubapi/client.py", line 140, in async_call_api
    raise exception(message or response.data)
aiogithubapi.exceptions.GitHubAuthenticationException: Bad credentials
2022-03-09 14:30:00 ERROR (MainThread) [homeassistant.components.github] Bad credentials
Traceback (most recent call last):
  File "/usr/src/homeassistant/homeassistant/components/github/coordinator.py", line 125, in _async_update_data
    response = await self._client.graphql(
  File "/usr/local/lib/python3.9/site-packages/aiogithubapi/github.py", line 225, in graphql
    return await self._client.async_call_api(
  File "/usr/local/lib/python3.9/site-packages/aiogithubapi/client.py", line 140, in async_call_api
    raise exception(message or response.data)
aiogithubapi.exceptions.GitHubAuthenticationException: Bad credentials
2022-03-09 14:31:21 ERROR (MainThread) [homeassistant.components.github] Bad credentials
Traceback (most recent call last):
  File "/usr/src/homeassistant/homeassistant/components/github/coordinator.py", line 125, in _async_update_data
    response = await self._client.graphql(
  File "/usr/local/lib/python3.9/site-packages/aiogithubapi/github.py", line 225, in graphql
    return await self._client.async_call_api(
  File "/usr/local/lib/python3.9/site-packages/aiogithubapi/client.py", line 140, in async_call_api
    raise exception(message or response.data)
aiogithubapi.exceptions.GitHubAuthenticationException: Bad credentials
2022-03-09 14:32:42 ERROR (MainThread) [homeassistant.components.github] Bad credentials
Traceback (most recent call last):
  File "/usr/src/homeassistant/homeassistant/components/github/coordinator.py", line 125, in _async_update_data
    response = await self._client.graphql(
  File "/usr/local/lib/python3.9/site-packages/aiogithubapi/github.py", line 225, in graphql
    return await self._client.async_call_api(
  File "/usr/local/lib/python3.9/site-packages/aiogithubapi/client.py", line 140, in async_call_api
    raise exception(message or response.data)
aiogithubapi.exceptions.GitHubAuthenticationException: Bad credentials
2022-03-09 14:34:02 ERROR (MainThread) [homeassistant.components.github] Bad credentials
Traceback (most recent call last):
  File "/usr/src/homeassistant/homeassistant/components/github/coordinator.py", line 125, in _async_update_data
    response = await self._client.graphql(
  File "/usr/local/lib/python3.9/site-packages/aiogithubapi/github.py", line 225, in graphql
    return await self._client.async_call_api(
  File "/usr/local/lib/python3.9/site-packages/aiogithubapi/client.py", line 140, in async_call_api
    raise exception(message or response.data)
aiogithubapi.exceptions.GitHubAuthenticationException: Bad credentials
2022-03-09 14:35:23 ERROR (MainThread) [homeassistant.components.github] Bad credentials
Traceback (most recent call last):
  File "/usr/src/homeassistant/homeassistant/components/github/coordinator.py", line 125, in _async_update_data
    response = await self._client.graphql(
  File "/usr/local/lib/python3.9/site-packages/aiogithubapi/github.py", line 225, in graphql
    return await self._client.async_call_api(
  File "/usr/local/lib/python3.9/site-packages/aiogithubapi/client.py", line 140, in async_call_api
    raise exception(message or response.data)
aiogithubapi.exceptions.GitHubAuthenticationException: Bad credentials
2022-03-09 14:36:43 ERROR (MainThread) [homeassistant.components.github] Bad credentials
Traceback (most recent call last):
  File "/usr/src/homeassistant/homeassistant/components/github/coordinator.py", line 125, in _async_update_data
    response = await self._client.graphql(
  File "/usr/local/lib/python3.9/site-packages/aiogithubapi/github.py", line 225, in graphql
    return await self._client.async_call_api(
  File "/usr/local/lib/python3.9/site-packages/aiogithubapi/client.py", line 140, in async_call_api
    raise exception(message or response.data)
aiogithubapi.exceptions.GitHubAuthenticationException: Bad credentials
2022-03-09 14:38:04 ERROR (MainThread) [homeassistant.components.github] Bad credentials
Traceback (most recent call last):
  File "/usr/src/homeassistant/homeassistant/components/github/coordinator.py", line 125, in _async_update_data
    response = await self._client.graphql(
  File "/usr/local/lib/python3.9/site-packages/aiogithubapi/github.py", line 225, in graphql
    return await self._client.async_call_api(
  File "/usr/local/lib/python3.9/site-packages/aiogithubapi/client.py", line 140, in async_call_api
    raise exception(message or response.data)
aiogithubapi.exceptions.GitHubAuthenticationException: Bad credentials
2022-03-09 14:38:11 WARNING (MainThread) [homeassistant.components.hassio] Can't read Supervisor data: Container addon_a0d7b954_phpmyadmin is not running
2022-03-09 14:39:24 ERROR (MainThread) [homeassistant.components.github] Bad credentials
Traceback (most recent call last):
  File "/usr/src/homeassistant/homeassistant/components/github/coordinator.py", line 125, in _async_update_data
    response = await self._client.graphql(
  File "/usr/local/lib/python3.9/site-packages/aiogithubapi/github.py", line 225, in graphql
    return await self._client.async_call_api(
  File "/usr/local/lib/python3.9/site-packages/aiogithubapi/client.py", line 140, in async_call_api
    raise exception(message or response.data)
aiogithubapi.exceptions.GitHubAuthenticationException: Bad credentials
2022-03-09 14:40:45 ERROR (MainThread) [homeassistant.components.github] Bad credentials
Traceback (most recent call last):
  File "/usr/src/homeassistant/homeassistant/components/github/coordinator.py", line 125, in _async_update_data
    response = await self._client.graphql(
  File "/usr/local/lib/python3.9/site-packages/aiogithubapi/github.py", line 225, in graphql
    return await self._client.async_call_api(
  File "/usr/local/lib/python3.9/site-packages/aiogithubapi/client.py", line 140, in async_call_api
    raise exception(message or response.data)
aiogithubapi.exceptions.GitHubAuthenticationException: Bad credentials
2022-03-09 14:42:05 ERROR (MainThread) [homeassistant.components.github] Bad credentials
Traceback (most recent call last):
  File "/usr/src/homeassistant/homeassistant/components/github/coordinator.py", line 125, in _async_update_data
    response = await self._client.graphql(
  File "/usr/local/lib/python3.9/site-packages/aiogithubapi/github.py", line 225, in graphql
    return await self._client.async_call_api(
  File "/usr/local/lib/python3.9/site-packages/aiogithubapi/client.py", line 140, in async_call_api
    raise exception(message or response.data)
aiogithubapi.exceptions.GitHubAuthenticationException: Bad credentials
2022-03-09 14:43:11 WARNING (MainThread) [homeassistant.components.hassio] Can't read Supervisor data: Container addon_a0d7b954_phpmyadmin is not running
2022-03-09 14:43:26 ERROR (MainThread) [homeassistant.components.github] Bad credentials
Traceback (most recent call last):
  File "/usr/src/homeassistant/homeassistant/components/github/coordinator.py", line 125, in _async_update_data
    response = await self._client.graphql(
  File "/usr/local/lib/python3.9/site-packages/aiogithubapi/github.py", line 225, in graphql
    return await self._client.async_call_api(
  File "/usr/local/lib/python3.9/site-packages/aiogithubapi/client.py", line 140, in async_call_api
    raise exception(message or response.data)
aiogithubapi.exceptions.GitHubAuthenticationException: Bad credentials
2022-03-09 14:44:47 ERROR (MainThread) [homeassistant.components.github] Bad credentials
Traceback (most recent call last):
  File "/usr/src/homeassistant/homeassistant/components/github/coordinator.py", line 125, in _async_update_data
    response = await self._client.graphql(
  File "/usr/local/lib/python3.9/site-packages/aiogithubapi/github.py", line 225, in graphql
    return await self._client.async_call_api(
  File "/usr/local/lib/python3.9/site-packages/aiogithubapi/client.py", line 140, in async_call_api
    raise exception(message or response.data)
aiogithubapi.exceptions.GitHubAuthenticationException: Bad credentials
2022-03-09 14:46:07 ERROR (MainThread) [homeassistant.components.github] Bad credentials
Traceback (most recent call last):
  File "/usr/src/homeassistant/homeassistant/components/github/coordinator.py", line 125, in _async_update_data
    response = await self._client.graphql(
  File "/usr/local/lib/python3.9/site-packages/aiogithubapi/github.py", line 225, in graphql
    return await self._client.async_call_api(
  File "/usr/local/lib/python3.9/site-packages/aiogithubapi/client.py", line 140, in async_call_api
    raise exception(message or response.data)
aiogithubapi.exceptions.GitHubAuthenticationException: Bad credentials
2022-03-09 14:47:28 ERROR (MainThread) [homeassistant.components.github] Bad credentials
Traceback (most recent call last):
  File "/usr/src/homeassistant/homeassistant/components/github/coordinator.py", line 125, in _async_update_data
    response = await self._client.graphql(
  File "/usr/local/lib/python3.9/site-packages/aiogithubapi/github.py", line 225, in graphql
    return await self._client.async_call_api(
  File "/usr/local/lib/python3.9/site-packages/aiogithubapi/client.py", line 140, in async_call_api
    raise exception(message or response.data)
aiogithubapi.exceptions.GitHubAuthenticationException: Bad credentials
2022-03-09 14:48:11 WARNING (MainThread) [homeassistant.components.hassio] Can't read Supervisor data: Container addon_a0d7b954_phpmyadmin is not running
2022-03-09 14:48:48 ERROR (MainThread) [homeassistant.components.github] Bad credentials
Traceback (most recent call last):
  File "/usr/src/homeassistant/homeassistant/components/github/coordinator.py", line 125, in _async_update_data
    response = await self._client.graphql(
  File "/usr/local/lib/python3.9/site-packages/aiogithubapi/github.py", line 225, in graphql
    return await self._client.async_call_api(
  File "/usr/local/lib/python3.9/site-packages/aiogithubapi/client.py", line 140, in async_call_api
    raise exception(message or response.data)
aiogithubapi.exceptions.GitHubAuthenticationException: Bad credentials
2022-03-09 14:50:09 ERROR (MainThread) [homeassistant.components.github] Bad credentials
Traceback (most recent call last):
  File "/usr/src/homeassistant/homeassistant/components/github/coordinator.py", line 125, in _async_update_data
    response = await self._client.graphql(
  File "/usr/local/lib/python3.9/site-packages/aiogithubapi/github.py", line 225, in graphql
    return await self._client.async_call_api(
  File "/usr/local/lib/python3.9/site-packages/aiogithubapi/client.py", line 140, in async_call_api
    raise exception(message or response.data)
aiogithubapi.exceptions.GitHubAuthenticationException: Bad credentials
2022-03-09 14:51:29 ERROR (MainThread) [homeassistant.components.github] Bad credentials
Traceback (most recent call last):
  File "/usr/src/homeassistant/homeassistant/components/github/coordinator.py", line 125, in _async_update_data
    response = await self._client.graphql(
  File "/usr/local/lib/python3.9/site-packages/aiogithubapi/github.py", line 225, in graphql
    return await self._client.async_call_api(
  File "/usr/local/lib/python3.9/site-packages/aiogithubapi/client.py", line 140, in async_call_api
    raise exception(message or response.data)
aiogithubapi.exceptions.GitHubAuthenticationException: Bad credentials
2022-03-09 14:52:50 ERROR (MainThread) [homeassistant.components.github] Bad credentials
Traceback (most recent call last):
  File "/usr/src/homeassistant/homeassistant/components/github/coordinator.py", line 125, in _async_update_data
    response = await self._client.graphql(
  File "/usr/local/lib/python3.9/site-packages/aiogithubapi/github.py", line 225, in graphql
    return await self._client.async_call_api(
  File "/usr/local/lib/python3.9/site-packages/aiogithubapi/client.py", line 140, in async_call_api
    raise exception(message or response.data)
aiogithubapi.exceptions.GitHubAuthenticationException: Bad credentials
2022-03-09 14:53:11 WARNING (MainThread) [homeassistant.components.hassio] Can't read Supervisor data: Container addon_a0d7b954_phpmyadmin is not running
2022-03-09 14:54:10 ERROR (MainThread) [homeassistant.components.github] Bad credentials
Traceback (most recent call last):
  File "/usr/src/homeassistant/homeassistant/components/github/coordinator.py", line 125, in _async_update_data
    response = await self._client.graphql(
  File "/usr/local/lib/python3.9/site-packages/aiogithubapi/github.py", line 225, in graphql
    return await self._client.async_call_api(
  File "/usr/local/lib/python3.9/site-packages/aiogithubapi/client.py", line 140, in async_call_api
    raise exception(message or response.data)
aiogithubapi.exceptions.GitHubAuthenticationException: Bad credentials
2022-03-09 14:55:31 ERROR (MainThread) [homeassistant.components.github] Bad credentials
Traceback (most recent call last):
  File "/usr/src/homeassistant/homeassistant/components/github/coordinator.py", line 125, in _async_update_data
    response = await self._client.graphql(
  File "/usr/local/lib/python3.9/site-packages/aiogithubapi/github.py", line 225, in graphql
    return await self._client.async_call_api(
  File "/usr/local/lib/python3.9/site-packages/aiogithubapi/client.py", line 140, in async_call_api
    raise exception(message or response.data)
aiogithubapi.exceptions.GitHubAuthenticationException: Bad credentials
2022-03-09 14:56:52 ERROR (MainThread) [homeassistant.components.github] Bad credentials
Traceback (most recent call last):
  File "/usr/src/homeassistant/homeassistant/components/github/coordinator.py", line 125, in _async_update_data
    response = await self._client.graphql(
  File "/usr/local/lib/python3.9/site-packages/aiogithubapi/github.py", line 225, in graphql
    return await self._client.async_call_api(
  File "/usr/local/lib/python3.9/site-packages/aiogithubapi/client.py", line 140, in async_call_api
    raise exception(message or response.data)
aiogithubapi.exceptions.GitHubAuthenticationException: Bad credentials
2022-03-09 14:58:11 WARNING (MainThread) [homeassistant.components.hassio] Can't read Supervisor data: Container addon_a0d7b954_phpmyadmin is not running
2022-03-09 14:58:12 ERROR (MainThread) [homeassistant.components.github] Bad credentials
Traceback (most recent call last):
  File "/usr/src/homeassistant/homeassistant/components/github/coordinator.py", line 125, in _async_update_data
    response = await self._client.graphql(
  File "/usr/local/lib/python3.9/site-packages/aiogithubapi/github.py", line 225, in graphql
    return await self._client.async_call_api(
  File "/usr/local/lib/python3.9/site-packages/aiogithubapi/client.py", line 140, in async_call_api
    raise exception(message or response.data)
aiogithubapi.exceptions.GitHubAuthenticationException: Bad credentials
2022-03-09 14:59:33 ERROR (MainThread) [homeassistant.components.github] Bad credentials
Traceback (most recent call last):
  File "/usr/src/homeassistant/homeassistant/components/github/coordinator.py", line 125, in _async_update_data
    response = await self._client.graphql(
  File "/usr/local/lib/python3.9/site-packages/aiogithubapi/github.py", line 225, in graphql
    return await self._client.async_call_api(
  File "/usr/local/lib/python3.9/site-packages/aiogithubapi/client.py", line 140, in async_call_api
    raise exception(message or response.data)
aiogithubapi.exceptions.GitHubAuthenticationException: Bad credentials
2022-03-09 15:00:53 ERROR (MainThread) [homeassistant.components.github] Bad credentials
Traceback (most recent call last):
  File "/usr/src/homeassistant/homeassistant/components/github/coordinator.py", line 125, in _async_update_data
    response = await self._client.graphql(
  File "/usr/local/lib/python3.9/site-packages/aiogithubapi/github.py", line 225, in graphql
    return await self._client.async_call_api(
  File "/usr/local/lib/python3.9/site-packages/aiogithubapi/client.py", line 140, in async_call_api
    raise exception(message or response.data)
aiogithubapi.exceptions.GitHubAuthenticationException: Bad credentials
2022-03-09 15:02:14 ERROR (MainThread) [homeassistant.components.github] Bad credentials
Traceback (most recent call last):
  File "/usr/src/homeassistant/homeassistant/components/github/coordinator.py", line 125, in _async_update_data
    response = await self._client.graphql(
  File "/usr/local/lib/python3.9/site-packages/aiogithubapi/github.py", line 225, in graphql
    return await self._client.async_call_api(
  File "/usr/local/lib/python3.9/site-packages/aiogithubapi/client.py", line 140, in async_call_api
    raise exception(message or response.data)
aiogithubapi.exceptions.GitHubAuthenticationException: Bad credentials
2022-03-09 15:03:11 WARNING (MainThread) [homeassistant.components.hassio] Can't read Supervisor data: Container addon_a0d7b954_phpmyadmin is not running
2022-03-09 15:03:34 ERROR (MainThread) [homeassistant.components.github] Bad credentials
Traceback (most recent call last):
  File "/usr/src/homeassistant/homeassistant/components/github/coordinator.py", line 125, in _async_update_data
    response = await self._client.graphql(
  File "/usr/local/lib/python3.9/site-packages/aiogithubapi/github.py", line 225, in graphql
    return await self._client.async_call_api(
  File "/usr/local/lib/python3.9/site-packages/aiogithubapi/client.py", line 140, in async_call_api
    raise exception(message or response.data)
aiogithubapi.exceptions.GitHubAuthenticationException: Bad credentials
2022-03-09 15:04:55 ERROR (MainThread) [homeassistant.components.github] Bad credentials
Traceback (most recent call last):
  File "/usr/src/homeassistant/homeassistant/components/github/coordinator.py", line 125, in _async_update_data
    response = await self._client.graphql(
  File "/usr/local/lib/python3.9/site-packages/aiogithubapi/github.py", line 225, in graphql
    return await self._client.async_call_api(
  File "/usr/local/lib/python3.9/site-packages/aiogithubapi/client.py", line 140, in async_call_api
    raise exception(message or response.data)
aiogithubapi.exceptions.GitHubAuthenticationException: Bad credentials
2022-03-09 15:06:16 ERROR (MainThread) [homeassistant.components.github] Bad credentials
Traceback (most recent call last):
  File "/usr/src/homeassistant/homeassistant/components/github/coordinator.py", line 125, in _async_update_data
    response = await self._client.graphql(
  File "/usr/local/lib/python3.9/site-packages/aiogithubapi/github.py", line 225, in graphql
    return await self._client.async_call_api(
  File "/usr/local/lib/python3.9/site-packages/aiogithubapi/client.py", line 140, in async_call_api
    raise exception(message or response.data)
aiogithubapi.exceptions.GitHubAuthenticationException: Bad credentials
2022-03-09 15:07:36 ERROR (MainThread) [homeassistant.components.github] Bad credentials
Traceback (most recent call last):
  File "/usr/src/homeassistant/homeassistant/components/github/coordinator.py", line 125, in _async_update_data
    response = await self._client.graphql(
  File "/usr/local/lib/python3.9/site-packages/aiogithubapi/github.py", line 225, in graphql
    return await self._client.async_call_api(
  File "/usr/local/lib/python3.9/site-packages/aiogithubapi/client.py", line 140, in async_call_api
    raise exception(message or response.data)
aiogithubapi.exceptions.GitHubAuthenticationException: Bad credentials
2022-03-09 15:08:11 WARNING (MainThread) [homeassistant.components.hassio] Can't read Supervisor data: Container addon_a0d7b954_phpmyadmin is not running
2022-03-09 15:08:57 ERROR (MainThread) [homeassistant.components.github] Bad credentials
Traceback (most recent call last):
  File "/usr/src/homeassistant/homeassistant/components/github/coordinator.py", line 125, in _async_update_data
    response = await self._client.graphql(
  File "/usr/local/lib/python3.9/site-packages/aiogithubapi/github.py", line 225, in graphql
    return await self._client.async_call_api(
  File "/usr/local/lib/python3.9/site-packages/aiogithubapi/client.py", line 140, in async_call_api
    raise exception(message or response.data)
aiogithubapi.exceptions.GitHubAuthenticationException: Bad credentials
2022-03-09 15:10:18 ERROR (MainThread) [homeassistant.components.github] Bad credentials
Traceback (most recent call last):
  File "/usr/src/homeassistant/homeassistant/components/github/coordinator.py", line 125, in _async_update_data
    response = await self._client.graphql(
  File "/usr/local/lib/python3.9/site-packages/aiogithubapi/github.py", line 225, in graphql
    return await self._client.async_call_api(
  File "/usr/local/lib/python3.9/site-packages/aiogithubapi/client.py", line 140, in async_call_api
    raise exception(message or response.data)
aiogithubapi.exceptions.GitHubAuthenticationException: Bad credentials
2022-03-09 15:11:38 ERROR (MainThread) [homeassistant.components.github] Bad credentials
Traceback (most recent call last):
  File "/usr/src/homeassistant/homeassistant/components/github/coordinator.py", line 125, in _async_update_data
    response = await self._client.graphql(
  File "/usr/local/lib/python3.9/site-packages/aiogithubapi/github.py", line 225, in graphql
    return await self._client.async_call_api(
  File "/usr/local/lib/python3.9/site-packages/aiogithubapi/client.py", line 140, in async_call_api
    raise exception(message or response.data)
aiogithubapi.exceptions.GitHubAuthenticationException: Bad credentials
2022-03-09 15:12:59 ERROR (MainThread) [homeassistant.components.github] Bad credentials
Traceback (most recent call last):
  File "/usr/src/homeassistant/homeassistant/components/github/coordinator.py", line 125, in _async_update_data
    response = await self._client.graphql(
  File "/usr/local/lib/python3.9/site-packages/aiogithubapi/github.py", line 225, in graphql
    return await self._client.async_call_api(
  File "/usr/local/lib/python3.9/site-packages/aiogithubapi/client.py", line 140, in async_call_api
    raise exception(message or response.data)
aiogithubapi.exceptions.GitHubAuthenticationException: Bad credentials
2022-03-09 15:14:19 ERROR (MainThread) [homeassistant.components.github] Bad credentials
Traceback (most recent call last):
  File "/usr/src/homeassistant/homeassistant/components/github/coordinator.py", line 125, in _async_update_data
    response = await self._client.graphql(
  File "/usr/local/lib/python3.9/site-packages/aiogithubapi/github.py", line 225, in graphql
    return await self._client.async_call_api(
  File "/usr/local/lib/python3.9/site-packages/aiogithubapi/client.py", line 140, in async_call_api
    raise exception(message or response.data)
aiogithubapi.exceptions.GitHubAuthenticationException: Bad credentials
2022-03-09 15:15:40 ERROR (MainThread) [homeassistant.components.github] Bad credentials
Traceback (most recent call last):
  File "/usr/src/homeassistant/homeassistant/components/github/coordinator.py", line 125, in _async_update_data
    response = await self._client.graphql(
  File "/usr/local/lib/python3.9/site-packages/aiogithubapi/github.py", line 225, in graphql
    return await self._client.async_call_api(
  File "/usr/local/lib/python3.9/site-packages/aiogithubapi/client.py", line 140, in async_call_api
    raise exception(message or response.data)
aiogithubapi.exceptions.GitHubAuthenticationException: Bad credentials
2022-03-09 15:17:00 ERROR (MainThread) [homeassistant.components.github] Bad credentials
Traceback (most recent call last):
  File "/usr/src/homeassistant/homeassistant/components/github/coordinator.py", line 125, in _async_update_data
    response = await self._client.graphql(
  File "/usr/local/lib/python3.9/site-packages/aiogithubapi/github.py", line 225, in graphql
    return await self._client.async_call_api(
  File "/usr/local/lib/python3.9/site-packages/aiogithubapi/client.py", line 140, in async_call_api
    raise exception(message or response.data)
aiogithubapi.exceptions.GitHubAuthenticationException: Bad credentials
2022-03-09 15:18:21 ERROR (MainThread) [homeassistant.components.github] Bad credentials
Traceback (most recent call last):
  File "/usr/src/homeassistant/homeassistant/components/github/coordinator.py", line 125, in _async_update_data
    response = await self._client.graphql(
  File "/usr/local/lib/python3.9/site-packages/aiogithubapi/github.py", line 225, in graphql
    return await self._client.async_call_api(
  File "/usr/local/lib/python3.9/site-packages/aiogithubapi/client.py", line 140, in async_call_api
    raise exception(message or response.data)
aiogithubapi.exceptions.GitHubAuthenticationException: Bad credentials
2022-03-09 15:19:42 ERROR (MainThread) [homeassistant.components.github] Bad credentials
Traceback (most recent call last):
  File "/usr/src/homeassistant/homeassistant/components/github/coordinator.py", line 125, in _async_update_data
    response = await self._client.graphql(
  File "/usr/local/lib/python3.9/site-packages/aiogithubapi/github.py", line 225, in graphql
    return await self._client.async_call_api(
  File "/usr/local/lib/python3.9/site-packages/aiogithubapi/client.py", line 140, in async_call_api
    raise exception(message or response.data)
aiogithubapi.exceptions.GitHubAuthenticationException: Bad credentials
2022-03-09 15:21:02 ERROR (MainThread) [homeassistant.components.github] Bad credentials
Traceback (most recent call last):
  File "/usr/src/homeassistant/homeassistant/components/github/coordinator.py", line 125, in _async_update_data
    response = await self._client.graphql(
  File "/usr/local/lib/python3.9/site-packages/aiogithubapi/github.py", line 225, in graphql
    return await self._client.async_call_api(
  File "/usr/local/lib/python3.9/site-packages/aiogithubapi/client.py", line 140, in async_call_api
    raise exception(message or response.data)
aiogithubapi.exceptions.GitHubAuthenticationException: Bad credentials
2022-03-09 15:22:23 ERROR (MainThread) [homeassistant.components.github] Bad credentials
Traceback (most recent call last):
  File "/usr/src/homeassistant/homeassistant/components/github/coordinator.py", line 125, in _async_update_data
    response = await self._client.graphql(
  File "/usr/local/lib/python3.9/site-packages/aiogithubapi/github.py", line 225, in graphql
    return await self._client.async_call_api(
  File "/usr/local/lib/python3.9/site-packages/aiogithubapi/client.py", line 140, in async_call_api
    raise exception(message or response.data)
aiogithubapi.exceptions.GitHubAuthenticationException: Bad credentials
2022-03-09 15:23:16 WARNING (MainThread) [homeassistant.components.hassio] Can't read Supervisor data: Container addon_a0d7b954_phpmyadmin is not running
2022-03-09 15:23:43 ERROR (MainThread) [homeassistant.components.github] Bad credentials
Traceback (most recent call last):
  File "/usr/src/homeassistant/homeassistant/components/github/coordinator.py", line 125, in _async_update_data
    response = await self._client.graphql(
  File "/usr/local/lib/python3.9/site-packages/aiogithubapi/github.py", line 225, in graphql
    return await self._client.async_call_api(
  File "/usr/local/lib/python3.9/site-packages/aiogithubapi/client.py", line 140, in async_call_api
    raise exception(message or response.data)
aiogithubapi.exceptions.GitHubAuthenticationException: Bad credentials
2022-03-09 15:25:04 ERROR (MainThread) [homeassistant.components.github] Bad credentials
Traceback (most recent call last):
  File "/usr/src/homeassistant/homeassistant/components/github/coordinator.py", line 125, in _async_update_data
    response = await self._client.graphql(
  File "/usr/local/lib/python3.9/site-packages/aiogithubapi/github.py", line 225, in graphql
    return await self._client.async_call_api(
  File "/usr/local/lib/python3.9/site-packages/aiogithubapi/client.py", line 140, in async_call_api
    raise exception(message or response.data)
aiogithubapi.exceptions.GitHubAuthenticationException: Bad credentials
2022-03-09 15:26:24 ERROR (MainThread) [homeassistant.components.github] Bad credentials
Traceback (most recent call last):
  File "/usr/src/homeassistant/homeassistant/components/github/coordinator.py", line 125, in _async_update_data
    response = await self._client.graphql(
  File "/usr/local/lib/python3.9/site-packages/aiogithubapi/github.py", line 225, in graphql
    return await self._client.async_call_api(
  File "/usr/local/lib/python3.9/site-packages/aiogithubapi/client.py", line 140, in async_call_api
    raise exception(message or response.data)
aiogithubapi.exceptions.GitHubAuthenticationException: Bad credentials
2022-03-09 15:27:45 ERROR (MainThread) [homeassistant.components.github] Bad credentials
Traceback (most recent call last):
  File "/usr/src/homeassistant/homeassistant/components/github/coordinator.py", line 125, in _async_update_data
    response = await self._client.graphql(
  File "/usr/local/lib/python3.9/site-packages/aiogithubapi/github.py", line 225, in graphql
    return await self._client.async_call_api(
  File "/usr/local/lib/python3.9/site-packages/aiogithubapi/client.py", line 140, in async_call_api
    raise exception(message or response.data)
aiogithubapi.exceptions.GitHubAuthenticationException: Bad credentials
2022-03-09 15:28:16 WARNING (MainThread) [homeassistant.components.hassio] Can't read Supervisor data: Container addon_a0d7b954_phpmyadmin is not running
2022-03-09 15:29:06 ERROR (MainThread) [homeassistant.components.github] Bad credentials
Traceback (most recent call last):
  File "/usr/src/homeassistant/homeassistant/components/github/coordinator.py", line 125, in _async_update_data
    response = await self._client.graphql(
  File "/usr/local/lib/python3.9/site-packages/aiogithubapi/github.py", line 225, in graphql
    return await self._client.async_call_api(
  File "/usr/local/lib/python3.9/site-packages/aiogithubapi/client.py", line 140, in async_call_api
    raise exception(message or response.data)
aiogithubapi.exceptions.GitHubAuthenticationException: Bad credentials
2022-03-09 15:30:26 ERROR (MainThread) [homeassistant.components.github] Bad credentials
Traceback (most recent call last):
  File "/usr/src/homeassistant/homeassistant/components/github/coordinator.py", line 125, in _async_update_data
    response = await self._client.graphql(
  File "/usr/local/lib/python3.9/site-packages/aiogithubapi/github.py", line 225, in graphql
    return await self._client.async_call_api(
  File "/usr/local/lib/python3.9/site-packages/aiogithubapi/client.py", line 140, in async_call_api
    raise exception(message or response.data)
aiogithubapi.exceptions.GitHubAuthenticationException: Bad credentials
2022-03-09 15:33:12 ERROR (MainThread) [homeassistant.components.github] Bad credentials
Traceback (most recent call last):
  File "/usr/src/homeassistant/homeassistant/components/github/coordinator.py", line 125, in _async_update_data
    response = await self._client.graphql(
  File "/usr/local/lib/python3.9/site-packages/aiogithubapi/github.py", line 225, in graphql
    return await self._client.async_call_api(
  File "/usr/local/lib/python3.9/site-packages/aiogithubapi/client.py", line 140, in async_call_api
    raise exception(message or response.data)
aiogithubapi.exceptions.GitHubAuthenticationException: Bad credentials
2022-03-09 15:33:16 WARNING (MainThread) [homeassistant.components.hassio] Can't read Supervisor data: Container addon_a0d7b954_phpmyadmin is not running
2022-03-09 15:34:32 ERROR (MainThread) [homeassistant.components.github] Bad credentials
Traceback (most recent call last):
  File "/usr/src/homeassistant/homeassistant/components/github/coordinator.py", line 125, in _async_update_data
    response = await self._client.graphql(
  File "/usr/local/lib/python3.9/site-packages/aiogithubapi/github.py", line 225, in graphql
    return await self._client.async_call_api(
  File "/usr/local/lib/python3.9/site-packages/aiogithubapi/client.py", line 140, in async_call_api
    raise exception(message or response.data)
aiogithubapi.exceptions.GitHubAuthenticationException: Bad credentials
2022-03-09 15:35:53 ERROR (MainThread) [homeassistant.components.github] Bad credentials
Traceback (most recent call last):
  File "/usr/src/homeassistant/homeassistant/components/github/coordinator.py", line 125, in _async_update_data
    response = await self._client.graphql(
  File "/usr/local/lib/python3.9/site-packages/aiogithubapi/github.py", line 225, in graphql
    return await self._client.async_call_api(
  File "/usr/local/lib/python3.9/site-packages/aiogithubapi/client.py", line 140, in async_call_api
    raise exception(message or response.data)
aiogithubapi.exceptions.GitHubAuthenticationException: Bad credentials
2022-03-09 15:37:14 ERROR (MainThread) [homeassistant.components.github] Bad credentials
Traceback (most recent call last):
  File "/usr/src/homeassistant/homeassistant/components/github/coordinator.py", line 125, in _async_update_data
    response = await self._client.graphql(
  File "/usr/local/lib/python3.9/site-packages/aiogithubapi/github.py", line 225, in graphql
    return await self._client.async_call_api(
  File "/usr/local/lib/python3.9/site-packages/aiogithubapi/client.py", line 140, in async_call_api
    raise exception(message or response.data)
aiogithubapi.exceptions.GitHubAuthenticationException: Bad credentials
2022-03-09 15:38:16 WARNING (MainThread) [homeassistant.components.hassio] Can't read Supervisor data: Container addon_a0d7b954_phpmyadmin is not running
2022-03-09 15:38:34 ERROR (MainThread) [homeassistant.components.github] Bad credentials
Traceback (most recent call last):
  File "/usr/src/homeassistant/homeassistant/components/github/coordinator.py", line 125, in _async_update_data
    response = await self._client.graphql(
  File "/usr/local/lib/python3.9/site-packages/aiogithubapi/github.py", line 225, in graphql
    return await self._client.async_call_api(
  File "/usr/local/lib/python3.9/site-packages/aiogithubapi/client.py", line 140, in async_call_api
    raise exception(message or response.data)
aiogithubapi.exceptions.GitHubAuthenticationException: Bad credentials
2022-03-09 15:39:55 ERROR (MainThread) [homeassistant.components.github] Bad credentials
Traceback (most recent call last):
  File "/usr/src/homeassistant/homeassistant/components/github/coordinator.py", line 125, in _async_update_data
    response = await self._client.graphql(
  File "/usr/local/lib/python3.9/site-packages/aiogithubapi/github.py", line 225, in graphql
    return await self._client.async_call_api(
  File "/usr/local/lib/python3.9/site-packages/aiogithubapi/client.py", line 140, in async_call_api
    raise exception(message or response.data)
aiogithubapi.exceptions.GitHubAuthenticationException: Bad credentials
2022-03-09 15:41:15 ERROR (MainThread) [homeassistant.components.github] Bad credentials
Traceback (most recent call last):
  File "/usr/src/homeassistant/homeassistant/components/github/coordinator.py", line 125, in _async_update_data
    response = await self._client.graphql(
  File "/usr/local/lib/python3.9/site-packages/aiogithubapi/github.py", line 225, in graphql
    return await self._client.async_call_api(
  File "/usr/local/lib/python3.9/site-packages/aiogithubapi/client.py", line 140, in async_call_api
    raise exception(message or response.data)
aiogithubapi.exceptions.GitHubAuthenticationException: Bad credentials
2022-03-09 15:42:36 ERROR (MainThread) [homeassistant.components.github] Bad credentials
Traceback (most recent call last):
  File "/usr/src/homeassistant/homeassistant/components/github/coordinator.py", line 125, in _async_update_data
    response = await self._client.graphql(
  File "/usr/local/lib/python3.9/site-packages/aiogithubapi/github.py", line 225, in graphql
    return await self._client.async_call_api(
  File "/usr/local/lib/python3.9/site-packages/aiogithubapi/client.py", line 140, in async_call_api
    raise exception(message or response.data)
aiogithubapi.exceptions.GitHubAuthenticationException: Bad credentials
2022-03-09 15:43:57 ERROR (MainThread) [homeassistant.components.github] Bad credentials
Traceback (most recent call last):
  File "/usr/src/homeassistant/homeassistant/components/github/coordinator.py", line 125, in _async_update_data
    response = await self._client.graphql(
  File "/usr/local/lib/python3.9/site-packages/aiogithubapi/github.py", line 225, in graphql
    return await self._client.async_call_api(
  File "/usr/local/lib/python3.9/site-packages/aiogithubapi/client.py", line 140, in async_call_api
    raise exception(message or response.data)
aiogithubapi.exceptions.GitHubAuthenticationException: Bad credentials
2022-03-09 15:45:17 ERROR (MainThread) [homeassistant.components.github] Bad credentials
Traceback (most recent call last):
  File "/usr/src/homeassistant/homeassistant/components/github/coordinator.py", line 125, in _async_update_data
    response = await self._client.graphql(
  File "/usr/local/lib/python3.9/site-packages/aiogithubapi/github.py", line 225, in graphql
    return await self._client.async_call_api(
  File "/usr/local/lib/python3.9/site-packages/aiogithubapi/client.py", line 140, in async_call_api
    raise exception(message or response.data)
aiogithubapi.exceptions.GitHubAuthenticationException: Bad credentials
2022-03-09 15:46:38 ERROR (MainThread) [homeassistant.components.github] Bad credentials
Traceback (most recent call last):
  File "/usr/src/homeassistant/homeassistant/components/github/coordinator.py", line 125, in _async_update_data
    response = await self._client.graphql(
  File "/usr/local/lib/python3.9/site-packages/aiogithubapi/github.py", line 225, in graphql
    return await self._client.async_call_api(
  File "/usr/local/lib/python3.9/site-packages/aiogithubapi/client.py", line 140, in async_call_api
    raise exception(message or response.data)
aiogithubapi.exceptions.GitHubAuthenticationException: Bad credentials
2022-03-09 15:47:58 ERROR (MainThread) [homeassistant.components.github] Bad credentials
Traceback (most recent call last):
  File "/usr/src/homeassistant/homeassistant/components/github/coordinator.py", line 125, in _async_update_data
    response = await self._client.graphql(
  File "/usr/local/lib/python3.9/site-packages/aiogithubapi/github.py", line 225, in graphql
    return await self._client.async_call_api(
  File "/usr/local/lib/python3.9/site-packages/aiogithubapi/client.py", line 140, in async_call_api
    raise exception(message or response.data)
aiogithubapi.exceptions.GitHubAuthenticationException: Bad credentials
2022-03-09 15:48:18 WARNING (MainThread) [homeassistant.components.hassio] Can't read Supervisor data: Container addon_a0d7b954_phpmyadmin is not running
2022-03-09 15:49:19 ERROR (MainThread) [homeassistant.components.github] Bad credentials
Traceback (most recent call last):
  File "/usr/src/homeassistant/homeassistant/components/github/coordinator.py", line 125, in _async_update_data
    response = await self._client.graphql(
  File "/usr/local/lib/python3.9/site-packages/aiogithubapi/github.py", line 225, in graphql
    return await self._client.async_call_api(
  File "/usr/local/lib/python3.9/site-packages/aiogithubapi/client.py", line 140, in async_call_api
    raise exception(message or response.data)
aiogithubapi.exceptions.GitHubAuthenticationException: Bad credentials
2022-03-09 15:50:40 ERROR (MainThread) [homeassistant.components.github] Bad credentials
Traceback (most recent call last):
  File "/usr/src/homeassistant/homeassistant/components/github/coordinator.py", line 125, in _async_update_data
    response = await self._client.graphql(
  File "/usr/local/lib/python3.9/site-packages/aiogithubapi/github.py", line 225, in graphql
    return await self._client.async_call_api(
  File "/usr/local/lib/python3.9/site-packages/aiogithubapi/client.py", line 140, in async_call_api
    raise exception(message or response.data)
aiogithubapi.exceptions.GitHubAuthenticationException: Bad credentials
2022-03-09 15:52:00 ERROR (MainThread) [homeassistant.components.github] Bad credentials
Traceback (most recent call last):
  File "/usr/src/homeassistant/homeassistant/components/github/coordinator.py", line 125, in _async_update_data
    response = await self._client.graphql(
  File "/usr/local/lib/python3.9/site-packages/aiogithubapi/github.py", line 225, in graphql
    return await self._client.async_call_api(
  File "/usr/local/lib/python3.9/site-packages/aiogithubapi/client.py", line 140, in async_call_api
    raise exception(message or response.data)
aiogithubapi.exceptions.GitHubAuthenticationException: Bad credentials
2022-03-09 15:53:18 WARNING (MainThread) [homeassistant.components.hassio] Can't read Supervisor data: Container addon_a0d7b954_phpmyadmin is not running
2022-03-09 15:53:21 ERROR (MainThread) [homeassistant.components.github] Bad credentials
Traceback (most recent call last):
  File "/usr/src/homeassistant/homeassistant/components/github/coordinator.py", line 125, in _async_update_data
    response = await self._client.graphql(
  File "/usr/local/lib/python3.9/site-packages/aiogithubapi/github.py", line 225, in graphql
    return await self._client.async_call_api(
  File "/usr/local/lib/python3.9/site-packages/aiogithubapi/client.py", line 140, in async_call_api
    raise exception(message or response.data)
aiogithubapi.exceptions.GitHubAuthenticationException: Bad credentials
2022-03-09 15:54:42 ERROR (MainThread) [homeassistant.components.github] Bad credentials
Traceback (most recent call last):
  File "/usr/src/homeassistant/homeassistant/components/github/coordinator.py", line 125, in _async_update_data
    response = await self._client.graphql(
  File "/usr/local/lib/python3.9/site-packages/aiogithubapi/github.py", line 225, in graphql
    return await self._client.async_call_api(
  File "/usr/local/lib/python3.9/site-packages/aiogithubapi/client.py", line 140, in async_call_api
    raise exception(message or response.data)
aiogithubapi.exceptions.GitHubAuthenticationException: Bad credentials
2022-03-09 15:56:02 ERROR (MainThread) [homeassistant.components.github] Bad credentials
Traceback (most recent call last):
  File "/usr/src/homeassistant/homeassistant/components/github/coordinator.py", line 125, in _async_update_data
    response = await self._client.graphql(
  File "/usr/local/lib/python3.9/site-packages/aiogithubapi/github.py", line 225, in graphql
    return await self._client.async_call_api(
  File "/usr/local/lib/python3.9/site-packages/aiogithubapi/client.py", line 140, in async_call_api
    raise exception(message or response.data)
aiogithubapi.exceptions.GitHubAuthenticationException: Bad credentials
2022-03-09 15:57:23 ERROR (MainThread) [homeassistant.components.github] Bad credentials
Traceback (most recent call last):
  File "/usr/src/homeassistant/homeassistant/components/github/coordinator.py", line 125, in _async_update_data
    response = await self._client.graphql(
  File "/usr/local/lib/python3.9/site-packages/aiogithubapi/github.py", line 225, in graphql
    return await self._client.async_call_api(
  File "/usr/local/lib/python3.9/site-packages/aiogithubapi/client.py", line 140, in async_call_api
    raise exception(message or response.data)
aiogithubapi.exceptions.GitHubAuthenticationException: Bad credentials
2022-03-09 15:58:18 WARNING (MainThread) [homeassistant.components.hassio] Can't read Supervisor data: Container addon_a0d7b954_phpmyadmin is not running
2022-03-09 15:58:43 ERROR (MainThread) [homeassistant.components.github] Bad credentials
Traceback (most recent call last):
  File "/usr/src/homeassistant/homeassistant/components/github/coordinator.py", line 125, in _async_update_data
    response = await self._client.graphql(
  File "/usr/local/lib/python3.9/site-packages/aiogithubapi/github.py", line 225, in graphql
    return await self._client.async_call_api(
  File "/usr/local/lib/python3.9/site-packages/aiogithubapi/client.py", line 140, in async_call_api
    raise exception(message or response.data)
aiogithubapi.exceptions.GitHubAuthenticationException: Bad credentials
2022-03-09 16:00:04 ERROR (MainThread) [homeassistant.components.github] Bad credentials
Traceback (most recent call last):
  File "/usr/src/homeassistant/homeassistant/components/github/coordinator.py", line 125, in _async_update_data
    response = await self._client.graphql(
  File "/usr/local/lib/python3.9/site-packages/aiogithubapi/github.py", line 225, in graphql
    return await self._client.async_call_api(
  File "/usr/local/lib/python3.9/site-packages/aiogithubapi/client.py", line 140, in async_call_api
    raise exception(message or response.data)
aiogithubapi.exceptions.GitHubAuthenticationException: Bad credentials
2022-03-09 16:01:25 ERROR (MainThread) [homeassistant.components.github] Bad credentials
Traceback (most recent call last):
  File "/usr/src/homeassistant/homeassistant/components/github/coordinator.py", line 125, in _async_update_data
    response = await self._client.graphql(
  File "/usr/local/lib/python3.9/site-packages/aiogithubapi/github.py", line 225, in graphql
    return await self._client.async_call_api(
  File "/usr/local/lib/python3.9/site-packages/aiogithubapi/client.py", line 140, in async_call_api
    raise exception(message or response.data)
aiogithubapi.exceptions.GitHubAuthenticationException: Bad credentials
2022-03-09 16:02:45 ERROR (MainThread) [homeassistant.components.github] Bad credentials
Traceback (most recent call last):
  File "/usr/src/homeassistant/homeassistant/components/github/coordinator.py", line 125, in _async_update_data
    response = await self._client.graphql(
  File "/usr/local/lib/python3.9/site-packages/aiogithubapi/github.py", line 225, in graphql
    return await self._client.async_call_api(
  File "/usr/local/lib/python3.9/site-packages/aiogithubapi/client.py", line 140, in async_call_api
    raise exception(message or response.data)
aiogithubapi.exceptions.GitHubAuthenticationException: Bad credentials
2022-03-09 16:03:18 WARNING (MainThread) [homeassistant.components.hassio] Can't read Supervisor data: Container addon_a0d7b954_phpmyadmin is not running
2022-03-09 16:03:26 ERROR (MainThread) [homeassistant.helpers.script.websocket_api_script] websocket_api script: Error executing script. Invalid data for call_service at pos 1: required key not provided @ data['input']
2022-03-09 16:03:26 ERROR (MainThread) [homeassistant.components.websocket_api.http.connection] [140336690349056] Error handling message: required key not provided @ data['addon']. Got None
required key not provided @ data['input']. Got None
2022-03-09 16:04:06 ERROR (MainThread) [homeassistant.components.github] Bad credentials
Traceback (most recent call last):
  File "/usr/src/homeassistant/homeassistant/components/github/coordinator.py", line 125, in _async_update_data
    response = await self._client.graphql(
  File "/usr/local/lib/python3.9/site-packages/aiogithubapi/github.py", line 225, in graphql
    return await self._client.async_call_api(
  File "/usr/local/lib/python3.9/site-packages/aiogithubapi/client.py", line 140, in async_call_api
    raise exception(message or response.data)
aiogithubapi.exceptions.GitHubAuthenticationException: Bad credentials
2022-03-09 16:05:26 ERROR (MainThread) [homeassistant.components.github] Bad credentials
Traceback (most recent call last):
  File "/usr/src/homeassistant/homeassistant/components/github/coordinator.py", line 125, in _async_update_data
    response = await self._client.graphql(
  File "/usr/local/lib/python3.9/site-packages/aiogithubapi/github.py", line 225, in graphql
    return await self._client.async_call_api(
  File "/usr/local/lib/python3.9/site-packages/aiogithubapi/client.py", line 140, in async_call_api
    raise exception(message or response.data)
aiogithubapi.exceptions.GitHubAuthenticationException: Bad credentials
2022-03-09 16:06:47 ERROR (MainThread) [homeassistant.components.github] Bad credentials
Traceback (most recent call last):
  File "/usr/src/homeassistant/homeassistant/components/github/coordinator.py", line 125, in _async_update_data
    response = await self._client.graphql(
  File "/usr/local/lib/python3.9/site-packages/aiogithubapi/github.py", line 225, in graphql
    return await self._client.async_call_api(
  File "/usr/local/lib/python3.9/site-packages/aiogithubapi/client.py", line 140, in async_call_api
    raise exception(message or response.data)
aiogithubapi.exceptions.GitHubAuthenticationException: Bad credentials
2022-03-09 16:08:07 ERROR (MainThread) [homeassistant.components.github] Bad credentials
Traceback (most recent call last):
  File "/usr/src/homeassistant/homeassistant/components/github/coordinator.py", line 125, in _async_update_data
    response = await self._client.graphql(
  File "/usr/local/lib/python3.9/site-packages/aiogithubapi/github.py", line 225, in graphql
    return await self._client.async_call_api(
  File "/usr/local/lib/python3.9/site-packages/aiogithubapi/client.py", line 140, in async_call_api
    raise exception(message or response.data)
aiogithubapi.exceptions.GitHubAuthenticationException: Bad credentials
2022-03-09 16:09:28 ERROR (MainThread) [homeassistant.components.github] Bad credentials
Traceback (most recent call last):
  File "/usr/src/homeassistant/homeassistant/components/github/coordinator.py", line 125, in _async_update_data
    response = await self._client.graphql(
  File "/usr/local/lib/python3.9/site-packages/aiogithubapi/github.py", line 225, in graphql
    return await self._client.async_call_api(
  File "/usr/local/lib/python3.9/site-packages/aiogithubapi/client.py", line 140, in async_call_api
    raise exception(message or response.data)
aiogithubapi.exceptions.GitHubAuthenticationException: Bad credentials
2022-03-09 16:10:37 ERROR (MainThread) [homeassistant.components.automation.home_assistant_config_folder_push_to_github] Home assistant config folder push to github: Error executing script. Invalid data for call_service at pos 1: required key not provided @ data['input']
2022-03-09 16:10:37 ERROR (MainThread) [homeassistant.components.automation.home_assistant_config_folder_push_to_github] Error while executing automation automation.home_assistant_config_folder_push_to_github: required key not provided @ data['input']
2022-03-09 16:10:49 ERROR (MainThread) [homeassistant.components.github] Bad credentials
Traceback (most recent call last):
  File "/usr/src/homeassistant/homeassistant/components/github/coordinator.py", line 125, in _async_update_data
    response = await self._client.graphql(
  File "/usr/local/lib/python3.9/site-packages/aiogithubapi/github.py", line 225, in graphql
    return await self._client.async_call_api(
  File "/usr/local/lib/python3.9/site-packages/aiogithubapi/client.py", line 140, in async_call_api
    raise exception(message or response.data)
aiogithubapi.exceptions.GitHubAuthenticationException: Bad credentials
2022-03-09 16:11:43 ERROR (MainThread) [homeassistant.components.automation.home_assistant_config_folder_push_to_github] Home assistant config folder push to github: Error executing script. Invalid data for call_service at pos 1: required key not provided @ data['input']
2022-03-09 16:11:43 ERROR (MainThread) [homeassistant.components.automation.home_assistant_config_folder_push_to_github] Error while executing automation automation.home_assistant_config_folder_push_to_github: required key not provided @ data['input']
2022-03-09 16:11:58 ERROR (MainThread) [homeassistant.components.automation.home_assistant_config_folder_push_to_github] Home assistant config folder push to github: Error executing script. Invalid data for call_service at pos 1: required key not provided @ data['input']
2022-03-09 16:11:58 ERROR (MainThread) [homeassistant.components.automation.home_assistant_config_folder_push_to_github] Error while executing automation automation.home_assistant_config_folder_push_to_github: required key not provided @ data['input']
2022-03-09 16:12:09 ERROR (MainThread) [homeassistant.components.github] Bad credentials
Traceback (most recent call last):
  File "/usr/src/homeassistant/homeassistant/components/github/coordinator.py", line 125, in _async_update_data
    response = await self._client.graphql(
  File "/usr/local/lib/python3.9/site-packages/aiogithubapi/github.py", line 225, in graphql
    return await self._client.async_call_api(
  File "/usr/local/lib/python3.9/site-packages/aiogithubapi/client.py", line 140, in async_call_api
    raise exception(message or response.data)
aiogithubapi.exceptions.GitHubAuthenticationException: Bad credentials
2022-03-09 16:13:30 ERROR (MainThread) [homeassistant.components.github] Bad credentials
Traceback (most recent call last):
  File "/usr/src/homeassistant/homeassistant/components/github/coordinator.py", line 125, in _async_update_data
    response = await self._client.graphql(
  File "/usr/local/lib/python3.9/site-packages/aiogithubapi/github.py", line 225, in graphql
    return await self._client.async_call_api(
  File "/usr/local/lib/python3.9/site-packages/aiogithubapi/client.py", line 140, in async_call_api
    raise exception(message or response.data)
aiogithubapi.exceptions.GitHubAuthenticationException: Bad credentials
2022-03-09 16:13:33 ERROR (MainThread) [homeassistant.helpers.script.websocket_api_script] websocket_api script: Error executing script. Invalid data for call_service at pos 1: required key not provided @ data['input']
2022-03-09 16:13:33 ERROR (MainThread) [homeassistant.components.websocket_api.http.connection] [140336690349056] Error handling message: required key not provided @ data['addon']. Got None
required key not provided @ data['input']. Got None
2022-03-09 16:14:34 ERROR (MainThread) [homeassistant.helpers.script.websocket_api_script] websocket_api script: Error executing script. Invalid data for call_service at pos 1: required key not provided @ data['input']
2022-03-09 16:14:34 ERROR (MainThread) [homeassistant.components.websocket_api.http.connection] [140336690349056] Error handling message: required key not provided @ data['addon']. Got None
required key not provided @ data['input']. Got None
2022-03-09 16:14:50 ERROR (MainThread) [homeassistant.components.github] Bad credentials
Traceback (most recent call last):
  File "/usr/src/homeassistant/homeassistant/components/github/coordinator.py", line 125, in _async_update_data
    response = await self._client.graphql(
  File "/usr/local/lib/python3.9/site-packages/aiogithubapi/github.py", line 225, in graphql
    return await self._client.async_call_api(
  File "/usr/local/lib/python3.9/site-packages/aiogithubapi/client.py", line 140, in async_call_api
    raise exception(message or response.data)
aiogithubapi.exceptions.GitHubAuthenticationException: Bad credentials
2022-03-09 16:15:58 ERROR (MainThread) [homeassistant.components.automation.home_assistant_config_folder_push_to_github] Home assistant config folder push to github: Error executing script. Invalid data for call_service at pos 1: required key not provided @ data['input']
2022-03-09 16:15:58 ERROR (MainThread) [homeassistant.components.automation.home_assistant_config_folder_push_to_github] Error while executing automation automation.home_assistant_config_folder_push_to_github: required key not provided @ data['input']
2022-03-09 16:16:11 ERROR (MainThread) [homeassistant.components.github] Bad credentials
Traceback (most recent call last):
  File "/usr/src/homeassistant/homeassistant/components/github/coordinator.py", line 125, in _async_update_data
    response = await self._client.graphql(
  File "/usr/local/lib/python3.9/site-packages/aiogithubapi/github.py", line 225, in graphql
    return await self._client.async_call_api(
  File "/usr/local/lib/python3.9/site-packages/aiogithubapi/client.py", line 140, in async_call_api
    raise exception(message or response.data)
aiogithubapi.exceptions.GitHubAuthenticationException: Bad credentials
2022-03-09 16:16:38 ERROR (MainThread) [homeassistant.components.automation.home_assistant_config_folder_push_to_github] Home assistant config folder push to github: Error executing script. Invalid data for call_service at pos 1: required key not provided @ data['input']
2022-03-09 16:16:38 ERROR (MainThread) [homeassistant.components.automation.home_assistant_config_folder_push_to_github] Error while executing automation automation.home_assistant_config_folder_push_to_github: required key not provided @ data['input']
2022-03-09 16:17:32 ERROR (MainThread) [homeassistant.components.github] Bad credentials
Traceback (most recent call last):
  File "/usr/src/homeassistant/homeassistant/components/github/coordinator.py", line 125, in _async_update_data
    response = await self._client.graphql(
  File "/usr/local/lib/python3.9/site-packages/aiogithubapi/github.py", line 225, in graphql
    return await self._client.async_call_api(
  File "/usr/local/lib/python3.9/site-packages/aiogithubapi/client.py", line 140, in async_call_api
    raise exception(message or response.data)
aiogithubapi.exceptions.GitHubAuthenticationException: Bad credentials
2022-03-09 16:18:52 ERROR (MainThread) [homeassistant.components.github] Bad credentials
Traceback (most recent call last):
  File "/usr/src/homeassistant/homeassistant/components/github/coordinator.py", line 125, in _async_update_data
    response = await self._client.graphql(
  File "/usr/local/lib/python3.9/site-packages/aiogithubapi/github.py", line 225, in graphql
    return await self._client.async_call_api(
  File "/usr/local/lib/python3.9/site-packages/aiogithubapi/client.py", line 140, in async_call_api
    raise exception(message or response.data)
aiogithubapi.exceptions.GitHubAuthenticationException: Bad credentials
2022-03-09 16:19:50 ERROR (MainThread) [homeassistant.components.automation.home_assistant_config_folder_push_to_github] Home assistant config folder push to github: Error executing script. Invalid data for call_service at pos 1: required key not provided @ data['input']
2022-03-09 16:19:50 ERROR (MainThread) [homeassistant.components.automation.home_assistant_config_folder_push_to_github] Error while executing automation automation.home_assistant_config_folder_push_to_github: required key not provided @ data['input']
2022-03-09 16:19:52 ERROR (MainThread) [homeassistant.components.automation.home_assistant_config_folder_push_to_github] Home assistant config folder push to github: Error executing script. Invalid data for call_service at pos 1: required key not provided @ data['input']
2022-03-09 16:19:52 ERROR (MainThread) [homeassistant.components.automation.home_assistant_config_folder_push_to_github] Error while executing automation automation.home_assistant_config_folder_push_to_github: required key not provided @ data['input']
2022-03-09 16:20:13 ERROR (MainThread) [homeassistant.components.github] Bad credentials
Traceback (most recent call last):
  File "/usr/src/homeassistant/homeassistant/components/github/coordinator.py", line 125, in _async_update_data
    response = await self._client.graphql(
  File "/usr/local/lib/python3.9/site-packages/aiogithubapi/github.py", line 225, in graphql
    return await self._client.async_call_api(
  File "/usr/local/lib/python3.9/site-packages/aiogithubapi/client.py", line 140, in async_call_api
    raise exception(message or response.data)
aiogithubapi.exceptions.GitHubAuthenticationException: Bad credentials
2022-03-09 16:21:33 ERROR (MainThread) [homeassistant.components.github] Bad credentials
Traceback (most recent call last):
  File "/usr/src/homeassistant/homeassistant/components/github/coordinator.py", line 125, in _async_update_data
    response = await self._client.graphql(
  File "/usr/local/lib/python3.9/site-packages/aiogithubapi/github.py", line 225, in graphql
    return await self._client.async_call_api(
  File "/usr/local/lib/python3.9/site-packages/aiogithubapi/client.py", line 140, in async_call_api
    raise exception(message or response.data)
aiogithubapi.exceptions.GitHubAuthenticationException: Bad credentials
2022-03-09 16:22:54 ERROR (MainThread) [homeassistant.components.github] Bad credentials
Traceback (most recent call last):
  File "/usr/src/homeassistant/homeassistant/components/github/coordinator.py", line 125, in _async_update_data
    response = await self._client.graphql(
  File "/usr/local/lib/python3.9/site-packages/aiogithubapi/github.py", line 225, in graphql
    return await self._client.async_call_api(
  File "/usr/local/lib/python3.9/site-packages/aiogithubapi/client.py", line 140, in async_call_api
    raise exception(message or response.data)
aiogithubapi.exceptions.GitHubAuthenticationException: Bad credentials
2022-03-09 16:24:14 ERROR (MainThread) [homeassistant.components.github] Bad credentials
Traceback (most recent call last):
  File "/usr/src/homeassistant/homeassistant/components/github/coordinator.py", line 125, in _async_update_data
    response = await self._client.graphql(
  File "/usr/local/lib/python3.9/site-packages/aiogithubapi/github.py", line 225, in graphql
    return await self._client.async_call_api(
  File "/usr/local/lib/python3.9/site-packages/aiogithubapi/client.py", line 140, in async_call_api
    raise exception(message or response.data)
aiogithubapi.exceptions.GitHubAuthenticationException: Bad credentials
2022-03-09 16:25:35 ERROR (MainThread) [homeassistant.components.github] Bad credentials
Traceback (most recent call last):
  File "/usr/src/homeassistant/homeassistant/components/github/coordinator.py", line 125, in _async_update_data
    response = await self._client.graphql(
  File "/usr/local/lib/python3.9/site-packages/aiogithubapi/github.py", line 225, in graphql
    return await self._client.async_call_api(
  File "/usr/local/lib/python3.9/site-packages/aiogithubapi/client.py", line 140, in async_call_api
    raise exception(message or response.data)
aiogithubapi.exceptions.GitHubAuthenticationException: Bad credentials
2022-03-09 16:26:55 ERROR (MainThread) [homeassistant.components.github] Bad credentials
Traceback (most recent call last):
  File "/usr/src/homeassistant/homeassistant/components/github/coordinator.py", line 125, in _async_update_data
    response = await self._client.graphql(
  File "/usr/local/lib/python3.9/site-packages/aiogithubapi/github.py", line 225, in graphql
    return await self._client.async_call_api(
  File "/usr/local/lib/python3.9/site-packages/aiogithubapi/client.py", line 140, in async_call_api
    raise exception(message or response.data)
aiogithubapi.exceptions.GitHubAuthenticationException: Bad credentials
2022-03-09 16:28:16 ERROR (MainThread) [homeassistant.components.github] Bad credentials
Traceback (most recent call last):
  File "/usr/src/homeassistant/homeassistant/components/github/coordinator.py", line 125, in _async_update_data
    response = await self._client.graphql(
  File "/usr/local/lib/python3.9/site-packages/aiogithubapi/github.py", line 225, in graphql
    return await self._client.async_call_api(
  File "/usr/local/lib/python3.9/site-packages/aiogithubapi/client.py", line 140, in async_call_api
    raise exception(message or response.data)
aiogithubapi.exceptions.GitHubAuthenticationException: Bad credentials
2022-03-09 16:28:27 WARNING (MainThread) [homeassistant.components.hassio] Can't read Supervisor data: Container addon_a0d7b954_phpmyadmin is not running
2022-03-09 16:29:37 ERROR (MainThread) [homeassistant.components.github] Bad credentials
Traceback (most recent call last):
  File "/usr/src/homeassistant/homeassistant/components/github/coordinator.py", line 125, in _async_update_data
    response = await self._client.graphql(
  File "/usr/local/lib/python3.9/site-packages/aiogithubapi/github.py", line 225, in graphql
    return await self._client.async_call_api(
  File "/usr/local/lib/python3.9/site-packages/aiogithubapi/client.py", line 140, in async_call_api
    raise exception(message or response.data)
aiogithubapi.exceptions.GitHubAuthenticationException: Bad credentials
2022-03-09 16:30:57 ERROR (MainThread) [homeassistant.components.github] Bad credentials
Traceback (most recent call last):
  File "/usr/src/homeassistant/homeassistant/components/github/coordinator.py", line 125, in _async_update_data
    response = await self._client.graphql(
  File "/usr/local/lib/python3.9/site-packages/aiogithubapi/github.py", line 225, in graphql
    return await self._client.async_call_api(
  File "/usr/local/lib/python3.9/site-packages/aiogithubapi/client.py", line 140, in async_call_api
    raise exception(message or response.data)
aiogithubapi.exceptions.GitHubAuthenticationException: Bad credentials
2022-03-09 16:32:18 ERROR (MainThread) [homeassistant.components.github] Bad credentials
Traceback (most recent call last):
  File "/usr/src/homeassistant/homeassistant/components/github/coordinator.py", line 125, in _async_update_data
    response = await self._client.graphql(
  File "/usr/local/lib/python3.9/site-packages/aiogithubapi/github.py", line 225, in graphql
    return await self._client.async_call_api(
  File "/usr/local/lib/python3.9/site-packages/aiogithubapi/client.py", line 140, in async_call_api
    raise exception(message or response.data)
aiogithubapi.exceptions.GitHubAuthenticationException: Bad credentials
2022-03-09 16:33:27 WARNING (MainThread) [homeassistant.components.hassio] Can't read Supervisor data: Container addon_a0d7b954_phpmyadmin is not running
2022-03-09 16:33:38 ERROR (MainThread) [homeassistant.components.github] Bad credentials
Traceback (most recent call last):
  File "/usr/src/homeassistant/homeassistant/components/github/coordinator.py", line 125, in _async_update_data
    response = await self._client.graphql(
  File "/usr/local/lib/python3.9/site-packages/aiogithubapi/github.py", line 225, in graphql
    return await self._client.async_call_api(
  File "/usr/local/lib/python3.9/site-packages/aiogithubapi/client.py", line 140, in async_call_api
    raise exception(message or response.data)
aiogithubapi.exceptions.GitHubAuthenticationException: Bad credentials
2022-03-09 16:34:59 ERROR (MainThread) [homeassistant.components.github] Bad credentials
Traceback (most recent call last):
  File "/usr/src/homeassistant/homeassistant/components/github/coordinator.py", line 125, in _async_update_data
    response = await self._client.graphql(
  File "/usr/local/lib/python3.9/site-packages/aiogithubapi/github.py", line 225, in graphql
    return await self._client.async_call_api(
  File "/usr/local/lib/python3.9/site-packages/aiogithubapi/client.py", line 140, in async_call_api
    raise exception(message or response.data)
aiogithubapi.exceptions.GitHubAuthenticationException: Bad credentials
2022-03-09 16:36:20 ERROR (MainThread) [homeassistant.components.github] Bad credentials
Traceback (most recent call last):
  File "/usr/src/homeassistant/homeassistant/components/github/coordinator.py", line 125, in _async_update_data
    response = await self._client.graphql(
  File "/usr/local/lib/python3.9/site-packages/aiogithubapi/github.py", line 225, in graphql
    return await self._client.async_call_api(
  File "/usr/local/lib/python3.9/site-packages/aiogithubapi/client.py", line 140, in async_call_api
    raise exception(message or response.data)
aiogithubapi.exceptions.GitHubAuthenticationException: Bad credentials
2022-03-09 16:37:40 ERROR (MainThread) [homeassistant.components.github] Bad credentials
Traceback (most recent call last):
  File "/usr/src/homeassistant/homeassistant/components/github/coordinator.py", line 125, in _async_update_data
    response = await self._client.graphql(
  File "/usr/local/lib/python3.9/site-packages/aiogithubapi/github.py", line 225, in graphql
    return await self._client.async_call_api(
  File "/usr/local/lib/python3.9/site-packages/aiogithubapi/client.py", line 140, in async_call_api
    raise exception(message or response.data)
aiogithubapi.exceptions.GitHubAuthenticationException: Bad credentials
2022-03-09 16:38:27 WARNING (MainThread) [homeassistant.components.hassio] Can't read Supervisor data: Container addon_a0d7b954_phpmyadmin is not running
2022-03-09 16:39:01 ERROR (MainThread) [homeassistant.components.github] Bad credentials
Traceback (most recent call last):
  File "/usr/src/homeassistant/homeassistant/components/github/coordinator.py", line 125, in _async_update_data
    response = await self._client.graphql(
  File "/usr/local/lib/python3.9/site-packages/aiogithubapi/github.py", line 225, in graphql
    return await self._client.async_call_api(
  File "/usr/local/lib/python3.9/site-packages/aiogithubapi/client.py", line 140, in async_call_api
    raise exception(message or response.data)
aiogithubapi.exceptions.GitHubAuthenticationException: Bad credentials
2022-03-09 16:40:22 ERROR (MainThread) [homeassistant.components.github] Bad credentials
Traceback (most recent call last):
  File "/usr/src/homeassistant/homeassistant/components/github/coordinator.py", line 125, in _async_update_data
    response = await self._client.graphql(
  File "/usr/local/lib/python3.9/site-packages/aiogithubapi/github.py", line 225, in graphql
    return await self._client.async_call_api(
  File "/usr/local/lib/python3.9/site-packages/aiogithubapi/client.py", line 140, in async_call_api
    raise exception(message or response.data)
aiogithubapi.exceptions.GitHubAuthenticationException: Bad credentials
2022-03-09 16:41:42 ERROR (MainThread) [homeassistant.components.github] Bad credentials
Traceback (most recent call last):
  File "/usr/src/homeassistant/homeassistant/components/github/coordinator.py", line 125, in _async_update_data
    response = await self._client.graphql(
  File "/usr/local/lib/python3.9/site-packages/aiogithubapi/github.py", line 225, in graphql
    return await self._client.async_call_api(
  File "/usr/local/lib/python3.9/site-packages/aiogithubapi/client.py", line 140, in async_call_api
    raise exception(message or response.data)
aiogithubapi.exceptions.GitHubAuthenticationException: Bad credentials
2022-03-09 16:43:03 ERROR (MainThread) [homeassistant.components.github] Bad credentials
Traceback (most recent call last):
  File "/usr/src/homeassistant/homeassistant/components/github/coordinator.py", line 125, in _async_update_data
    response = await self._client.graphql(
  File "/usr/local/lib/python3.9/site-packages/aiogithubapi/github.py", line 225, in graphql
    return await self._client.async_call_api(
  File "/usr/local/lib/python3.9/site-packages/aiogithubapi/client.py", line 140, in async_call_api
    raise exception(message or response.data)
aiogithubapi.exceptions.GitHubAuthenticationException: Bad credentials
2022-03-09 16:43:27 WARNING (MainThread) [homeassistant.components.hassio] Can't read Supervisor data: Container addon_a0d7b954_phpmyadmin is not running
2022-03-09 16:44:23 ERROR (MainThread) [homeassistant.components.github] Bad credentials
Traceback (most recent call last):
  File "/usr/src/homeassistant/homeassistant/components/github/coordinator.py", line 125, in _async_update_data
    response = await self._client.graphql(
  File "/usr/local/lib/python3.9/site-packages/aiogithubapi/github.py", line 225, in graphql
    return await self._client.async_call_api(
  File "/usr/local/lib/python3.9/site-packages/aiogithubapi/client.py", line 140, in async_call_api
    raise exception(message or response.data)
aiogithubapi.exceptions.GitHubAuthenticationException: Bad credentials
2022-03-09 16:45:44 ERROR (MainThread) [homeassistant.components.github] Bad credentials
Traceback (most recent call last):
  File "/usr/src/homeassistant/homeassistant/components/github/coordinator.py", line 125, in _async_update_data
    response = await self._client.graphql(
  File "/usr/local/lib/python3.9/site-packages/aiogithubapi/github.py", line 225, in graphql
    return await self._client.async_call_api(
  File "/usr/local/lib/python3.9/site-packages/aiogithubapi/client.py", line 140, in async_call_api
    raise exception(message or response.data)
aiogithubapi.exceptions.GitHubAuthenticationException: Bad credentials
2022-03-09 16:47:04 ERROR (MainThread) [homeassistant.components.github] Bad credentials
Traceback (most recent call last):
  File "/usr/src/homeassistant/homeassistant/components/github/coordinator.py", line 125, in _async_update_data
    response = await self._client.graphql(
  File "/usr/local/lib/python3.9/site-packages/aiogithubapi/github.py", line 225, in graphql
    return await self._client.async_call_api(
  File "/usr/local/lib/python3.9/site-packages/aiogithubapi/client.py", line 140, in async_call_api
    raise exception(message or response.data)
aiogithubapi.exceptions.GitHubAuthenticationException: Bad credentials
2022-03-09 16:48:25 ERROR (MainThread) [homeassistant.components.github] Bad credentials
Traceback (most recent call last):
  File "/usr/src/homeassistant/homeassistant/components/github/coordinator.py", line 125, in _async_update_data
    response = await self._client.graphql(
  File "/usr/local/lib/python3.9/site-packages/aiogithubapi/github.py", line 225, in graphql
    return await self._client.async_call_api(
  File "/usr/local/lib/python3.9/site-packages/aiogithubapi/client.py", line 140, in async_call_api
    raise exception(message or response.data)
aiogithubapi.exceptions.GitHubAuthenticationException: Bad credentials
2022-03-09 16:48:27 WARNING (MainThread) [homeassistant.components.hassio] Can't read Supervisor data: Container addon_a0d7b954_phpmyadmin is not running
2022-03-09 16:49:46 ERROR (MainThread) [homeassistant.components.github] Bad credentials
Traceback (most recent call last):
  File "/usr/src/homeassistant/homeassistant/components/github/coordinator.py", line 125, in _async_update_data
    response = await self._client.graphql(
  File "/usr/local/lib/python3.9/site-packages/aiogithubapi/github.py", line 225, in graphql
    return await self._client.async_call_api(
  File "/usr/local/lib/python3.9/site-packages/aiogithubapi/client.py", line 140, in async_call_api
    raise exception(message or response.data)
aiogithubapi.exceptions.GitHubAuthenticationException: Bad credentials
2022-03-09 16:51:06 ERROR (MainThread) [homeassistant.components.github] Bad credentials
Traceback (most recent call last):
  File "/usr/src/homeassistant/homeassistant/components/github/coordinator.py", line 125, in _async_update_data
    response = await self._client.graphql(
  File "/usr/local/lib/python3.9/site-packages/aiogithubapi/github.py", line 225, in graphql
    return await self._client.async_call_api(
  File "/usr/local/lib/python3.9/site-packages/aiogithubapi/client.py", line 140, in async_call_api
    raise exception(message or response.data)
aiogithubapi.exceptions.GitHubAuthenticationException: Bad credentials
2022-03-09 16:52:27 ERROR (MainThread) [homeassistant.components.github] Bad credentials
Traceback (most recent call last):
  File "/usr/src/homeassistant/homeassistant/components/github/coordinator.py", line 125, in _async_update_data
    response = await self._client.graphql(
  File "/usr/local/lib/python3.9/site-packages/aiogithubapi/github.py", line 225, in graphql
    return await self._client.async_call_api(
  File "/usr/local/lib/python3.9/site-packages/aiogithubapi/client.py", line 140, in async_call_api
    raise exception(message or response.data)
aiogithubapi.exceptions.GitHubAuthenticationException: Bad credentials
2022-03-09 16:53:27 WARNING (MainThread) [homeassistant.components.hassio] Can't read Supervisor data: Container addon_a0d7b954_phpmyadmin is not running
2022-03-09 16:53:47 ERROR (MainThread) [homeassistant.components.github] Bad credentials
Traceback (most recent call last):
  File "/usr/src/homeassistant/homeassistant/components/github/coordinator.py", line 125, in _async_update_data
    response = await self._client.graphql(
  File "/usr/local/lib/python3.9/site-packages/aiogithubapi/github.py", line 225, in graphql
    return await self._client.async_call_api(
  File "/usr/local/lib/python3.9/site-packages/aiogithubapi/client.py", line 140, in async_call_api
    raise exception(message or response.data)
aiogithubapi.exceptions.GitHubAuthenticationException: Bad credentials
2022-03-09 16:55:08 ERROR (MainThread) [homeassistant.components.github] Bad credentials
Traceback (most recent call last):
  File "/usr/src/homeassistant/homeassistant/components/github/coordinator.py", line 125, in _async_update_data
    response = await self._client.graphql(
  File "/usr/local/lib/python3.9/site-packages/aiogithubapi/github.py", line 225, in graphql
    return await self._client.async_call_api(
  File "/usr/local/lib/python3.9/site-packages/aiogithubapi/client.py", line 140, in async_call_api
    raise exception(message or response.data)
aiogithubapi.exceptions.GitHubAuthenticationException: Bad credentials
2022-03-09 16:56:28 ERROR (MainThread) [homeassistant.components.github] Bad credentials
Traceback (most recent call last):
  File "/usr/src/homeassistant/homeassistant/components/github/coordinator.py", line 125, in _async_update_data
    response = await self._client.graphql(
  File "/usr/local/lib/python3.9/site-packages/aiogithubapi/github.py", line 225, in graphql
    return await self._client.async_call_api(
  File "/usr/local/lib/python3.9/site-packages/aiogithubapi/client.py", line 140, in async_call_api
    raise exception(message or response.data)
aiogithubapi.exceptions.GitHubAuthenticationException: Bad credentials
2022-03-09 16:57:49 ERROR (MainThread) [homeassistant.components.github] Bad credentials
Traceback (most recent call last):
  File "/usr/src/homeassistant/homeassistant/components/github/coordinator.py", line 125, in _async_update_data
    response = await self._client.graphql(
  File "/usr/local/lib/python3.9/site-packages/aiogithubapi/github.py", line 225, in graphql
    return await self._client.async_call_api(
  File "/usr/local/lib/python3.9/site-packages/aiogithubapi/client.py", line 140, in async_call_api
    raise exception(message or response.data)
aiogithubapi.exceptions.GitHubAuthenticationException: Bad credentials
2022-03-09 16:58:27 WARNING (MainThread) [homeassistant.components.hassio] Can't read Supervisor data: Container addon_a0d7b954_phpmyadmin is not running
2022-03-09 16:58:28 ERROR (MainThread) [homeassistant.components.automation.config_push_to_git] config push to git: Error executing script. Invalid data for call_service at pos 1: required key not provided @ data['input']
2022-03-09 16:58:28 ERROR (MainThread) [homeassistant.components.automation.config_push_to_git] Error while executing automation automation.config_push_to_git: required key not provided @ data['input']
2022-03-09 16:59:04 ERROR (MainThread) [homeassistant.components.automation.config_push_to_git] config push to git: Error executing script. Invalid data for call_service at pos 1: required key not provided @ data['input']
2022-03-09 16:59:04 ERROR (MainThread) [homeassistant.components.automation.config_push_to_git] Error while executing automation automation.config_push_to_git: required key not provided @ data['input']
2022-03-09 16:59:05 ERROR (MainThread) [homeassistant.components.automation.config_push_to_git] config push to git: Error executing script. Invalid data for call_service at pos 1: required key not provided @ data['input']
2022-03-09 16:59:05 ERROR (MainThread) [homeassistant.components.automation.config_push_to_git] Error while executing automation automation.config_push_to_git: required key not provided @ data['input']
2022-03-09 16:59:05 ERROR (MainThread) [homeassistant.components.automation.config_push_to_git] config push to git: Error executing script. Invalid data for call_service at pos 1: required key not provided @ data['input']
2022-03-09 16:59:05 ERROR (MainThread) [homeassistant.components.automation.config_push_to_git] Error while executing automation automation.config_push_to_git: required key not provided @ data['input']
2022-03-09 16:59:10 ERROR (MainThread) [homeassistant.components.github] Bad credentials
Traceback (most recent call last):
  File "/usr/src/homeassistant/homeassistant/components/github/coordinator.py", line 125, in _async_update_data
    response = await self._client.graphql(
  File "/usr/local/lib/python3.9/site-packages/aiogithubapi/github.py", line 225, in graphql
    return await self._client.async_call_api(
  File "/usr/local/lib/python3.9/site-packages/aiogithubapi/client.py", line 140, in async_call_api
    raise exception(message or response.data)
aiogithubapi.exceptions.GitHubAuthenticationException: Bad credentials
2022-03-09 17:00:30 ERROR (MainThread) [homeassistant.components.github] Bad credentials
Traceback (most recent call last):
  File "/usr/src/homeassistant/homeassistant/components/github/coordinator.py", line 125, in _async_update_data
    response = await self._client.graphql(
  File "/usr/local/lib/python3.9/site-packages/aiogithubapi/github.py", line 225, in graphql
    return await self._client.async_call_api(
  File "/usr/local/lib/python3.9/site-packages/aiogithubapi/client.py", line 140, in async_call_api
    raise exception(message or response.data)
aiogithubapi.exceptions.GitHubAuthenticationException: Bad credentials
2022-03-09 17:01:51 ERROR (MainThread) [homeassistant.components.github] Bad credentials
Traceback (most recent call last):
  File "/usr/src/homeassistant/homeassistant/components/github/coordinator.py", line 125, in _async_update_data
    response = await self._client.graphql(
  File "/usr/local/lib/python3.9/site-packages/aiogithubapi/github.py", line 225, in graphql
    return await self._client.async_call_api(
  File "/usr/local/lib/python3.9/site-packages/aiogithubapi/client.py", line 140, in async_call_api
    raise exception(message or response.data)
aiogithubapi.exceptions.GitHubAuthenticationException: Bad credentials
2022-03-09 17:03:11 ERROR (MainThread) [homeassistant.components.github] Bad credentials
Traceback (most recent call last):
  File "/usr/src/homeassistant/homeassistant/components/github/coordinator.py", line 125, in _async_update_data
    response = await self._client.graphql(
  File "/usr/local/lib/python3.9/site-packages/aiogithubapi/github.py", line 225, in graphql
    return await self._client.async_call_api(
  File "/usr/local/lib/python3.9/site-packages/aiogithubapi/client.py", line 140, in async_call_api
    raise exception(message or response.data)
aiogithubapi.exceptions.GitHubAuthenticationException: Bad credentials
2022-03-09 17:03:27 WARNING (MainThread) [homeassistant.components.hassio] Can't read Supervisor data: Container addon_a0d7b954_phpmyadmin is not running
2022-03-09 17:04:32 ERROR (MainThread) [homeassistant.components.github] Bad credentials
Traceback (most recent call last):
  File "/usr/src/homeassistant/homeassistant/components/github/coordinator.py", line 125, in _async_update_data
    response = await self._client.graphql(
  File "/usr/local/lib/python3.9/site-packages/aiogithubapi/github.py", line 225, in graphql
    return await self._client.async_call_api(
  File "/usr/local/lib/python3.9/site-packages/aiogithubapi/client.py", line 140, in async_call_api
    raise exception(message or response.data)
aiogithubapi.exceptions.GitHubAuthenticationException: Bad credentials
2022-03-09 17:05:53 ERROR (MainThread) [homeassistant.components.github] Bad credentials
Traceback (most recent call last):
  File "/usr/src/homeassistant/homeassistant/components/github/coordinator.py", line 125, in _async_update_data
    response = await self._client.graphql(
  File "/usr/local/lib/python3.9/site-packages/aiogithubapi/github.py", line 225, in graphql
    return await self._client.async_call_api(
  File "/usr/local/lib/python3.9/site-packages/aiogithubapi/client.py", line 140, in async_call_api
    raise exception(message or response.data)
aiogithubapi.exceptions.GitHubAuthenticationException: Bad credentials
2022-03-09 17:07:13 ERROR (MainThread) [homeassistant.components.github] Bad credentials
Traceback (most recent call last):
  File "/usr/src/homeassistant/homeassistant/components/github/coordinator.py", line 125, in _async_update_data
    response = await self._client.graphql(
  File "/usr/local/lib/python3.9/site-packages/aiogithubapi/github.py", line 225, in graphql
    return await self._client.async_call_api(
  File "/usr/local/lib/python3.9/site-packages/aiogithubapi/client.py", line 140, in async_call_api
    raise exception(message or response.data)
aiogithubapi.exceptions.GitHubAuthenticationException: Bad credentials
2022-03-09 17:08:34 ERROR (MainThread) [homeassistant.components.github] Bad credentials
Traceback (most recent call last):
  File "/usr/src/homeassistant/homeassistant/components/github/coordinator.py", line 125, in _async_update_data
    response = await self._client.graphql(
  File "/usr/local/lib/python3.9/site-packages/aiogithubapi/github.py", line 225, in graphql
    return await self._client.async_call_api(
  File "/usr/local/lib/python3.9/site-packages/aiogithubapi/client.py", line 140, in async_call_api
    raise exception(message or response.data)
aiogithubapi.exceptions.GitHubAuthenticationException: Bad credentials
2022-03-09 17:09:54 ERROR (MainThread) [homeassistant.components.github] Bad credentials
Traceback (most recent call last):
  File "/usr/src/homeassistant/homeassistant/components/github/coordinator.py", line 125, in _async_update_data
    response = await self._client.graphql(
  File "/usr/local/lib/python3.9/site-packages/aiogithubapi/github.py", line 225, in graphql
    return await self._client.async_call_api(
  File "/usr/local/lib/python3.9/site-packages/aiogithubapi/client.py", line 140, in async_call_api
    raise exception(message or response.data)
aiogithubapi.exceptions.GitHubAuthenticationException: Bad credentials
2022-03-09 17:11:15 ERROR (MainThread) [homeassistant.components.github] Bad credentials
Traceback (most recent call last):
  File "/usr/src/homeassistant/homeassistant/components/github/coordinator.py", line 125, in _async_update_data
    response = await self._client.graphql(
  File "/usr/local/lib/python3.9/site-packages/aiogithubapi/github.py", line 225, in graphql
    return await self._client.async_call_api(
  File "/usr/local/lib/python3.9/site-packages/aiogithubapi/client.py", line 140, in async_call_api
    raise exception(message or response.data)
aiogithubapi.exceptions.GitHubAuthenticationException: Bad credentials
2022-03-09 17:12:36 ERROR (MainThread) [homeassistant.components.github] Bad credentials
Traceback (most recent call last):
  File "/usr/src/homeassistant/homeassistant/components/github/coordinator.py", line 125, in _async_update_data
    response = await self._client.graphql(
  File "/usr/local/lib/python3.9/site-packages/aiogithubapi/github.py", line 225, in graphql
    return await self._client.async_call_api(
  File "/usr/local/lib/python3.9/site-packages/aiogithubapi/client.py", line 140, in async_call_api
    raise exception(message or response.data)
aiogithubapi.exceptions.GitHubAuthenticationException: Bad credentials
2022-03-09 17:13:56 ERROR (MainThread) [homeassistant.components.github] Bad credentials
Traceback (most recent call last):
  File "/usr/src/homeassistant/homeassistant/components/github/coordinator.py", line 125, in _async_update_data
    response = await self._client.graphql(
  File "/usr/local/lib/python3.9/site-packages/aiogithubapi/github.py", line 225, in graphql
    return await self._client.async_call_api(
  File "/usr/local/lib/python3.9/site-packages/aiogithubapi/client.py", line 140, in async_call_api
    raise exception(message or response.data)
aiogithubapi.exceptions.GitHubAuthenticationException: Bad credentials
2022-03-09 17:15:17 ERROR (MainThread) [homeassistant.components.github] Bad credentials
Traceback (most recent call last):
  File "/usr/src/homeassistant/homeassistant/components/github/coordinator.py", line 125, in _async_update_data
    response = await self._client.graphql(
  File "/usr/local/lib/python3.9/site-packages/aiogithubapi/github.py", line 225, in graphql
    return await self._client.async_call_api(
  File "/usr/local/lib/python3.9/site-packages/aiogithubapi/client.py", line 140, in async_call_api
    raise exception(message or response.data)
aiogithubapi.exceptions.GitHubAuthenticationException: Bad credentials
2022-03-09 17:16:37 ERROR (MainThread) [homeassistant.components.github] Bad credentials
Traceback (most recent call last):
  File "/usr/src/homeassistant/homeassistant/components/github/coordinator.py", line 125, in _async_update_data
    response = await self._client.graphql(
  File "/usr/local/lib/python3.9/site-packages/aiogithubapi/github.py", line 225, in graphql
    return await self._client.async_call_api(
  File "/usr/local/lib/python3.9/site-packages/aiogithubapi/client.py", line 140, in async_call_api
    raise exception(message or response.data)
aiogithubapi.exceptions.GitHubAuthenticationException: Bad credentials
2022-03-09 17:17:58 ERROR (MainThread) [homeassistant.components.github] Bad credentials
Traceback (most recent call last):
  File "/usr/src/homeassistant/homeassistant/components/github/coordinator.py", line 125, in _async_update_data
    response = await self._client.graphql(
  File "/usr/local/lib/python3.9/site-packages/aiogithubapi/github.py", line 225, in graphql
    return await self._client.async_call_api(
  File "/usr/local/lib/python3.9/site-packages/aiogithubapi/client.py", line 140, in async_call_api
    raise exception(message or response.data)
aiogithubapi.exceptions.GitHubAuthenticationException: Bad credentials
2022-03-09 17:18:32 WARNING (MainThread) [homeassistant.components.hassio] Can't read Supervisor data: Container addon_a0d7b954_phpmyadmin is not running
2022-03-09 17:19:19 ERROR (MainThread) [homeassistant.components.github] Bad credentials
Traceback (most recent call last):
  File "/usr/src/homeassistant/homeassistant/components/github/coordinator.py", line 125, in _async_update_data
    response = await self._client.graphql(
  File "/usr/local/lib/python3.9/site-packages/aiogithubapi/github.py", line 225, in graphql
    return await self._client.async_call_api(
  File "/usr/local/lib/python3.9/site-packages/aiogithubapi/client.py", line 140, in async_call_api
    raise exception(message or response.data)
aiogithubapi.exceptions.GitHubAuthenticationException: Bad credentials
2022-03-09 17:20:39 ERROR (MainThread) [homeassistant.components.github] Bad credentials
Traceback (most recent call last):
  File "/usr/src/homeassistant/homeassistant/components/github/coordinator.py", line 125, in _async_update_data
    response = await self._client.graphql(
  File "/usr/local/lib/python3.9/site-packages/aiogithubapi/github.py", line 225, in graphql
    return await self._client.async_call_api(
  File "/usr/local/lib/python3.9/site-packages/aiogithubapi/client.py", line 140, in async_call_api
    raise exception(message or response.data)
aiogithubapi.exceptions.GitHubAuthenticationException: Bad credentials
2022-03-09 17:22:00 ERROR (MainThread) [homeassistant.components.github] Bad credentials
Traceback (most recent call last):
  File "/usr/src/homeassistant/homeassistant/components/github/coordinator.py", line 125, in _async_update_data
    response = await self._client.graphql(
  File "/usr/local/lib/python3.9/site-packages/aiogithubapi/github.py", line 225, in graphql
    return await self._client.async_call_api(
  File "/usr/local/lib/python3.9/site-packages/aiogithubapi/client.py", line 140, in async_call_api
    raise exception(message or response.data)
aiogithubapi.exceptions.GitHubAuthenticationException: Bad credentials
2022-03-09 17:23:20 ERROR (MainThread) [homeassistant.components.github] Bad credentials
Traceback (most recent call last):
  File "/usr/src/homeassistant/homeassistant/components/github/coordinator.py", line 125, in _async_update_data
    response = await self._client.graphql(
  File "/usr/local/lib/python3.9/site-packages/aiogithubapi/github.py", line 225, in graphql
    return await self._client.async_call_api(
  File "/usr/local/lib/python3.9/site-packages/aiogithubapi/client.py", line 140, in async_call_api
    raise exception(message or response.data)
aiogithubapi.exceptions.GitHubAuthenticationException: Bad credentials
2022-03-09 17:23:32 WARNING (MainThread) [homeassistant.components.hassio] Can't read Supervisor data: Container addon_a0d7b954_phpmyadmin is not running
