2022-03-10 11:34:27 WARNING (Recorder) [homeassistant.components.recorder.util] The system could not validate that the sqlite3 database at //config/home-assistant_v2.db was shutdown cleanly
2022-03-10 11:34:27 WARNING (Recorder) [homeassistant.components.recorder.util] Ended unfinished session (id=5 from 2022-03-10 06:02:09.036093)
2022-03-10 11:34:30 ERROR (MainThread) [homeassistant.components.github] Bad credentials
Traceback (most recent call last):
  File "/usr/src/homeassistant/homeassistant/components/github/coordinator.py", line 125, in _async_update_data
    response = await self._client.graphql(
  File "/usr/local/lib/python3.9/site-packages/aiogithubapi/github.py", line 225, in graphql
    return await self._client.async_call_api(
  File "/usr/local/lib/python3.9/site-packages/aiogithubapi/client.py", line 140, in async_call_api
    raise exception(message or response.data)
aiogithubapi.exceptions.GitHubAuthenticationException: Bad credentials
2022-03-10 11:34:30 WARNING (MainThread) [homeassistant.config_entries] Config entry '' for github integration not ready yet: Bad credentials; Retrying in background
2022-03-10 11:34:32 ERROR (MainThread) [homeassistant.components.github] Bad credentials
Traceback (most recent call last):
  File "/usr/src/homeassistant/homeassistant/components/github/coordinator.py", line 125, in _async_update_data
    response = await self._client.graphql(
  File "/usr/local/lib/python3.9/site-packages/aiogithubapi/github.py", line 225, in graphql
    return await self._client.async_call_api(
  File "/usr/local/lib/python3.9/site-packages/aiogithubapi/client.py", line 140, in async_call_api
    raise exception(message or response.data)
aiogithubapi.exceptions.GitHubAuthenticationException: Bad credentials
2022-03-10 11:34:34 ERROR (Recorder) [homeassistant.components.recorder] Unrecoverable sqlite3 database corruption detected: (sqlite3.DatabaseError) database disk image is malformed
[SQL: INSERT INTO states (domain, entity_id, state, attributes, event_id, last_changed, last_updated, created, old_state_id) VALUES (?, ?, ?, ?, ?, ?, ?, ?, ?)]
[parameters: ('person', 'person.xtplsynergy', 'unknown', '{"editable":false,"id":"xtplsynergy","source":"person.xtplsynergy","user_id":"8dac49cf1d1c4553b1a211b92f45af75","friendly_name":"xtplsynergy"}', 1747, '2022-03-10 06:04:27.859064', '2022-03-10 06:04:27.859064', '2022-03-10 06:04:27.859064', None)]
(Background on this error at: https://sqlalche.me/e/14/4xp6)
Traceback (most recent call last):
  File "/usr/local/lib/python3.9/site-packages/sqlalchemy/engine/base.py", line 1802, in _execute_context
    self.dialect.do_execute(
  File "/usr/local/lib/python3.9/site-packages/sqlalchemy/engine/default.py", line 719, in do_execute
    cursor.execute(statement, parameters)
sqlite3.DatabaseError: database disk image is malformed

The above exception was the direct cause of the following exception:

Traceback (most recent call last):
  File "/usr/src/homeassistant/homeassistant/components/recorder/__init__.py", line 803, in _process_one_task_or_recover
    return task.run(self)
  File "/usr/src/homeassistant/homeassistant/components/recorder/__init__.py", line 478, in run
    instance._process_one_event(self.event)
  File "/usr/src/homeassistant/homeassistant/components/recorder/__init__.py", line 901, in _process_one_event
    self._commit_event_session_or_retry()
  File "/usr/src/homeassistant/homeassistant/components/recorder/__init__.py", line 964, in _commit_event_session_or_retry
    self._commit_event_session()
  File "/usr/src/homeassistant/homeassistant/components/recorder/__init__.py", line 983, in _commit_event_session
    self.event_session.flush()
  File "/usr/local/lib/python3.9/site-packages/sqlalchemy/orm/session.py", line 3345, in flush
    self._flush(objects)
  File "/usr/local/lib/python3.9/site-packages/sqlalchemy/orm/session.py", line 3485, in _flush
    transaction.rollback(_capture_exception=True)
  File "/usr/local/lib/python3.9/site-packages/sqlalchemy/util/langhelpers.py", line 70, in __exit__
    compat.raise_(
  File "/usr/local/lib/python3.9/site-packages/sqlalchemy/util/compat.py", line 207, in raise_
    raise exception
  File "/usr/local/lib/python3.9/site-packages/sqlalchemy/orm/session.py", line 3445, in _flush
    flush_context.execute()
  File "/usr/local/lib/python3.9/site-packages/sqlalchemy/orm/unitofwork.py", line 453, in execute
    n.execute_aggregate(self, set_)
  File "/usr/local/lib/python3.9/site-packages/sqlalchemy/orm/unitofwork.py", line 747, in execute_aggregate
    persistence.save_obj(
  File "/usr/local/lib/python3.9/site-packages/sqlalchemy/orm/persistence.py", line 244, in save_obj
    _emit_insert_statements(
  File "/usr/local/lib/python3.9/site-packages/sqlalchemy/orm/persistence.py", line 1221, in _emit_insert_statements
    result = connection._execute_20(
  File "/usr/local/lib/python3.9/site-packages/sqlalchemy/engine/base.py", line 1614, in _execute_20
    return meth(self, args_10style, kwargs_10style, execution_options)
  File "/usr/local/lib/python3.9/site-packages/sqlalchemy/sql/elements.py", line 325, in _execute_on_connection
    return connection._execute_clauseelement(
  File "/usr/local/lib/python3.9/site-packages/sqlalchemy/engine/base.py", line 1481, in _execute_clauseelement
    ret = self._execute_context(
  File "/usr/local/lib/python3.9/site-packages/sqlalchemy/engine/base.py", line 1845, in _execute_context
    self._handle_dbapi_exception(
  File "/usr/local/lib/python3.9/site-packages/sqlalchemy/engine/base.py", line 2026, in _handle_dbapi_exception
    util.raise_(
  File "/usr/local/lib/python3.9/site-packages/sqlalchemy/util/compat.py", line 207, in raise_
    raise exception
  File "/usr/local/lib/python3.9/site-packages/sqlalchemy/engine/base.py", line 1802, in _execute_context
    self.dialect.do_execute(
  File "/usr/local/lib/python3.9/site-packages/sqlalchemy/engine/default.py", line 719, in do_execute
    cursor.execute(statement, parameters)
sqlalchemy.exc.DatabaseError: (sqlite3.DatabaseError) database disk image is malformed
[SQL: INSERT INTO states (domain, entity_id, state, attributes, event_id, last_changed, last_updated, created, old_state_id) VALUES (?, ?, ?, ?, ?, ?, ?, ?, ?)]
[parameters: ('person', 'person.xtplsynergy', 'unknown', '{"editable":false,"id":"xtplsynergy","source":"person.xtplsynergy","user_id":"8dac49cf1d1c4553b1a211b92f45af75","friendly_name":"xtplsynergy"}', 1747, '2022-03-10 06:04:27.859064', '2022-03-10 06:04:27.859064', '2022-03-10 06:04:27.859064', None)]
(Background on this error at: https://sqlalche.me/e/14/4xp6)
2022-03-10 11:34:34 ERROR (Recorder) [homeassistant.components.recorder.util] The system will rename the corrupt database file //config/home-assistant_v2.db to //config/home-assistant_v2.db.corrupt.2022-03-10T06:04:34.146988+00:00 in order to allow startup to proceed
2022-03-10 11:35:05 ERROR (MainThread) [homeassistant.components.github] Bad credentials
Traceback (most recent call last):
  File "/usr/src/homeassistant/homeassistant/components/github/coordinator.py", line 125, in _async_update_data
    response = await self._client.graphql(
  File "/usr/local/lib/python3.9/site-packages/aiogithubapi/github.py", line 225, in graphql
    return await self._client.async_call_api(
  File "/usr/local/lib/python3.9/site-packages/aiogithubapi/client.py", line 140, in async_call_api
    raise exception(message or response.data)
aiogithubapi.exceptions.GitHubAuthenticationException: Bad credentials
2022-03-10 11:35:25 ERROR (MainThread) [homeassistant.components.github] Bad credentials
Traceback (most recent call last):
  File "/usr/src/homeassistant/homeassistant/components/github/coordinator.py", line 125, in _async_update_data
    response = await self._client.graphql(
  File "/usr/local/lib/python3.9/site-packages/aiogithubapi/github.py", line 225, in graphql
    return await self._client.async_call_api(
  File "/usr/local/lib/python3.9/site-packages/aiogithubapi/client.py", line 140, in async_call_api
    raise exception(message or response.data)
aiogithubapi.exceptions.GitHubAuthenticationException: Bad credentials
