2022-03-10 11:34:27 WARNING (Recorder) [homeassistant.components.recorder.util] The system could not validate that the sqlite3 database at //config/home-assistant_v2.db was shutdown cleanly
2022-03-10 11:34:27 WARNING (Recorder) [homeassistant.components.recorder.util] Ended unfinished session (id=5 from 2022-03-10 06:02:09.036093)
2022-03-10 11:34:30 ERROR (MainThread) [homeassistant.components.github] Bad credentials
Traceback (most recent call last):
  File "/usr/src/homeassistant/homeassistant/components/github/coordinator.py", line 125, in _async_update_data
    response = await self._client.graphql(
  File "/usr/local/lib/python3.9/site-packages/aiogithubapi/github.py", line 225, in graphql
    return await self._client.async_call_api(
  File "/usr/local/lib/python3.9/site-packages/aiogithubapi/client.py", line 140, in async_call_api
    raise exception(message or response.data)
aiogithubapi.exceptions.GitHubAuthenticationException: Bad credentials
2022-03-10 11:34:30 WARNING (MainThread) [homeassistant.config_entries] Config entry '' for github integration not ready yet: Bad credentials; Retrying in background
2022-03-10 11:34:32 ERROR (MainThread) [homeassistant.components.github] Bad credentials
Traceback (most recent call last):
  File "/usr/src/homeassistant/homeassistant/components/github/coordinator.py", line 125, in _async_update_data
    response = await self._client.graphql(
  File "/usr/local/lib/python3.9/site-packages/aiogithubapi/github.py", line 225, in graphql
    return await self._client.async_call_api(
  File "/usr/local/lib/python3.9/site-packages/aiogithubapi/client.py", line 140, in async_call_api
    raise exception(message or response.data)
aiogithubapi.exceptions.GitHubAuthenticationException: Bad credentials
2022-03-10 11:34:34 ERROR (Recorder) [homeassistant.components.recorder] Unrecoverable sqlite3 database corruption detected: (sqlite3.DatabaseError) database disk image is malformed
[SQL: INSERT INTO states (domain, entity_id, state, attributes, event_id, last_changed, last_updated, created, old_state_id) VALUES (?, ?, ?, ?, ?, ?, ?, ?, ?)]
[parameters: ('person', 'person.xtplsynergy', 'unknown', '{"editable":false,"id":"xtplsynergy","source":"person.xtplsynergy","user_id":"8dac49cf1d1c4553b1a211b92f45af75","friendly_name":"xtplsynergy"}', 1747, '2022-03-10 06:04:27.859064', '2022-03-10 06:04:27.859064', '2022-03-10 06:04:27.859064', None)]
(Background on this error at: https://sqlalche.me/e/14/4xp6)
Traceback (most recent call last):
  File "/usr/local/lib/python3.9/site-packages/sqlalchemy/engine/base.py", line 1802, in _execute_context
    self.dialect.do_execute(
  File "/usr/local/lib/python3.9/site-packages/sqlalchemy/engine/default.py", line 719, in do_execute
    cursor.execute(statement, parameters)
sqlite3.DatabaseError: database disk image is malformed

The above exception was the direct cause of the following exception:

Traceback (most recent call last):
  File "/usr/src/homeassistant/homeassistant/components/recorder/__init__.py", line 803, in _process_one_task_or_recover
    return task.run(self)
  File "/usr/src/homeassistant/homeassistant/components/recorder/__init__.py", line 478, in run
    instance._process_one_event(self.event)
  File "/usr/src/homeassistant/homeassistant/components/recorder/__init__.py", line 901, in _process_one_event
    self._commit_event_session_or_retry()
  File "/usr/src/homeassistant/homeassistant/components/recorder/__init__.py", line 964, in _commit_event_session_or_retry
    self._commit_event_session()
  File "/usr/src/homeassistant/homeassistant/components/recorder/__init__.py", line 983, in _commit_event_session
    self.event_session.flush()
  File "/usr/local/lib/python3.9/site-packages/sqlalchemy/orm/session.py", line 3345, in flush
    self._flush(objects)
  File "/usr/local/lib/python3.9/site-packages/sqlalchemy/orm/session.py", line 3485, in _flush
    transaction.rollback(_capture_exception=True)
  File "/usr/local/lib/python3.9/site-packages/sqlalchemy/util/langhelpers.py", line 70, in __exit__
    compat.raise_(
  File "/usr/local/lib/python3.9/site-packages/sqlalchemy/util/compat.py", line 207, in raise_
    raise exception
  File "/usr/local/lib/python3.9/site-packages/sqlalchemy/orm/session.py", line 3445, in _flush
    flush_context.execute()
  File "/usr/local/lib/python3.9/site-packages/sqlalchemy/orm/unitofwork.py", line 453, in execute
    n.execute_aggregate(self, set_)
  File "/usr/local/lib/python3.9/site-packages/sqlalchemy/orm/unitofwork.py", line 747, in execute_aggregate
    persistence.save_obj(
  File "/usr/local/lib/python3.9/site-packages/sqlalchemy/orm/persistence.py", line 244, in save_obj
    _emit_insert_statements(
  File "/usr/local/lib/python3.9/site-packages/sqlalchemy/orm/persistence.py", line 1221, in _emit_insert_statements
    result = connection._execute_20(
  File "/usr/local/lib/python3.9/site-packages/sqlalchemy/engine/base.py", line 1614, in _execute_20
    return meth(self, args_10style, kwargs_10style, execution_options)
  File "/usr/local/lib/python3.9/site-packages/sqlalchemy/sql/elements.py", line 325, in _execute_on_connection
    return connection._execute_clauseelement(
  File "/usr/local/lib/python3.9/site-packages/sqlalchemy/engine/base.py", line 1481, in _execute_clauseelement
    ret = self._execute_context(
  File "/usr/local/lib/python3.9/site-packages/sqlalchemy/engine/base.py", line 1845, in _execute_context
    self._handle_dbapi_exception(
  File "/usr/local/lib/python3.9/site-packages/sqlalchemy/engine/base.py", line 2026, in _handle_dbapi_exception
    util.raise_(
  File "/usr/local/lib/python3.9/site-packages/sqlalchemy/util/compat.py", line 207, in raise_
    raise exception
  File "/usr/local/lib/python3.9/site-packages/sqlalchemy/engine/base.py", line 1802, in _execute_context
    self.dialect.do_execute(
  File "/usr/local/lib/python3.9/site-packages/sqlalchemy/engine/default.py", line 719, in do_execute
    cursor.execute(statement, parameters)
sqlalchemy.exc.DatabaseError: (sqlite3.DatabaseError) database disk image is malformed
[SQL: INSERT INTO states (domain, entity_id, state, attributes, event_id, last_changed, last_updated, created, old_state_id) VALUES (?, ?, ?, ?, ?, ?, ?, ?, ?)]
[parameters: ('person', 'person.xtplsynergy', 'unknown', '{"editable":false,"id":"xtplsynergy","source":"person.xtplsynergy","user_id":"8dac49cf1d1c4553b1a211b92f45af75","friendly_name":"xtplsynergy"}', 1747, '2022-03-10 06:04:27.859064', '2022-03-10 06:04:27.859064', '2022-03-10 06:04:27.859064', None)]
(Background on this error at: https://sqlalche.me/e/14/4xp6)
2022-03-10 11:34:34 ERROR (Recorder) [homeassistant.components.recorder.util] The system will rename the corrupt database file //config/home-assistant_v2.db to //config/home-assistant_v2.db.corrupt.2022-03-10T06:04:34.146988+00:00 in order to allow startup to proceed
2022-03-10 11:35:05 ERROR (MainThread) [homeassistant.components.github] Bad credentials
Traceback (most recent call last):
  File "/usr/src/homeassistant/homeassistant/components/github/coordinator.py", line 125, in _async_update_data
    response = await self._client.graphql(
  File "/usr/local/lib/python3.9/site-packages/aiogithubapi/github.py", line 225, in graphql
    return await self._client.async_call_api(
  File "/usr/local/lib/python3.9/site-packages/aiogithubapi/client.py", line 140, in async_call_api
    raise exception(message or response.data)
aiogithubapi.exceptions.GitHubAuthenticationException: Bad credentials
2022-03-10 11:35:25 ERROR (MainThread) [homeassistant.components.github] Bad credentials
Traceback (most recent call last):
  File "/usr/src/homeassistant/homeassistant/components/github/coordinator.py", line 125, in _async_update_data
    response = await self._client.graphql(
  File "/usr/local/lib/python3.9/site-packages/aiogithubapi/github.py", line 225, in graphql
    return await self._client.async_call_api(
  File "/usr/local/lib/python3.9/site-packages/aiogithubapi/client.py", line 140, in async_call_api
    raise exception(message or response.data)
aiogithubapi.exceptions.GitHubAuthenticationException: Bad credentials
2022-03-10 11:36:06 ERROR (MainThread) [homeassistant.components.github] Bad credentials
Traceback (most recent call last):
  File "/usr/src/homeassistant/homeassistant/components/github/coordinator.py", line 125, in _async_update_data
    response = await self._client.graphql(
  File "/usr/local/lib/python3.9/site-packages/aiogithubapi/github.py", line 225, in graphql
    return await self._client.async_call_api(
  File "/usr/local/lib/python3.9/site-packages/aiogithubapi/client.py", line 140, in async_call_api
    raise exception(message or response.data)
aiogithubapi.exceptions.GitHubAuthenticationException: Bad credentials
2022-03-10 11:36:24 ERROR (MainThread) [homeassistant.components.hassio.handler] /ingress/validate_session return code 401
2022-03-10 11:36:24 ERROR (MainThread) [homeassistant.components.hassio] Failed to to call /ingress/validate_session - 
2022-03-10 11:36:24 ERROR (MainThread) [homeassistant.components.hassio.handler] /ingress/validate_session return code 401
2022-03-10 11:36:24 ERROR (MainThread) [homeassistant.components.hassio] Failed to to call /ingress/validate_session - 
2022-03-10 11:36:24 ERROR (MainThread) [homeassistant.components.hassio.handler] /ingress/validate_session return code 401
2022-03-10 11:36:24 ERROR (MainThread) [homeassistant.components.hassio] Failed to to call /ingress/validate_session - 
2022-03-10 11:37:27 ERROR (MainThread) [homeassistant.components.github] Bad credentials
Traceback (most recent call last):
  File "/usr/src/homeassistant/homeassistant/components/github/coordinator.py", line 125, in _async_update_data
    response = await self._client.graphql(
  File "/usr/local/lib/python3.9/site-packages/aiogithubapi/github.py", line 225, in graphql
    return await self._client.async_call_api(
  File "/usr/local/lib/python3.9/site-packages/aiogithubapi/client.py", line 140, in async_call_api
    raise exception(message or response.data)
aiogithubapi.exceptions.GitHubAuthenticationException: Bad credentials
2022-03-10 11:38:47 ERROR (MainThread) [homeassistant.components.github] Bad credentials
Traceback (most recent call last):
  File "/usr/src/homeassistant/homeassistant/components/github/coordinator.py", line 125, in _async_update_data
    response = await self._client.graphql(
  File "/usr/local/lib/python3.9/site-packages/aiogithubapi/github.py", line 225, in graphql
    return await self._client.async_call_api(
  File "/usr/local/lib/python3.9/site-packages/aiogithubapi/client.py", line 140, in async_call_api
    raise exception(message or response.data)
aiogithubapi.exceptions.GitHubAuthenticationException: Bad credentials
2022-03-10 11:39:52 WARNING (MainThread) [homeassistant.components.hassio] Can't read Supervisor data: Container addon_a0d7b954_phpmyadmin is not running
2022-03-10 11:40:08 ERROR (MainThread) [homeassistant.components.github] Bad credentials
Traceback (most recent call last):
  File "/usr/src/homeassistant/homeassistant/components/github/coordinator.py", line 125, in _async_update_data
    response = await self._client.graphql(
  File "/usr/local/lib/python3.9/site-packages/aiogithubapi/github.py", line 225, in graphql
    return await self._client.async_call_api(
  File "/usr/local/lib/python3.9/site-packages/aiogithubapi/client.py", line 140, in async_call_api
    raise exception(message or response.data)
aiogithubapi.exceptions.GitHubAuthenticationException: Bad credentials
2022-03-10 11:41:28 ERROR (MainThread) [homeassistant.components.github] Bad credentials
Traceback (most recent call last):
  File "/usr/src/homeassistant/homeassistant/components/github/coordinator.py", line 125, in _async_update_data
    response = await self._client.graphql(
  File "/usr/local/lib/python3.9/site-packages/aiogithubapi/github.py", line 225, in graphql
    return await self._client.async_call_api(
  File "/usr/local/lib/python3.9/site-packages/aiogithubapi/client.py", line 140, in async_call_api
    raise exception(message or response.data)
aiogithubapi.exceptions.GitHubAuthenticationException: Bad credentials
2022-03-10 11:42:49 ERROR (MainThread) [homeassistant.components.github] Bad credentials
Traceback (most recent call last):
  File "/usr/src/homeassistant/homeassistant/components/github/coordinator.py", line 125, in _async_update_data
    response = await self._client.graphql(
  File "/usr/local/lib/python3.9/site-packages/aiogithubapi/github.py", line 225, in graphql
    return await self._client.async_call_api(
  File "/usr/local/lib/python3.9/site-packages/aiogithubapi/client.py", line 140, in async_call_api
    raise exception(message or response.data)
aiogithubapi.exceptions.GitHubAuthenticationException: Bad credentials
2022-03-10 11:44:10 ERROR (MainThread) [homeassistant.components.github] Bad credentials
Traceback (most recent call last):
  File "/usr/src/homeassistant/homeassistant/components/github/coordinator.py", line 125, in _async_update_data
    response = await self._client.graphql(
  File "/usr/local/lib/python3.9/site-packages/aiogithubapi/github.py", line 225, in graphql
    return await self._client.async_call_api(
  File "/usr/local/lib/python3.9/site-packages/aiogithubapi/client.py", line 140, in async_call_api
    raise exception(message or response.data)
aiogithubapi.exceptions.GitHubAuthenticationException: Bad credentials
2022-03-10 11:44:52 WARNING (MainThread) [homeassistant.components.hassio] Can't read Supervisor data: Container addon_a0d7b954_phpmyadmin is not running
2022-03-10 11:45:30 ERROR (MainThread) [homeassistant.components.github] Bad credentials
Traceback (most recent call last):
  File "/usr/src/homeassistant/homeassistant/components/github/coordinator.py", line 125, in _async_update_data
    response = await self._client.graphql(
  File "/usr/local/lib/python3.9/site-packages/aiogithubapi/github.py", line 225, in graphql
    return await self._client.async_call_api(
  File "/usr/local/lib/python3.9/site-packages/aiogithubapi/client.py", line 140, in async_call_api
    raise exception(message or response.data)
aiogithubapi.exceptions.GitHubAuthenticationException: Bad credentials
2022-03-10 11:46:51 ERROR (MainThread) [homeassistant.components.github] Bad credentials
Traceback (most recent call last):
  File "/usr/src/homeassistant/homeassistant/components/github/coordinator.py", line 125, in _async_update_data
    response = await self._client.graphql(
  File "/usr/local/lib/python3.9/site-packages/aiogithubapi/github.py", line 225, in graphql
    return await self._client.async_call_api(
  File "/usr/local/lib/python3.9/site-packages/aiogithubapi/client.py", line 140, in async_call_api
    raise exception(message or response.data)
aiogithubapi.exceptions.GitHubAuthenticationException: Bad credentials
2022-03-10 11:48:12 ERROR (MainThread) [homeassistant.components.github] Bad credentials
Traceback (most recent call last):
  File "/usr/src/homeassistant/homeassistant/components/github/coordinator.py", line 125, in _async_update_data
    response = await self._client.graphql(
  File "/usr/local/lib/python3.9/site-packages/aiogithubapi/github.py", line 225, in graphql
    return await self._client.async_call_api(
  File "/usr/local/lib/python3.9/site-packages/aiogithubapi/client.py", line 140, in async_call_api
    raise exception(message or response.data)
aiogithubapi.exceptions.GitHubAuthenticationException: Bad credentials
2022-03-10 11:49:32 ERROR (MainThread) [homeassistant.components.github] Bad credentials
Traceback (most recent call last):
  File "/usr/src/homeassistant/homeassistant/components/github/coordinator.py", line 125, in _async_update_data
    response = await self._client.graphql(
  File "/usr/local/lib/python3.9/site-packages/aiogithubapi/github.py", line 225, in graphql
    return await self._client.async_call_api(
  File "/usr/local/lib/python3.9/site-packages/aiogithubapi/client.py", line 140, in async_call_api
    raise exception(message or response.data)
aiogithubapi.exceptions.GitHubAuthenticationException: Bad credentials
2022-03-10 11:49:52 WARNING (MainThread) [homeassistant.components.hassio] Can't read Supervisor data: Container addon_a0d7b954_phpmyadmin is not running
2022-03-10 11:50:53 ERROR (MainThread) [homeassistant.components.github] Bad credentials
Traceback (most recent call last):
  File "/usr/src/homeassistant/homeassistant/components/github/coordinator.py", line 125, in _async_update_data
    response = await self._client.graphql(
  File "/usr/local/lib/python3.9/site-packages/aiogithubapi/github.py", line 225, in graphql
    return await self._client.async_call_api(
  File "/usr/local/lib/python3.9/site-packages/aiogithubapi/client.py", line 140, in async_call_api
    raise exception(message or response.data)
aiogithubapi.exceptions.GitHubAuthenticationException: Bad credentials
2022-03-10 11:52:13 ERROR (MainThread) [homeassistant.components.github] Bad credentials
Traceback (most recent call last):
  File "/usr/src/homeassistant/homeassistant/components/github/coordinator.py", line 125, in _async_update_data
    response = await self._client.graphql(
  File "/usr/local/lib/python3.9/site-packages/aiogithubapi/github.py", line 225, in graphql
    return await self._client.async_call_api(
  File "/usr/local/lib/python3.9/site-packages/aiogithubapi/client.py", line 140, in async_call_api
    raise exception(message or response.data)
aiogithubapi.exceptions.GitHubAuthenticationException: Bad credentials
2022-03-10 11:53:34 ERROR (MainThread) [homeassistant.components.github] Bad credentials
Traceback (most recent call last):
  File "/usr/src/homeassistant/homeassistant/components/github/coordinator.py", line 125, in _async_update_data
    response = await self._client.graphql(
  File "/usr/local/lib/python3.9/site-packages/aiogithubapi/github.py", line 225, in graphql
    return await self._client.async_call_api(
  File "/usr/local/lib/python3.9/site-packages/aiogithubapi/client.py", line 140, in async_call_api
    raise exception(message or response.data)
aiogithubapi.exceptions.GitHubAuthenticationException: Bad credentials
2022-03-10 11:54:53 WARNING (MainThread) [homeassistant.components.hassio] Can't read Supervisor data: Container addon_a0d7b954_phpmyadmin is not running
2022-03-10 11:54:55 ERROR (MainThread) [homeassistant.components.github] Bad credentials
Traceback (most recent call last):
  File "/usr/src/homeassistant/homeassistant/components/github/coordinator.py", line 125, in _async_update_data
    response = await self._client.graphql(
  File "/usr/local/lib/python3.9/site-packages/aiogithubapi/github.py", line 225, in graphql
    return await self._client.async_call_api(
  File "/usr/local/lib/python3.9/site-packages/aiogithubapi/client.py", line 140, in async_call_api
    raise exception(message or response.data)
aiogithubapi.exceptions.GitHubAuthenticationException: Bad credentials
2022-03-10 11:56:15 ERROR (MainThread) [homeassistant.components.github] Bad credentials
Traceback (most recent call last):
  File "/usr/src/homeassistant/homeassistant/components/github/coordinator.py", line 125, in _async_update_data
    response = await self._client.graphql(
  File "/usr/local/lib/python3.9/site-packages/aiogithubapi/github.py", line 225, in graphql
    return await self._client.async_call_api(
  File "/usr/local/lib/python3.9/site-packages/aiogithubapi/client.py", line 140, in async_call_api
    raise exception(message or response.data)
aiogithubapi.exceptions.GitHubAuthenticationException: Bad credentials
2022-03-10 11:57:36 ERROR (MainThread) [homeassistant.components.github] Bad credentials
Traceback (most recent call last):
  File "/usr/src/homeassistant/homeassistant/components/github/coordinator.py", line 125, in _async_update_data
    response = await self._client.graphql(
  File "/usr/local/lib/python3.9/site-packages/aiogithubapi/github.py", line 225, in graphql
    return await self._client.async_call_api(
  File "/usr/local/lib/python3.9/site-packages/aiogithubapi/client.py", line 140, in async_call_api
    raise exception(message or response.data)
aiogithubapi.exceptions.GitHubAuthenticationException: Bad credentials
2022-03-10 11:58:57 ERROR (MainThread) [homeassistant.components.github] Bad credentials
Traceback (most recent call last):
  File "/usr/src/homeassistant/homeassistant/components/github/coordinator.py", line 125, in _async_update_data
    response = await self._client.graphql(
  File "/usr/local/lib/python3.9/site-packages/aiogithubapi/github.py", line 225, in graphql
    return await self._client.async_call_api(
  File "/usr/local/lib/python3.9/site-packages/aiogithubapi/client.py", line 140, in async_call_api
    raise exception(message or response.data)
aiogithubapi.exceptions.GitHubAuthenticationException: Bad credentials
2022-03-10 12:00:17 ERROR (MainThread) [homeassistant.components.github] Bad credentials
Traceback (most recent call last):
  File "/usr/src/homeassistant/homeassistant/components/github/coordinator.py", line 125, in _async_update_data
    response = await self._client.graphql(
  File "/usr/local/lib/python3.9/site-packages/aiogithubapi/github.py", line 225, in graphql
    return await self._client.async_call_api(
  File "/usr/local/lib/python3.9/site-packages/aiogithubapi/client.py", line 140, in async_call_api
    raise exception(message or response.data)
aiogithubapi.exceptions.GitHubAuthenticationException: Bad credentials
2022-03-10 12:01:38 ERROR (MainThread) [homeassistant.components.github] Bad credentials
Traceback (most recent call last):
  File "/usr/src/homeassistant/homeassistant/components/github/coordinator.py", line 125, in _async_update_data
    response = await self._client.graphql(
  File "/usr/local/lib/python3.9/site-packages/aiogithubapi/github.py", line 225, in graphql
    return await self._client.async_call_api(
  File "/usr/local/lib/python3.9/site-packages/aiogithubapi/client.py", line 140, in async_call_api
    raise exception(message or response.data)
aiogithubapi.exceptions.GitHubAuthenticationException: Bad credentials
2022-03-10 12:02:58 ERROR (MainThread) [homeassistant.components.github] Bad credentials
Traceback (most recent call last):
  File "/usr/src/homeassistant/homeassistant/components/github/coordinator.py", line 125, in _async_update_data
    response = await self._client.graphql(
  File "/usr/local/lib/python3.9/site-packages/aiogithubapi/github.py", line 225, in graphql
    return await self._client.async_call_api(
  File "/usr/local/lib/python3.9/site-packages/aiogithubapi/client.py", line 140, in async_call_api
    raise exception(message or response.data)
aiogithubapi.exceptions.GitHubAuthenticationException: Bad credentials
2022-03-10 12:04:19 ERROR (MainThread) [homeassistant.components.github] Bad credentials
Traceback (most recent call last):
  File "/usr/src/homeassistant/homeassistant/components/github/coordinator.py", line 125, in _async_update_data
    response = await self._client.graphql(
  File "/usr/local/lib/python3.9/site-packages/aiogithubapi/github.py", line 225, in graphql
    return await self._client.async_call_api(
  File "/usr/local/lib/python3.9/site-packages/aiogithubapi/client.py", line 140, in async_call_api
    raise exception(message or response.data)
aiogithubapi.exceptions.GitHubAuthenticationException: Bad credentials
2022-03-10 12:05:40 ERROR (MainThread) [homeassistant.components.github] Bad credentials
Traceback (most recent call last):
  File "/usr/src/homeassistant/homeassistant/components/github/coordinator.py", line 125, in _async_update_data
    response = await self._client.graphql(
  File "/usr/local/lib/python3.9/site-packages/aiogithubapi/github.py", line 225, in graphql
    return await self._client.async_call_api(
  File "/usr/local/lib/python3.9/site-packages/aiogithubapi/client.py", line 140, in async_call_api
    raise exception(message or response.data)
aiogithubapi.exceptions.GitHubAuthenticationException: Bad credentials
2022-03-10 12:07:00 ERROR (MainThread) [homeassistant.components.github] Bad credentials
Traceback (most recent call last):
  File "/usr/src/homeassistant/homeassistant/components/github/coordinator.py", line 125, in _async_update_data
    response = await self._client.graphql(
  File "/usr/local/lib/python3.9/site-packages/aiogithubapi/github.py", line 225, in graphql
    return await self._client.async_call_api(
  File "/usr/local/lib/python3.9/site-packages/aiogithubapi/client.py", line 140, in async_call_api
    raise exception(message or response.data)
aiogithubapi.exceptions.GitHubAuthenticationException: Bad credentials
2022-03-10 12:08:21 ERROR (MainThread) [homeassistant.components.github] Bad credentials
Traceback (most recent call last):
  File "/usr/src/homeassistant/homeassistant/components/github/coordinator.py", line 125, in _async_update_data
    response = await self._client.graphql(
  File "/usr/local/lib/python3.9/site-packages/aiogithubapi/github.py", line 225, in graphql
    return await self._client.async_call_api(
  File "/usr/local/lib/python3.9/site-packages/aiogithubapi/client.py", line 140, in async_call_api
    raise exception(message or response.data)
aiogithubapi.exceptions.GitHubAuthenticationException: Bad credentials
2022-03-10 12:09:42 ERROR (MainThread) [homeassistant.components.github] Bad credentials
Traceback (most recent call last):
  File "/usr/src/homeassistant/homeassistant/components/github/coordinator.py", line 125, in _async_update_data
    response = await self._client.graphql(
  File "/usr/local/lib/python3.9/site-packages/aiogithubapi/github.py", line 225, in graphql
    return await self._client.async_call_api(
  File "/usr/local/lib/python3.9/site-packages/aiogithubapi/client.py", line 140, in async_call_api
    raise exception(message or response.data)
aiogithubapi.exceptions.GitHubAuthenticationException: Bad credentials
2022-03-10 12:11:02 ERROR (MainThread) [homeassistant.components.github] Bad credentials
Traceback (most recent call last):
  File "/usr/src/homeassistant/homeassistant/components/github/coordinator.py", line 125, in _async_update_data
    response = await self._client.graphql(
  File "/usr/local/lib/python3.9/site-packages/aiogithubapi/github.py", line 225, in graphql
    return await self._client.async_call_api(
  File "/usr/local/lib/python3.9/site-packages/aiogithubapi/client.py", line 140, in async_call_api
    raise exception(message or response.data)
aiogithubapi.exceptions.GitHubAuthenticationException: Bad credentials
2022-03-10 12:12:23 ERROR (MainThread) [homeassistant.components.github] Bad credentials
Traceback (most recent call last):
  File "/usr/src/homeassistant/homeassistant/components/github/coordinator.py", line 125, in _async_update_data
    response = await self._client.graphql(
  File "/usr/local/lib/python3.9/site-packages/aiogithubapi/github.py", line 225, in graphql
    return await self._client.async_call_api(
  File "/usr/local/lib/python3.9/site-packages/aiogithubapi/client.py", line 140, in async_call_api
    raise exception(message or response.data)
aiogithubapi.exceptions.GitHubAuthenticationException: Bad credentials
2022-03-10 12:13:43 ERROR (MainThread) [homeassistant.components.github] Bad credentials
Traceback (most recent call last):
  File "/usr/src/homeassistant/homeassistant/components/github/coordinator.py", line 125, in _async_update_data
    response = await self._client.graphql(
  File "/usr/local/lib/python3.9/site-packages/aiogithubapi/github.py", line 225, in graphql
    return await self._client.async_call_api(
  File "/usr/local/lib/python3.9/site-packages/aiogithubapi/client.py", line 140, in async_call_api
    raise exception(message or response.data)
aiogithubapi.exceptions.GitHubAuthenticationException: Bad credentials
2022-03-10 12:15:02 WARNING (MainThread) [homeassistant.components.hassio] Can't read Supervisor data: Container addon_a0d7b954_phpmyadmin is not running
2022-03-10 12:15:04 ERROR (MainThread) [homeassistant.components.github] Bad credentials
Traceback (most recent call last):
  File "/usr/src/homeassistant/homeassistant/components/github/coordinator.py", line 125, in _async_update_data
    response = await self._client.graphql(
  File "/usr/local/lib/python3.9/site-packages/aiogithubapi/github.py", line 225, in graphql
    return await self._client.async_call_api(
  File "/usr/local/lib/python3.9/site-packages/aiogithubapi/client.py", line 140, in async_call_api
    raise exception(message or response.data)
aiogithubapi.exceptions.GitHubAuthenticationException: Bad credentials
2022-03-10 12:16:25 ERROR (MainThread) [homeassistant.components.github] Bad credentials
Traceback (most recent call last):
  File "/usr/src/homeassistant/homeassistant/components/github/coordinator.py", line 125, in _async_update_data
    response = await self._client.graphql(
  File "/usr/local/lib/python3.9/site-packages/aiogithubapi/github.py", line 225, in graphql
    return await self._client.async_call_api(
  File "/usr/local/lib/python3.9/site-packages/aiogithubapi/client.py", line 140, in async_call_api
    raise exception(message or response.data)
aiogithubapi.exceptions.GitHubAuthenticationException: Bad credentials
2022-03-10 12:17:45 ERROR (MainThread) [homeassistant.components.github] Bad credentials
Traceback (most recent call last):
  File "/usr/src/homeassistant/homeassistant/components/github/coordinator.py", line 125, in _async_update_data
    response = await self._client.graphql(
  File "/usr/local/lib/python3.9/site-packages/aiogithubapi/github.py", line 225, in graphql
    return await self._client.async_call_api(
  File "/usr/local/lib/python3.9/site-packages/aiogithubapi/client.py", line 140, in async_call_api
    raise exception(message or response.data)
aiogithubapi.exceptions.GitHubAuthenticationException: Bad credentials
2022-03-10 12:19:06 ERROR (MainThread) [homeassistant.components.github] Bad credentials
Traceback (most recent call last):
  File "/usr/src/homeassistant/homeassistant/components/github/coordinator.py", line 125, in _async_update_data
    response = await self._client.graphql(
  File "/usr/local/lib/python3.9/site-packages/aiogithubapi/github.py", line 225, in graphql
    return await self._client.async_call_api(
  File "/usr/local/lib/python3.9/site-packages/aiogithubapi/client.py", line 140, in async_call_api
    raise exception(message or response.data)
aiogithubapi.exceptions.GitHubAuthenticationException: Bad credentials
2022-03-10 12:20:02 WARNING (MainThread) [homeassistant.components.hassio] Can't read Supervisor data: Container addon_a0d7b954_phpmyadmin is not running
2022-03-10 12:20:26 ERROR (MainThread) [homeassistant.components.github] Bad credentials
Traceback (most recent call last):
  File "/usr/src/homeassistant/homeassistant/components/github/coordinator.py", line 125, in _async_update_data
    response = await self._client.graphql(
  File "/usr/local/lib/python3.9/site-packages/aiogithubapi/github.py", line 225, in graphql
    return await self._client.async_call_api(
  File "/usr/local/lib/python3.9/site-packages/aiogithubapi/client.py", line 140, in async_call_api
    raise exception(message or response.data)
aiogithubapi.exceptions.GitHubAuthenticationException: Bad credentials
2022-03-10 12:21:47 ERROR (MainThread) [homeassistant.components.github] Bad credentials
Traceback (most recent call last):
  File "/usr/src/homeassistant/homeassistant/components/github/coordinator.py", line 125, in _async_update_data
    response = await self._client.graphql(
  File "/usr/local/lib/python3.9/site-packages/aiogithubapi/github.py", line 225, in graphql
    return await self._client.async_call_api(
  File "/usr/local/lib/python3.9/site-packages/aiogithubapi/client.py", line 140, in async_call_api
    raise exception(message or response.data)
aiogithubapi.exceptions.GitHubAuthenticationException: Bad credentials
2022-03-10 12:23:08 ERROR (MainThread) [homeassistant.components.github] Bad credentials
Traceback (most recent call last):
  File "/usr/src/homeassistant/homeassistant/components/github/coordinator.py", line 125, in _async_update_data
    response = await self._client.graphql(
  File "/usr/local/lib/python3.9/site-packages/aiogithubapi/github.py", line 225, in graphql
    return await self._client.async_call_api(
  File "/usr/local/lib/python3.9/site-packages/aiogithubapi/client.py", line 140, in async_call_api
    raise exception(message or response.data)
aiogithubapi.exceptions.GitHubAuthenticationException: Bad credentials
2022-03-10 12:24:28 ERROR (MainThread) [homeassistant.components.github] Bad credentials
Traceback (most recent call last):
  File "/usr/src/homeassistant/homeassistant/components/github/coordinator.py", line 125, in _async_update_data
    response = await self._client.graphql(
  File "/usr/local/lib/python3.9/site-packages/aiogithubapi/github.py", line 225, in graphql
    return await self._client.async_call_api(
  File "/usr/local/lib/python3.9/site-packages/aiogithubapi/client.py", line 140, in async_call_api
    raise exception(message or response.data)
aiogithubapi.exceptions.GitHubAuthenticationException: Bad credentials
2022-03-10 12:25:02 WARNING (MainThread) [homeassistant.components.hassio] Can't read Supervisor data: Container addon_a0d7b954_phpmyadmin is not running
2022-03-10 12:25:49 ERROR (MainThread) [homeassistant.components.github] Bad credentials
Traceback (most recent call last):
  File "/usr/src/homeassistant/homeassistant/components/github/coordinator.py", line 125, in _async_update_data
    response = await self._client.graphql(
  File "/usr/local/lib/python3.9/site-packages/aiogithubapi/github.py", line 225, in graphql
    return await self._client.async_call_api(
  File "/usr/local/lib/python3.9/site-packages/aiogithubapi/client.py", line 140, in async_call_api
    raise exception(message or response.data)
aiogithubapi.exceptions.GitHubAuthenticationException: Bad credentials
2022-03-10 12:27:09 ERROR (MainThread) [homeassistant.components.github] Bad credentials
Traceback (most recent call last):
  File "/usr/src/homeassistant/homeassistant/components/github/coordinator.py", line 125, in _async_update_data
    response = await self._client.graphql(
  File "/usr/local/lib/python3.9/site-packages/aiogithubapi/github.py", line 225, in graphql
    return await self._client.async_call_api(
  File "/usr/local/lib/python3.9/site-packages/aiogithubapi/client.py", line 140, in async_call_api
    raise exception(message or response.data)
aiogithubapi.exceptions.GitHubAuthenticationException: Bad credentials
2022-03-10 12:28:30 ERROR (MainThread) [homeassistant.components.github] Bad credentials
Traceback (most recent call last):
  File "/usr/src/homeassistant/homeassistant/components/github/coordinator.py", line 125, in _async_update_data
    response = await self._client.graphql(
  File "/usr/local/lib/python3.9/site-packages/aiogithubapi/github.py", line 225, in graphql
    return await self._client.async_call_api(
  File "/usr/local/lib/python3.9/site-packages/aiogithubapi/client.py", line 140, in async_call_api
    raise exception(message or response.data)
aiogithubapi.exceptions.GitHubAuthenticationException: Bad credentials
2022-03-10 12:29:51 ERROR (MainThread) [homeassistant.components.github] Bad credentials
Traceback (most recent call last):
  File "/usr/src/homeassistant/homeassistant/components/github/coordinator.py", line 125, in _async_update_data
    response = await self._client.graphql(
  File "/usr/local/lib/python3.9/site-packages/aiogithubapi/github.py", line 225, in graphql
    return await self._client.async_call_api(
  File "/usr/local/lib/python3.9/site-packages/aiogithubapi/client.py", line 140, in async_call_api
    raise exception(message or response.data)
aiogithubapi.exceptions.GitHubAuthenticationException: Bad credentials
2022-03-10 12:30:02 WARNING (MainThread) [homeassistant.components.hassio] Can't read Supervisor data: Container addon_a0d7b954_phpmyadmin is not running
2022-03-10 12:31:11 ERROR (MainThread) [homeassistant.components.github] Bad credentials
Traceback (most recent call last):
  File "/usr/src/homeassistant/homeassistant/components/github/coordinator.py", line 125, in _async_update_data
    response = await self._client.graphql(
  File "/usr/local/lib/python3.9/site-packages/aiogithubapi/github.py", line 225, in graphql
    return await self._client.async_call_api(
  File "/usr/local/lib/python3.9/site-packages/aiogithubapi/client.py", line 140, in async_call_api
    raise exception(message or response.data)
aiogithubapi.exceptions.GitHubAuthenticationException: Bad credentials
2022-03-10 12:32:32 ERROR (MainThread) [homeassistant.components.github] Bad credentials
Traceback (most recent call last):
  File "/usr/src/homeassistant/homeassistant/components/github/coordinator.py", line 125, in _async_update_data
    response = await self._client.graphql(
  File "/usr/local/lib/python3.9/site-packages/aiogithubapi/github.py", line 225, in graphql
    return await self._client.async_call_api(
  File "/usr/local/lib/python3.9/site-packages/aiogithubapi/client.py", line 140, in async_call_api
    raise exception(message or response.data)
aiogithubapi.exceptions.GitHubAuthenticationException: Bad credentials
2022-03-10 12:33:53 ERROR (MainThread) [homeassistant.components.github] Bad credentials
Traceback (most recent call last):
  File "/usr/src/homeassistant/homeassistant/components/github/coordinator.py", line 125, in _async_update_data
    response = await self._client.graphql(
  File "/usr/local/lib/python3.9/site-packages/aiogithubapi/github.py", line 225, in graphql
    return await self._client.async_call_api(
  File "/usr/local/lib/python3.9/site-packages/aiogithubapi/client.py", line 140, in async_call_api
    raise exception(message or response.data)
aiogithubapi.exceptions.GitHubAuthenticationException: Bad credentials
2022-03-10 12:35:02 WARNING (MainThread) [homeassistant.components.hassio] Can't read Supervisor data: Container addon_a0d7b954_phpmyadmin is not running
2022-03-10 12:35:13 ERROR (MainThread) [homeassistant.components.github] Bad credentials
Traceback (most recent call last):
  File "/usr/src/homeassistant/homeassistant/components/github/coordinator.py", line 125, in _async_update_data
    response = await self._client.graphql(
  File "/usr/local/lib/python3.9/site-packages/aiogithubapi/github.py", line 225, in graphql
    return await self._client.async_call_api(
  File "/usr/local/lib/python3.9/site-packages/aiogithubapi/client.py", line 140, in async_call_api
    raise exception(message or response.data)
aiogithubapi.exceptions.GitHubAuthenticationException: Bad credentials
2022-03-10 12:36:34 ERROR (MainThread) [homeassistant.components.github] Bad credentials
Traceback (most recent call last):
  File "/usr/src/homeassistant/homeassistant/components/github/coordinator.py", line 125, in _async_update_data
    response = await self._client.graphql(
  File "/usr/local/lib/python3.9/site-packages/aiogithubapi/github.py", line 225, in graphql
    return await self._client.async_call_api(
  File "/usr/local/lib/python3.9/site-packages/aiogithubapi/client.py", line 140, in async_call_api
    raise exception(message or response.data)
aiogithubapi.exceptions.GitHubAuthenticationException: Bad credentials
2022-03-10 12:37:54 ERROR (MainThread) [homeassistant.components.github] Bad credentials
Traceback (most recent call last):
  File "/usr/src/homeassistant/homeassistant/components/github/coordinator.py", line 125, in _async_update_data
    response = await self._client.graphql(
  File "/usr/local/lib/python3.9/site-packages/aiogithubapi/github.py", line 225, in graphql
    return await self._client.async_call_api(
  File "/usr/local/lib/python3.9/site-packages/aiogithubapi/client.py", line 140, in async_call_api
    raise exception(message or response.data)
aiogithubapi.exceptions.GitHubAuthenticationException: Bad credentials
2022-03-10 12:39:15 ERROR (MainThread) [homeassistant.components.github] Bad credentials
Traceback (most recent call last):
  File "/usr/src/homeassistant/homeassistant/components/github/coordinator.py", line 125, in _async_update_data
    response = await self._client.graphql(
  File "/usr/local/lib/python3.9/site-packages/aiogithubapi/github.py", line 225, in graphql
    return await self._client.async_call_api(
  File "/usr/local/lib/python3.9/site-packages/aiogithubapi/client.py", line 140, in async_call_api
    raise exception(message or response.data)
aiogithubapi.exceptions.GitHubAuthenticationException: Bad credentials
2022-03-10 12:40:02 WARNING (MainThread) [homeassistant.components.hassio] Can't read Supervisor data: Container addon_a0d7b954_phpmyadmin is not running
2022-03-10 12:40:36 ERROR (MainThread) [homeassistant.components.github] Bad credentials
Traceback (most recent call last):
  File "/usr/src/homeassistant/homeassistant/components/github/coordinator.py", line 125, in _async_update_data
    response = await self._client.graphql(
  File "/usr/local/lib/python3.9/site-packages/aiogithubapi/github.py", line 225, in graphql
    return await self._client.async_call_api(
  File "/usr/local/lib/python3.9/site-packages/aiogithubapi/client.py", line 140, in async_call_api
    raise exception(message or response.data)
aiogithubapi.exceptions.GitHubAuthenticationException: Bad credentials
2022-03-10 12:41:56 ERROR (MainThread) [homeassistant.components.github] Bad credentials
Traceback (most recent call last):
  File "/usr/src/homeassistant/homeassistant/components/github/coordinator.py", line 125, in _async_update_data
    response = await self._client.graphql(
  File "/usr/local/lib/python3.9/site-packages/aiogithubapi/github.py", line 225, in graphql
    return await self._client.async_call_api(
  File "/usr/local/lib/python3.9/site-packages/aiogithubapi/client.py", line 140, in async_call_api
    raise exception(message or response.data)
aiogithubapi.exceptions.GitHubAuthenticationException: Bad credentials
2022-03-10 12:43:17 ERROR (MainThread) [homeassistant.components.github] Bad credentials
Traceback (most recent call last):
  File "/usr/src/homeassistant/homeassistant/components/github/coordinator.py", line 125, in _async_update_data
    response = await self._client.graphql(
  File "/usr/local/lib/python3.9/site-packages/aiogithubapi/github.py", line 225, in graphql
    return await self._client.async_call_api(
  File "/usr/local/lib/python3.9/site-packages/aiogithubapi/client.py", line 140, in async_call_api
    raise exception(message or response.data)
aiogithubapi.exceptions.GitHubAuthenticationException: Bad credentials
2022-03-10 12:44:38 ERROR (MainThread) [homeassistant.components.github] Bad credentials
Traceback (most recent call last):
  File "/usr/src/homeassistant/homeassistant/components/github/coordinator.py", line 125, in _async_update_data
    response = await self._client.graphql(
  File "/usr/local/lib/python3.9/site-packages/aiogithubapi/github.py", line 225, in graphql
    return await self._client.async_call_api(
  File "/usr/local/lib/python3.9/site-packages/aiogithubapi/client.py", line 140, in async_call_api
    raise exception(message or response.data)
aiogithubapi.exceptions.GitHubAuthenticationException: Bad credentials
2022-03-10 12:45:02 WARNING (MainThread) [homeassistant.components.hassio] Can't read Supervisor data: Container addon_a0d7b954_phpmyadmin is not running
2022-03-10 12:45:58 ERROR (MainThread) [homeassistant.components.github] Bad credentials
Traceback (most recent call last):
  File "/usr/src/homeassistant/homeassistant/components/github/coordinator.py", line 125, in _async_update_data
    response = await self._client.graphql(
  File "/usr/local/lib/python3.9/site-packages/aiogithubapi/github.py", line 225, in graphql
    return await self._client.async_call_api(
  File "/usr/local/lib/python3.9/site-packages/aiogithubapi/client.py", line 140, in async_call_api
    raise exception(message or response.data)
aiogithubapi.exceptions.GitHubAuthenticationException: Bad credentials
2022-03-10 12:47:19 ERROR (MainThread) [homeassistant.components.github] Bad credentials
Traceback (most recent call last):
  File "/usr/src/homeassistant/homeassistant/components/github/coordinator.py", line 125, in _async_update_data
    response = await self._client.graphql(
  File "/usr/local/lib/python3.9/site-packages/aiogithubapi/github.py", line 225, in graphql
    return await self._client.async_call_api(
  File "/usr/local/lib/python3.9/site-packages/aiogithubapi/client.py", line 140, in async_call_api
    raise exception(message or response.data)
aiogithubapi.exceptions.GitHubAuthenticationException: Bad credentials
2022-03-10 12:48:39 ERROR (MainThread) [homeassistant.components.github] Bad credentials
Traceback (most recent call last):
  File "/usr/src/homeassistant/homeassistant/components/github/coordinator.py", line 125, in _async_update_data
    response = await self._client.graphql(
  File "/usr/local/lib/python3.9/site-packages/aiogithubapi/github.py", line 225, in graphql
    return await self._client.async_call_api(
  File "/usr/local/lib/python3.9/site-packages/aiogithubapi/client.py", line 140, in async_call_api
    raise exception(message or response.data)
aiogithubapi.exceptions.GitHubAuthenticationException: Bad credentials
2022-03-10 12:50:00 ERROR (MainThread) [homeassistant.components.github] Bad credentials
Traceback (most recent call last):
  File "/usr/src/homeassistant/homeassistant/components/github/coordinator.py", line 125, in _async_update_data
    response = await self._client.graphql(
  File "/usr/local/lib/python3.9/site-packages/aiogithubapi/github.py", line 225, in graphql
    return await self._client.async_call_api(
  File "/usr/local/lib/python3.9/site-packages/aiogithubapi/client.py", line 140, in async_call_api
    raise exception(message or response.data)
aiogithubapi.exceptions.GitHubAuthenticationException: Bad credentials
2022-03-10 12:51:21 ERROR (MainThread) [homeassistant.components.github] Bad credentials
Traceback (most recent call last):
  File "/usr/src/homeassistant/homeassistant/components/github/coordinator.py", line 125, in _async_update_data
    response = await self._client.graphql(
  File "/usr/local/lib/python3.9/site-packages/aiogithubapi/github.py", line 225, in graphql
    return await self._client.async_call_api(
  File "/usr/local/lib/python3.9/site-packages/aiogithubapi/client.py", line 140, in async_call_api
    raise exception(message or response.data)
aiogithubapi.exceptions.GitHubAuthenticationException: Bad credentials
2022-03-10 12:52:41 ERROR (MainThread) [homeassistant.components.github] Bad credentials
Traceback (most recent call last):
  File "/usr/src/homeassistant/homeassistant/components/github/coordinator.py", line 125, in _async_update_data
    response = await self._client.graphql(
  File "/usr/local/lib/python3.9/site-packages/aiogithubapi/github.py", line 225, in graphql
    return await self._client.async_call_api(
  File "/usr/local/lib/python3.9/site-packages/aiogithubapi/client.py", line 140, in async_call_api
    raise exception(message or response.data)
aiogithubapi.exceptions.GitHubAuthenticationException: Bad credentials
2022-03-10 12:54:02 ERROR (MainThread) [homeassistant.components.github] Bad credentials
Traceback (most recent call last):
  File "/usr/src/homeassistant/homeassistant/components/github/coordinator.py", line 125, in _async_update_data
    response = await self._client.graphql(
  File "/usr/local/lib/python3.9/site-packages/aiogithubapi/github.py", line 225, in graphql
    return await self._client.async_call_api(
  File "/usr/local/lib/python3.9/site-packages/aiogithubapi/client.py", line 140, in async_call_api
    raise exception(message or response.data)
aiogithubapi.exceptions.GitHubAuthenticationException: Bad credentials
2022-03-10 12:55:23 ERROR (MainThread) [homeassistant.components.github] Bad credentials
Traceback (most recent call last):
  File "/usr/src/homeassistant/homeassistant/components/github/coordinator.py", line 125, in _async_update_data
    response = await self._client.graphql(
  File "/usr/local/lib/python3.9/site-packages/aiogithubapi/github.py", line 225, in graphql
    return await self._client.async_call_api(
  File "/usr/local/lib/python3.9/site-packages/aiogithubapi/client.py", line 140, in async_call_api
    raise exception(message or response.data)
aiogithubapi.exceptions.GitHubAuthenticationException: Bad credentials
2022-03-10 12:56:43 ERROR (MainThread) [homeassistant.components.github] Bad credentials
Traceback (most recent call last):
  File "/usr/src/homeassistant/homeassistant/components/github/coordinator.py", line 125, in _async_update_data
    response = await self._client.graphql(
  File "/usr/local/lib/python3.9/site-packages/aiogithubapi/github.py", line 225, in graphql
    return await self._client.async_call_api(
  File "/usr/local/lib/python3.9/site-packages/aiogithubapi/client.py", line 140, in async_call_api
    raise exception(message or response.data)
aiogithubapi.exceptions.GitHubAuthenticationException: Bad credentials
2022-03-10 12:58:04 ERROR (MainThread) [homeassistant.components.github] Bad credentials
Traceback (most recent call last):
  File "/usr/src/homeassistant/homeassistant/components/github/coordinator.py", line 125, in _async_update_data
    response = await self._client.graphql(
  File "/usr/local/lib/python3.9/site-packages/aiogithubapi/github.py", line 225, in graphql
    return await self._client.async_call_api(
  File "/usr/local/lib/python3.9/site-packages/aiogithubapi/client.py", line 140, in async_call_api
    raise exception(message or response.data)
aiogithubapi.exceptions.GitHubAuthenticationException: Bad credentials
2022-03-10 12:59:24 ERROR (MainThread) [homeassistant.components.github] Bad credentials
Traceback (most recent call last):
  File "/usr/src/homeassistant/homeassistant/components/github/coordinator.py", line 125, in _async_update_data
    response = await self._client.graphql(
  File "/usr/local/lib/python3.9/site-packages/aiogithubapi/github.py", line 225, in graphql
    return await self._client.async_call_api(
  File "/usr/local/lib/python3.9/site-packages/aiogithubapi/client.py", line 140, in async_call_api
    raise exception(message or response.data)
aiogithubapi.exceptions.GitHubAuthenticationException: Bad credentials
2022-03-10 13:00:09 WARNING (MainThread) [homeassistant.components.hassio] Can't read Supervisor data: Container addon_a0d7b954_phpmyadmin is not running
2022-03-10 13:00:45 ERROR (MainThread) [homeassistant.components.github] Bad credentials
Traceback (most recent call last):
  File "/usr/src/homeassistant/homeassistant/components/github/coordinator.py", line 125, in _async_update_data
    response = await self._client.graphql(
  File "/usr/local/lib/python3.9/site-packages/aiogithubapi/github.py", line 225, in graphql
    return await self._client.async_call_api(
  File "/usr/local/lib/python3.9/site-packages/aiogithubapi/client.py", line 140, in async_call_api
    raise exception(message or response.data)
aiogithubapi.exceptions.GitHubAuthenticationException: Bad credentials
2022-03-10 13:02:06 ERROR (MainThread) [homeassistant.components.github] Bad credentials
Traceback (most recent call last):
  File "/usr/src/homeassistant/homeassistant/components/github/coordinator.py", line 125, in _async_update_data
    response = await self._client.graphql(
  File "/usr/local/lib/python3.9/site-packages/aiogithubapi/github.py", line 225, in graphql
    return await self._client.async_call_api(
  File "/usr/local/lib/python3.9/site-packages/aiogithubapi/client.py", line 140, in async_call_api
    raise exception(message or response.data)
aiogithubapi.exceptions.GitHubAuthenticationException: Bad credentials
2022-03-10 13:03:26 ERROR (MainThread) [homeassistant.components.github] Bad credentials
Traceback (most recent call last):
  File "/usr/src/homeassistant/homeassistant/components/github/coordinator.py", line 125, in _async_update_data
    response = await self._client.graphql(
  File "/usr/local/lib/python3.9/site-packages/aiogithubapi/github.py", line 225, in graphql
    return await self._client.async_call_api(
  File "/usr/local/lib/python3.9/site-packages/aiogithubapi/client.py", line 140, in async_call_api
    raise exception(message or response.data)
aiogithubapi.exceptions.GitHubAuthenticationException: Bad credentials
2022-03-10 13:04:47 ERROR (MainThread) [homeassistant.components.github] Bad credentials
Traceback (most recent call last):
  File "/usr/src/homeassistant/homeassistant/components/github/coordinator.py", line 125, in _async_update_data
    response = await self._client.graphql(
  File "/usr/local/lib/python3.9/site-packages/aiogithubapi/github.py", line 225, in graphql
    return await self._client.async_call_api(
  File "/usr/local/lib/python3.9/site-packages/aiogithubapi/client.py", line 140, in async_call_api
    raise exception(message or response.data)
aiogithubapi.exceptions.GitHubAuthenticationException: Bad credentials
2022-03-10 13:05:09 WARNING (MainThread) [homeassistant.components.hassio] Can't read Supervisor data: Container addon_a0d7b954_phpmyadmin is not running
2022-03-10 13:06:08 ERROR (MainThread) [homeassistant.components.github] Bad credentials
Traceback (most recent call last):
  File "/usr/src/homeassistant/homeassistant/components/github/coordinator.py", line 125, in _async_update_data
    response = await self._client.graphql(
  File "/usr/local/lib/python3.9/site-packages/aiogithubapi/github.py", line 225, in graphql
    return await self._client.async_call_api(
  File "/usr/local/lib/python3.9/site-packages/aiogithubapi/client.py", line 140, in async_call_api
    raise exception(message or response.data)
aiogithubapi.exceptions.GitHubAuthenticationException: Bad credentials
2022-03-10 13:07:28 ERROR (MainThread) [homeassistant.components.github] Bad credentials
Traceback (most recent call last):
  File "/usr/src/homeassistant/homeassistant/components/github/coordinator.py", line 125, in _async_update_data
    response = await self._client.graphql(
  File "/usr/local/lib/python3.9/site-packages/aiogithubapi/github.py", line 225, in graphql
    return await self._client.async_call_api(
  File "/usr/local/lib/python3.9/site-packages/aiogithubapi/client.py", line 140, in async_call_api
    raise exception(message or response.data)
aiogithubapi.exceptions.GitHubAuthenticationException: Bad credentials
2022-03-10 13:08:49 ERROR (MainThread) [homeassistant.components.github] Bad credentials
Traceback (most recent call last):
  File "/usr/src/homeassistant/homeassistant/components/github/coordinator.py", line 125, in _async_update_data
    response = await self._client.graphql(
  File "/usr/local/lib/python3.9/site-packages/aiogithubapi/github.py", line 225, in graphql
    return await self._client.async_call_api(
  File "/usr/local/lib/python3.9/site-packages/aiogithubapi/client.py", line 140, in async_call_api
    raise exception(message or response.data)
aiogithubapi.exceptions.GitHubAuthenticationException: Bad credentials
2022-03-10 13:10:09 WARNING (MainThread) [homeassistant.components.hassio] Can't read Supervisor data: Container addon_a0d7b954_phpmyadmin is not running
2022-03-10 13:10:10 ERROR (MainThread) [homeassistant.components.github] Bad credentials
Traceback (most recent call last):
  File "/usr/src/homeassistant/homeassistant/components/github/coordinator.py", line 125, in _async_update_data
    response = await self._client.graphql(
  File "/usr/local/lib/python3.9/site-packages/aiogithubapi/github.py", line 225, in graphql
    return await self._client.async_call_api(
  File "/usr/local/lib/python3.9/site-packages/aiogithubapi/client.py", line 140, in async_call_api
    raise exception(message or response.data)
aiogithubapi.exceptions.GitHubAuthenticationException: Bad credentials
2022-03-10 13:11:30 ERROR (MainThread) [homeassistant.components.github] Bad credentials
Traceback (most recent call last):
  File "/usr/src/homeassistant/homeassistant/components/github/coordinator.py", line 125, in _async_update_data
    response = await self._client.graphql(
  File "/usr/local/lib/python3.9/site-packages/aiogithubapi/github.py", line 225, in graphql
    return await self._client.async_call_api(
  File "/usr/local/lib/python3.9/site-packages/aiogithubapi/client.py", line 140, in async_call_api
    raise exception(message or response.data)
aiogithubapi.exceptions.GitHubAuthenticationException: Bad credentials
2022-03-10 13:12:51 ERROR (MainThread) [homeassistant.components.github] Bad credentials
Traceback (most recent call last):
  File "/usr/src/homeassistant/homeassistant/components/github/coordinator.py", line 125, in _async_update_data
    response = await self._client.graphql(
  File "/usr/local/lib/python3.9/site-packages/aiogithubapi/github.py", line 225, in graphql
    return await self._client.async_call_api(
  File "/usr/local/lib/python3.9/site-packages/aiogithubapi/client.py", line 140, in async_call_api
    raise exception(message or response.data)
aiogithubapi.exceptions.GitHubAuthenticationException: Bad credentials
2022-03-10 13:14:12 ERROR (MainThread) [homeassistant.components.github] Bad credentials
Traceback (most recent call last):
  File "/usr/src/homeassistant/homeassistant/components/github/coordinator.py", line 125, in _async_update_data
    response = await self._client.graphql(
  File "/usr/local/lib/python3.9/site-packages/aiogithubapi/github.py", line 225, in graphql
    return await self._client.async_call_api(
  File "/usr/local/lib/python3.9/site-packages/aiogithubapi/client.py", line 140, in async_call_api
    raise exception(message or response.data)
aiogithubapi.exceptions.GitHubAuthenticationException: Bad credentials
2022-03-10 13:15:09 WARNING (MainThread) [homeassistant.components.hassio] Can't read Supervisor data: Container addon_a0d7b954_phpmyadmin is not running
2022-03-10 13:15:32 ERROR (MainThread) [homeassistant.components.github] Bad credentials
Traceback (most recent call last):
  File "/usr/src/homeassistant/homeassistant/components/github/coordinator.py", line 125, in _async_update_data
    response = await self._client.graphql(
  File "/usr/local/lib/python3.9/site-packages/aiogithubapi/github.py", line 225, in graphql
    return await self._client.async_call_api(
  File "/usr/local/lib/python3.9/site-packages/aiogithubapi/client.py", line 140, in async_call_api
    raise exception(message or response.data)
aiogithubapi.exceptions.GitHubAuthenticationException: Bad credentials
2022-03-10 13:16:53 ERROR (MainThread) [homeassistant.components.github] Bad credentials
Traceback (most recent call last):
  File "/usr/src/homeassistant/homeassistant/components/github/coordinator.py", line 125, in _async_update_data
    response = await self._client.graphql(
  File "/usr/local/lib/python3.9/site-packages/aiogithubapi/github.py", line 225, in graphql
    return await self._client.async_call_api(
  File "/usr/local/lib/python3.9/site-packages/aiogithubapi/client.py", line 140, in async_call_api
    raise exception(message or response.data)
aiogithubapi.exceptions.GitHubAuthenticationException: Bad credentials
2022-03-10 13:18:13 ERROR (MainThread) [homeassistant.components.github] Bad credentials
Traceback (most recent call last):
  File "/usr/src/homeassistant/homeassistant/components/github/coordinator.py", line 125, in _async_update_data
    response = await self._client.graphql(
  File "/usr/local/lib/python3.9/site-packages/aiogithubapi/github.py", line 225, in graphql
    return await self._client.async_call_api(
  File "/usr/local/lib/python3.9/site-packages/aiogithubapi/client.py", line 140, in async_call_api
    raise exception(message or response.data)
aiogithubapi.exceptions.GitHubAuthenticationException: Bad credentials
2022-03-10 13:19:34 ERROR (MainThread) [homeassistant.components.github] Bad credentials
Traceback (most recent call last):
  File "/usr/src/homeassistant/homeassistant/components/github/coordinator.py", line 125, in _async_update_data
    response = await self._client.graphql(
  File "/usr/local/lib/python3.9/site-packages/aiogithubapi/github.py", line 225, in graphql
    return await self._client.async_call_api(
  File "/usr/local/lib/python3.9/site-packages/aiogithubapi/client.py", line 140, in async_call_api
    raise exception(message or response.data)
aiogithubapi.exceptions.GitHubAuthenticationException: Bad credentials
2022-03-10 13:20:09 WARNING (MainThread) [homeassistant.components.hassio] Can't read Supervisor data: Container addon_a0d7b954_phpmyadmin is not running
2022-03-10 13:20:55 ERROR (MainThread) [homeassistant.components.github] Bad credentials
Traceback (most recent call last):
  File "/usr/src/homeassistant/homeassistant/components/github/coordinator.py", line 125, in _async_update_data
    response = await self._client.graphql(
  File "/usr/local/lib/python3.9/site-packages/aiogithubapi/github.py", line 225, in graphql
    return await self._client.async_call_api(
  File "/usr/local/lib/python3.9/site-packages/aiogithubapi/client.py", line 140, in async_call_api
    raise exception(message or response.data)
aiogithubapi.exceptions.GitHubAuthenticationException: Bad credentials
2022-03-10 13:22:15 ERROR (MainThread) [homeassistant.components.github] Bad credentials
Traceback (most recent call last):
  File "/usr/src/homeassistant/homeassistant/components/github/coordinator.py", line 125, in _async_update_data
    response = await self._client.graphql(
  File "/usr/local/lib/python3.9/site-packages/aiogithubapi/github.py", line 225, in graphql
    return await self._client.async_call_api(
  File "/usr/local/lib/python3.9/site-packages/aiogithubapi/client.py", line 140, in async_call_api
    raise exception(message or response.data)
aiogithubapi.exceptions.GitHubAuthenticationException: Bad credentials
2022-03-10 13:23:36 ERROR (MainThread) [homeassistant.components.github] Bad credentials
Traceback (most recent call last):
  File "/usr/src/homeassistant/homeassistant/components/github/coordinator.py", line 125, in _async_update_data
    response = await self._client.graphql(
  File "/usr/local/lib/python3.9/site-packages/aiogithubapi/github.py", line 225, in graphql
    return await self._client.async_call_api(
  File "/usr/local/lib/python3.9/site-packages/aiogithubapi/client.py", line 140, in async_call_api
    raise exception(message or response.data)
aiogithubapi.exceptions.GitHubAuthenticationException: Bad credentials
2022-03-10 13:24:57 ERROR (MainThread) [homeassistant.components.github] Bad credentials
Traceback (most recent call last):
  File "/usr/src/homeassistant/homeassistant/components/github/coordinator.py", line 125, in _async_update_data
    response = await self._client.graphql(
  File "/usr/local/lib/python3.9/site-packages/aiogithubapi/github.py", line 225, in graphql
    return await self._client.async_call_api(
  File "/usr/local/lib/python3.9/site-packages/aiogithubapi/client.py", line 140, in async_call_api
    raise exception(message or response.data)
aiogithubapi.exceptions.GitHubAuthenticationException: Bad credentials
2022-03-10 13:25:09 WARNING (MainThread) [homeassistant.components.hassio] Can't read Supervisor data: Container addon_a0d7b954_phpmyadmin is not running
2022-03-10 13:26:17 ERROR (MainThread) [homeassistant.components.github] Bad credentials
Traceback (most recent call last):
  File "/usr/src/homeassistant/homeassistant/components/github/coordinator.py", line 125, in _async_update_data
    response = await self._client.graphql(
  File "/usr/local/lib/python3.9/site-packages/aiogithubapi/github.py", line 225, in graphql
    return await self._client.async_call_api(
  File "/usr/local/lib/python3.9/site-packages/aiogithubapi/client.py", line 140, in async_call_api
    raise exception(message or response.data)
aiogithubapi.exceptions.GitHubAuthenticationException: Bad credentials
2022-03-10 13:27:38 ERROR (MainThread) [homeassistant.components.github] Bad credentials
Traceback (most recent call last):
  File "/usr/src/homeassistant/homeassistant/components/github/coordinator.py", line 125, in _async_update_data
    response = await self._client.graphql(
  File "/usr/local/lib/python3.9/site-packages/aiogithubapi/github.py", line 225, in graphql
    return await self._client.async_call_api(
  File "/usr/local/lib/python3.9/site-packages/aiogithubapi/client.py", line 140, in async_call_api
    raise exception(message or response.data)
aiogithubapi.exceptions.GitHubAuthenticationException: Bad credentials
2022-03-10 13:28:58 ERROR (MainThread) [homeassistant.components.github] Bad credentials
Traceback (most recent call last):
  File "/usr/src/homeassistant/homeassistant/components/github/coordinator.py", line 125, in _async_update_data
    response = await self._client.graphql(
  File "/usr/local/lib/python3.9/site-packages/aiogithubapi/github.py", line 225, in graphql
    return await self._client.async_call_api(
  File "/usr/local/lib/python3.9/site-packages/aiogithubapi/client.py", line 140, in async_call_api
    raise exception(message or response.data)
aiogithubapi.exceptions.GitHubAuthenticationException: Bad credentials
2022-03-10 13:30:19 ERROR (MainThread) [homeassistant.components.github] Bad credentials
Traceback (most recent call last):
  File "/usr/src/homeassistant/homeassistant/components/github/coordinator.py", line 125, in _async_update_data
    response = await self._client.graphql(
  File "/usr/local/lib/python3.9/site-packages/aiogithubapi/github.py", line 225, in graphql
    return await self._client.async_call_api(
  File "/usr/local/lib/python3.9/site-packages/aiogithubapi/client.py", line 140, in async_call_api
    raise exception(message or response.data)
aiogithubapi.exceptions.GitHubAuthenticationException: Bad credentials
2022-03-10 13:30:47 ERROR (MainThread) [homeassistant.components.hassio.handler] /ingress/validate_session return code 401
2022-03-10 13:30:47 ERROR (MainThread) [homeassistant.components.hassio] Failed to to call /ingress/validate_session - 
2022-03-10 13:30:47 ERROR (MainThread) [homeassistant.components.hassio.handler] /ingress/validate_session return code 401
2022-03-10 13:30:47 ERROR (MainThread) [homeassistant.components.hassio] Failed to to call /ingress/validate_session - 
2022-03-10 13:31:40 ERROR (MainThread) [homeassistant.components.github] Bad credentials
Traceback (most recent call last):
  File "/usr/src/homeassistant/homeassistant/components/github/coordinator.py", line 125, in _async_update_data
    response = await self._client.graphql(
  File "/usr/local/lib/python3.9/site-packages/aiogithubapi/github.py", line 225, in graphql
    return await self._client.async_call_api(
  File "/usr/local/lib/python3.9/site-packages/aiogithubapi/client.py", line 140, in async_call_api
    raise exception(message or response.data)
aiogithubapi.exceptions.GitHubAuthenticationException: Bad credentials
2022-03-10 13:33:00 ERROR (MainThread) [homeassistant.components.github] Bad credentials
Traceback (most recent call last):
  File "/usr/src/homeassistant/homeassistant/components/github/coordinator.py", line 125, in _async_update_data
    response = await self._client.graphql(
  File "/usr/local/lib/python3.9/site-packages/aiogithubapi/github.py", line 225, in graphql
    return await self._client.async_call_api(
  File "/usr/local/lib/python3.9/site-packages/aiogithubapi/client.py", line 140, in async_call_api
    raise exception(message or response.data)
aiogithubapi.exceptions.GitHubAuthenticationException: Bad credentials
